Workbook
Name apr_tot_down: #REF!
Name apr_tot_up: #REF!
Name dec_tot_down: 'December 2017'!$Y$33
Name dec_tot_hrs: 'December 2017'!$I$33
Name dec_tot_up: 'December 2017'!$Z$33
Name feb_tot_down: 'February 2018'!$Y$33
Name feb_tot_hrs: 'February 2018'!$I$33
Name feb_tot_up: 'February 2018'!$Z$33
Name jan_tot_down: 'January 2018'!$Y$33
Name jan_tot_hrs: 'January 2018'!$I$33
Name jan_tot_up: 'January 2018'!$Z$33
Name MAR_F_A_DN: 'April 2018'!$M$33
Name MAR_F_A_DN: 'March 2018'!$M$33
Name mar_tot_down: 'April 2018'!$Y$33
Name mar_tot_down: 'March 2018'!$Y$33
Name mar_tot_hrs: 'April 2018'!$I$33
Name mar_tot_hrs: 'March 2018'!$I$33
Name mar_tot_up: 'April 2018'!$Z$33
Name mar_tot_up: 'March 2018'!$Z$33
Name nov_tot_down: 'November 2017'!$Y$33
Name nov_tot_hrs: 'November 2017'!$I$33
Name nov_tot_up: 'November 2017'!$Z$33

Sheet April 2018
A1: Date | B1: Sunset | C1: Civil Twilight | D1: Captain | E1: Monitored (Y/N) | F1: Start time HH:MM | G1: End time HH:MM | H1: Hours monitored | I1: Team Hrs. | J1: Start temp | K1: End temp | L1: Weather | M1: Females assisted down | N1: Males assisted down | O1: Unassisted Females down | P1: Unasissted Males down | Q1: Females assisted up | R1: Males assisted up | S1: Unassisted females up | T1: Unassisted males up | U1: Juveniles assisted up | V1: Roadkill Females | W1: Roadkill Males | X1: Roadkill Unk | Y1: Total frogs down | Z1: Total frogs up | AA1: Total Frogs Assisted Down | AB1: Total Frogs Assisted Up | AC1: % moon visible | AD1: Comments
A2: 43191 | B2: 1939 | C2: 2009 | D2: =CHOOSE(WEEKDAY(A2),"Fred/Anne", "Jane", "Phil","Sue/Panos","Shawn/Owens","Jeff", "Rob") -> Fred/Anne | E2: Y | F2: 0.80208333 | G2: 0.87847222 | H2: =G2-F2 -> 0.076388889 | I2: 9 | J2: 44 | K2: 39 | L2: wet pavement, rain earlier | M2: 0 | N2: 0 | O2: 0 | P2: 0 | Q2: 0 | R2: 0 | S2: 0 | T2: 0 | U2: 0 | V2: 0 | W2: 0 | X2: 1 | Y2: =SUM(M2:P2) -> 0 | Z2: =SUM(Q2:U2) -> 0 | AA2: =SUM(M2:N2) -> 0 | AB2: =SUM(Q2:R2,U2) -> 0 | AC2: 0.99 | AD2: 8 Chorus frogs up, sex not determined. Interestingly, all found crossing MW uphill at 42-39 degrees. One hypothermic to torpor. Two Roadkill chorus frogs.
A3: 43192 | B3: 1940 | C3: 2010 | D3: =CHOOSE(WEEKDAY(A3),"Fred/Anne", "Jane", "Phil","Sue/Panos","Shawn/Owens","Jeff", "Rob") -> Jane | E3: N | H3: =G3-F3 -> 0 | J3: 45 | L3: dry | M3: 0 | N3: 0 | O3: 0 | P3: 0 | Q3: 0 | R3: 0 | S3: 0 | T3: 0 | U3: 0 | V3: 0 | W3: 0 | X3: 0 | Y3: =SUM(M3:P3) -> 0 | Z3: =SUM(Q3:U3) -> 0 | AA3: =SUM(M3:N3) -> 0 | AB3: =SUM(Q3:R3,U3) -> 0 | AC3: 0.96
A4: 43193 | B4: 1942 | C4: 2012 | D4: =CHOOSE(WEEKDAY(A4),"Fred/Anne", "Jane", "Phil/Tom","Sue/Panos","Shawn/Owens","Jeff", "Rob") -> Phil/Tom | E4: N | H4: =G4-F4 -> 0 | J4: 52 | K4: 52 | L4: dry | M4: 0 | N4: 0 | O4: 0 | P4: 0 | Q4: 0 | R4: 0 | S4: 0 | T4: 0 | U4: 0 | V4: 0 | W4: 0 | X4: 0 | Y4: =SUM(M4:P4) -> 0 | Z4: =SUM(Q4:U4) -> 0 | AA4: =SUM(M4:N4) -> 0 | AB4: =SUM(Q4:R4,U4) -> 0 | AC4: 0.91
A5: 43194 | B5: 1943 | C5: 2013 | D5: =CHOOSE(WEEKDAY(A5),"Fred/Anne", "Jane", "Phil","Sue/Panos","Shawn/Owens","Jeff", "Rob") -> Sue/Panos | E5: N | F5: 0.83333333 | G5: 0.83333333 | H5: =G5-F5 -> 0 | J5: 52 | L5: Dry | M5: 0 | N5: 0 | O5: 0 | P5: 0 | Q5: 0 | R5: 0 | S5: 0 | T5: 0 | U5: 0 | V5: 0 | W5: 0 | X5: 0 | Y5: =SUM(M5:P5) -> 0 | Z5: =SUM(Q5:U5) -> 0 | AA5: =SUM(M5:N5) -> 0 | AB5: =SUM(Q5:R5,U5) -> 0 | AC5: 0.85
A6: 43195 | B6: 1944 | C6: 2014 | D6: =CHOOSE(WEEKDAY(A6),"Fred/Anne", "Jane", "Phil","Sue/Panos","Shawn/Owens","Jeff", "Rob") -> Shawn/Owens | E6: Y | F6: 0.83333333 | G6: 1 | H6: =G6-F6 -> 0.16666667 | I6: 24.5 | J6: 55 | K6: 53 | L6: Dry, wet pavement (rained earlier) Drizzle after 11:30 | M6: 0 | N6: 0 | O6: 0 | P6: 1 | Q6: 11 | R6: 21 | S6: 0 | T6: 1 | U6: 4 | V6: 0 | W6: 0 | X6: 0 | Y6: =SUM(M6:P6) -> 1 | Z6: =SUM(Q6:U6) -> 37 | AA6: =SUM(M6:N6) -> 0 | AB6: =SUM(Q6:R6,U6) -> 36 | AC6: 0.77 | AD6: 3 chorus down, 30+ up; 1 NW Salamander up; 10(?) RL banded for tracking
A7: 43196 | B7: 1945 | C7: 2016 | D7: =CHOOSE(WEEKDAY(A7),"Fred/Anne", "Jane", "Phil","Sue/Panos","Shawn/Owens","Jeff", "Rob") -> Jeff | E7: Y | F7: 0.96527778 | G7: 0.99305556 | H7: =G7-F7 -> 0.027777778 | I7: 0.6 | J7: 61 | K7: 59 | L7: Dry (dry and warm all day) | M7: 0 | N7: 0 | O7: 0 | P7: 0 | Q7: 0 | R7: 0 | S7: 0 | T7: 0 | U7: 0 | V7: 0 | W7: 0 | X7: 0 | Y7: =SUM(M7:P7) -> 0 | Z7: =SUM(Q7:U7) -> 0 | AA7: =SUM(M7:N7) -> 0 | AB7: =SUM(Q7:R7,U7) -> 0 | AC7: 0.68 | AD7: Rain forecast for 11PM hour did not occur
A8: 43197 | B8: 1947 | C8: 2017 | D8: =CHOOSE(WEEKDAY(A8),"Fred/Anne", "Jane", "Phil","Sue/Panos","Shawn/Owens","Jeff", "Rob") -> Rob | E8: y | F8: 0.8125 | G8: 0.89583333 | H8: =G8-F8 -> 0.083333333 | I8: 8 | J8: 47 | K8: 47 | L8: steady rain | M8: 0 | N8: 0 | O8: 0 | P8: 0 | Q8: 0 | R8: 0 | S8: 0 | T8: 0 | U8: 0 | V8: 0 | W8: 0 | X8: 0 | Y8: =SUM(M8:P8) -> 0 | Z8: =SUM(Q8:U8) -> 0 | AA8: =SUM(M8:N8) -> 0 | AB8: =SUM(Q8:R8,U8) -> 0 | AC8: 0.59
A9: 43198 | B9: 1948 | C9: 2019 | D9: =CHOOSE(WEEKDAY(A9),"Fred/Anne", "Jane", "Phil","Sue/Panos","Shawn/Owens","Jeff", "Rob") -> Fred/Anne | E9: y | F9: 0.84375 | G9: 0.88541667 | H9: =G9-F9 -> 0.041666667 | I9: 2 | J9: 43 | K9: 42 | L9: Dry; dry pavement | M9: 0 | N9: 0 | O9: 0 | P9: 0 | Q9: 0 | R9: 0 | S9: 0 | T9: 0 | U9: 0 | V9: 0 | W9: 0 | X9: 0 | Y9: =SUM(M9:P9) -> 0 | Z9: =SUM(Q9:U9) -> 0 | AA9: =SUM(M9:N9) -> 0 | AB9: =SUM(Q9:R9,U9) -> 0 | AC9: 0.5 | AD9: Looked carefully for bodies from last night, saw none. 1 LT Salamander moved uphill.
A10: 43199 | B10: 1949 | C10: 2020 | D10: =CHOOSE(WEEKDAY(A10),"Fred/Anne", "Jane", "Phil","Sue/Panos","Shawn/Owens","Jeff", "Rob") -> Jane | E10: Y | F10: 0.86458333 | G10: 0.875 | H10: =G10-F10 -> 0.010416667 | I10: 0.25 | J10: 55 | K10: 55 | L10: Dry | M10: 0 | N10: 0 | O10: 0 | P10: 0 | Q10: 0 | R10: 0 | S10: 0 | T10: 0 | U10: 0 | V10: 0 | W10: 0 | X10: 0 | Y10: =SUM(M10:P10) -> 0 | Z10: =SUM(Q10:U10) -> 0 | AA10: =SUM(M10:N10) -> 0 | AB10: =SUM(Q10:R10,U10) -> 0 | AC10: 0.4
A11: 43200 | B11: 1951 | C11: 2021 | D11: =CHOOSE(WEEKDAY(A11),"Fred/Anne", "Jane", "Phil/Tom","Sue/Panos","Shawn/Owens","Jeff", "Rob") -> Phil/Tom | E11: Y | F11: 0.84375 | G11: 0.85416667 | H11: =G11-F11 -> 0.010416667 | I11: 0.25 | J11: 53 | K11: 52 | L11: Dry | M11: 0 | N11: 0 | O11: 0 | P11: 0 | Q11: 0 | R11: 0 | S11: 0 | T11: 0 | U11: 0 | V11: 0 | W11: 0 | X11: 0 | Y11: =SUM(M11:P11) -> 0 | Z11: =SUM(Q11:U11) -> 0 | AA11: =SUM(M11:N11) -> 0 | AB11: =SUM(Q11:R11,U11) -> 0 | AC11: 0.31
A12: 43201 | B12: 1952 | C12: 2023 | D12: =CHOOSE(WEEKDAY(A12),"Fred/Anne", "Jane", "Phil","Sue/Panos","Shawn/Owens","Jeff", "Rob") -> Sue/Panos | E12: Y | F12: 0.83333333 | G12: 0.88541667 | H12: =G12-F12 -> 0.052083333 | I12: 3 | J12: 48 | K12: 44 | L12: wet pavement, rain earlier | M12: 0 | N12: 0 | O12: 0 | P12: 0 | Q12: 0 | R12: 0 | S12: 0 | T12: 0 | U12: 0 | V12: 0 | W12: 0 | X12: 0 | Y12: =SUM(M12:P12) -> 0 | Z12: =SUM(Q12:U12) -> 0 | AA12: =SUM(M12:N12) -> 0 | AB12: =SUM(Q12:R12,U12) -> 0 | AC12: 0.23 | AD12: 10 chorus frogs up, 5 down
A13: 43202 | B13: 1953 | C13: 2024 | D13: =CHOOSE(WEEKDAY(A13),"Fred/Anne", "Jane", "Phil","Sue/Panos","Shawn/Owens","Jeff", "Rob") -> Shawn/Owens | E13: Y | F13: 0.84375 | G13: 0.86458333 | H13: =G13-F13 -> 0.020833333 | I13: 0.5 | J13: 46 | K13: 45 | L13: Dry, temp cooling | M13: 0 | N13: 0 | O13: 0 | P13: 0 | Q13: 0 | R13: 0 | S13: 0 | T13: 0 | U13: 0 | V13: 0 | W13: 0 | X13: 0 | Y13: =SUM(M13:P13) -> 0 | Z13: =SUM(Q13:U13) -> 0 | AA13: =SUM(M13:N13) -> 0 | AB13: =SUM(Q13:R13,U13) -> 0 | AC13: 0.15 | AD13: Nary a chorus frog; wetlands were loud
A14: 43203 | B14: 1954 | C14: 2025 | D14: =CHOOSE(WEEKDAY(A14),"Fred/Anne", "Jane", "Phil","Sue/Panos","Shawn/Owens","Jeff", "Rob") -> Jeff | E14: Y | F14: 0.85069444 | G14: 0.875 | H14: =G14-F14 -> 0.024305556 | I14: 0.6 | J14: 51 | K14: 50 | L14: Dry, overcast | M14: 0 | N14: 0 | O14: 0 | P14: 0 | Q14: 0 | R14: 0 | S14: 0 | T14: 0 | U14: 0 | V14: 0 | W14: 0 | X14: 0 | Y14: =SUM(M14:P14) -> 0 | Z14: =SUM(Q14:U14) -> 0 | AA14: =SUM(M14:N14) -> 0 | AB14: =SUM(Q14:R14,U14) -> 0 | AC14: 0.09
A15: 43204 | B15: 1956 | C15: 2027 | D15: =CHOOSE(WEEKDAY(A15),"Fred/Anne", "Jane", "Phil","Sue/Panos","Shawn/Owens","Jeff", "Rob") -> Rob | H15: =G15-F15 -> 0 | M15: 0 | N15: 0 | O15: 0 | P15: 0 | Q15: 0 | R15: 0 | S15: 0 | T15: 0 | U15: 0 | V15: 0 | W15: 0 | X15: 0 | Y15: =SUM(M15:P15) -> 0 | Z15: =SUM(Q15:U15) -> 0 | AA15: =SUM(M15:N15) -> 0 | AB15: =SUM(Q15:R15,U15) -> 0 | AC15: 0.04
A16: 43205 | B16: 1957 | C16: 2028 | D16: =CHOOSE(WEEKDAY(A16),"Fred/Anne", "Jane", "Phil","Sue/Panos","Shawn/Owens","Jeff", "Rob") -> Fred/Anne | E16: Y | F16: 0.83680556 | G16: 0.87152778 | H16: =G16-F16 -> 0.034722222 | I16: 3.3 | J16: 48 | K16: 46 | L16: wet, light rain on and off | M16: 0 | N16: 0 | O16: 0 | P16: 0 | Q16: 0 | R16: 0 | S16: 0 | T16: 0 | U16: 0 | V16: 0 | W16: 0 | X16: 0 | Y16: =SUM(M16:P16) -> 0 | Z16: =SUM(Q16:U16) -> 0 | AA16: =SUM(M16:N16) -> 0 | AB16: =SUM(Q16:R16,U16) -> 0 | AC16: 0.01
A17: 43206 | B17: 1958 | C17: 2030 | D17: =CHOOSE(WEEKDAY(A17),"Fred/Anne", "Jane", "Phil","Sue/Panos","Shawn/Owens","Jeff", "Rob") -> Jane | H17: =G17-F17 -> 0 | M17: 0 | N17: 0 | O17: 0 | P17: 0 | Q17: 0 | R17: 0 | S17: 0 | T17: 0 | U17: 0 | V17: 0 | W17: 0 | X17: 0 | Y17: =SUM(M17:P17) -> 0 | Z17: =SUM(Q17:U17) -> 0 | AA17: =SUM(M17:N17) -> 0 | AB17: =SUM(Q17:R17,U17) -> 0 | AC17: 0
A18: 43207 | B18: 2000 | C18: 2031 | D18: =CHOOSE(WEEKDAY(A18),"Fred/Anne", "Jane", "Phil/Tom","Sue/Panos","Shawn/Owens","Jeff", "Rob") -> Phil/Tom | H18: =G18-F18 -> 0 | M18: 0 | N18: 0 | O18: 0 | P18: 0 | Q18: 0 | R18: 0 | S18: 0 | T18: 0 | U18: 0 | V18: 0 | W18: 0 | X18: 0 | Y18: =SUM(M18:P18) -> 0 | Z18: =SUM(Q18:U18) -> 0 | AA18: =SUM(M18:N18) -> 0 | AB18: =SUM(Q18:R18,U18) -> 0 | AC18: 0.02
A19: 43208 | B19: 2001 | C19: 2032 | D19: =CHOOSE(WEEKDAY(A19),"Fred/Anne", "Jane", "Phil","Sue/Panos","Shawn/Owens","Jeff", "Rob") -> Sue/Panos | H19: =G19-F19 -> 0 | M19: 0 | N19: 0 | O19: 0 | P19: 0 | Q19: 0 | R19: 0 | S19: 0 | T19: 0 | U19: 0 | V19: 0 | W19: 0 | X19: 0 | Y19: =SUM(M19:P19) -> 0 | Z19: =SUM(Q19:U19) -> 0 | AA19: =SUM(M19:N19) -> 0 | AB19: =SUM(Q19:R19,U19) -> 0 | AC19: 0.07
A20: 43209 | B20: 2002 | C20: 2034 | D20: =CHOOSE(WEEKDAY(A20),"Fred/Anne", "Jane", "Phil","Sue/Panos","Shawn/Owens","Jeff", "Rob") -> Shawn/Owens | H20: =G20-F20 -> 0 | M20: 0 | N20: 0 | O20: 0 | P20: 0 | Q20: 0 | R20: 0 | S20: 0 | T20: 0 | U20: 0 | V20: 0 | W20: 0 | X20: 0 | Y20: =SUM(M20:P20) -> 0 | Z20: =SUM(Q20:U20) -> 0 | AA20: =SUM(M20:N20) -> 0 | AB20: =SUM(Q20:R20,U20) -> 0 | AC20: 0.13
A21: 43210 | B21: 2004 | C21: 2035 | D21: =CHOOSE(WEEKDAY(A21),"Fred/Anne", "Jane", "Phil","Sue/Panos","Shawn/Owens","Jeff", "Rob") -> Jeff | H21: =G21-F21 -> 0 | M21: 0 | N21: 0 | O21: 0 | P21: 0 | Q21: 0 | R21: 0 | S21: 0 | T21: 0 | U21: 0 | V21: 0 | W21: 0 | X21: 0 | Y21: =SUM(M21:P21) -> 0 | Z21: =SUM(Q21:U21) -> 0 | AA21: =SUM(M21:N21) -> 0 | AB21: =SUM(Q21:R21,U21) -> 0 | AC21: 0.22
A22: 43211 | B22: 2005 | C22: 2037 | D22: =CHOOSE(WEEKDAY(A22),"Fred/Anne", "Jane", "Phil","Sue/Panos","Shawn/Owens","Jeff", "Rob") -> Rob | H22: =G22-F22 -> 0 | M22: 0 | N22: 0 | O22: 0 | P22: 0 | Q22: 0 | R22: 0 | S22: 0 | T22: 0 | U22: 0 | V22: 0 | W22: 0 | X22: 0 | Y22: =SUM(M22:P22) -> 0 | Z22: =SUM(Q22:U22) -> 0 | AA22: =SUM(M22:N22) -> 0 | AB22: =SUM(Q22:R22,U22) -> 0 | AC22: 0.32
A23: 43212 | B23: 2006 | C23: 2038 | D23: =CHOOSE(WEEKDAY(A23),"Fred/Anne", "Jane", "Phil","Sue/Panos","Shawn/Owens","Jeff", "Rob") -> Fred/Anne | H23: =G23-F23 -> 0 | M23: 0 | N23: 0 | O23: 0 | P23: 0 | Q23: 0 | R23: 0 | S23: 0 | T23: 0 | U23: 0 | V23: 0 | W23: 0 | X23: 0 | Y23: =SUM(M23:P23) -> 0 | Z23: =SUM(Q23:U23) -> 0 | AA23: =SUM(M23:N23) -> 0 | AB23: =SUM(Q23:R23,U23) -> 0 | AC23: 0.44
A24: 43213 | B24: 2007 | C24: 2039 | D24: =CHOOSE(WEEKDAY(A24),"Fred/Anne", "Jane", "Phil","Sue/Panos","Shawn/Owens","Jeff", "Rob") -> Jane | H24: =G24-F24 -> 0 | M24: 0 | N24: 0 | O24: 0 | P24: 0 | Q24: 0 | R24: 0 | S24: 0 | T24: 0 | U24: 0 | V24: 0 | W24: 0 | X24: 0 | Y24: =SUM(M24:P24) -> 0 | Z24: =SUM(Q24:U24) -> 0 | AA24: =SUM(M24:N24) -> 0 | AB24: =SUM(Q24:R24,U24) -> 0 | AC24: 0.55
A25: 43214 | B25: 2009 | C25: 2041 | D25: =CHOOSE(WEEKDAY(A25),"Fred/Anne", "Jane", "Phil/Tom","Sue/Panos","Shawn/Owens","Jeff", "Rob") -> Phil/Tom | H25: =G25-F25 -> 0 | M25: 0 | N25: 0 | O25: 0 | P25: 0 | Q25: 0 | R25: 0 | S25: 0 | T25: 0 | U25: 0 | V25: 0 | W25: 0 | X25: 0 | Y25: =SUM(M25:P25) -> 0 | Z25: =SUM(Q25:U25) -> 0 | AA25: =SUM(M25:N25) -> 0 | AB25: =SUM(Q25:R25,U25) -> 0 | AC25: 0.66
A26: 43215 | B26: 2010 | C26: 2042 | D26: =CHOOSE(WEEKDAY(A26),"Fred/Anne", "Jane", "Phil","Sue/Panos","Shawn/Owens","Jeff", "Rob") -> Sue/Panos | H26: =G26-F26 -> 0 | M26: 0 | N26: 0 | O26: 0 | P26: 0 | Q26: 0 | R26: 0 | S26: 0 | T26: 0 | U26: 0 | V26: 0 | W26: 0 | X26: 0 | Y26: =SUM(M26:P26) -> 0 | Z26: =SUM(Q26:U26) -> 0 | AA26: =SUM(M26:N26) -> 0 | AB26: =SUM(Q26:R26,U26) -> 0 | AC26: 0.76
A27: 43216 | B27: 2011 | C27: 2044 | D27: =CHOOSE(WEEKDAY(A27),"Fred/Anne", "Jane", "Phil","Sue/Panos","Shawn/Owens","Jeff", "Rob") -> Shawn/Owens | H27: =G27-F27 -> 0 | M27: 0 | N27: 0 | O27: 0 | P27: 0 | Q27: 0 | R27: 0 | S27: 0 | T27: 0 | U27: 0 | V27: 0 | W27: 0 | X27: 0 | Y27: =SUM(M27:P27) -> 0 | Z27: =SUM(Q27:U27) -> 0 | AA27: =SUM(M27:N27) -> 0 | AB27: =SUM(Q27:R27,U27) -> 0 | AC27: 0.85
A28: 43217 | B28: 2013 | C28: 2045 | D28: =CHOOSE(WEEKDAY(A28),"Fred/Anne", "Jane", "Phil","Sue/Panos","Shawn/Owens","Jeff", "Rob") -> Jeff | H28: =G28-F28 -> 0 | M28: 0 | N28: 0 | O28: 0 | P28: 0 | Q28: 0 | R28: 0 | S28: 0 | T28: 0 | U28: 0 | V28: 0 | W28: 0 | X28: 0 | Y28: =SUM(M28:P28) -> 0 | Z28: =SUM(Q28:U28) -> 0 | AA28: =SUM(M28:N28) -> 0 | AB28: =SUM(Q28:R28,U28) -> 0 | AC28: 0.92
A29: 43218 | B29: 2014 | C29: 2046 | D29: =CHOOSE(WEEKDAY(A29),"Fred/Anne", "Jane", "Phil","Sue/Panos","Shawn/Owens","Jeff", "Rob") -> Rob | H29: =G29-F29 -> 0 | M29: 0 | N29: 0 | O29: 0 | P29: 0 | Q29: 0 | R29: 0 | S29: 0 | T29: 0 | U29: 0 | V29: 0 | W29: 0 | X29: 0 | Y29: =SUM(M29:P29) -> 0 | Z29: =SUM(Q29:U29) -> 0 | AA29: =SUM(M29:N29) -> 0 | AB29: =SUM(Q29:R29,U29) -> 0 | AC29: 0.97
A30: 43219 | B30: 2015 | C30: 2048 | D30: =CHOOSE(WEEKDAY(A30),"Fred/Anne", "Jane", "Phil","Sue/Panos","Shawn/Owens","Jeff", "Rob") -> Fred/Anne | H30: =G30-F30 -> 0 | M30: 0 | N30: 0 | O30: 0 | P30: 0 | Q30: 0 | R30: 0 | S30: 0 | T30: 0 | U30: 0 | V30: 0 | W30: 0 | X30: 0 | Y30: =SUM(M30:P30) -> 0 | Z30: =SUM(Q30:U30) -> 0 | AA30: =SUM(M30:N30) -> 0 | AB30: =SUM(Q30:R30,U30) -> 0 | AC30: 0.99
A31: 43220 | B31: 2016 | C31: 2049 | D31: =CHOOSE(WEEKDAY(A31),"Fred/Anne", "Jane", "Phil","Sue/Panos","Shawn/Owens","Jeff", "Rob") -> Jane | H31: =G31-F31 -> 0 | M31: 0 | N31: 0 | O31: 0 | P31: 0 | Q31: 0 | R31: 0 | S31: 0 | T31: 0 | U31: 0 | V31: 0 | W31: 0 | X31: 0 | Y31: =SUM(M31:P31) -> 0 | Z31: =SUM(Q31:U31) -> 0 | AA31: =SUM(M31:N31) -> 0 | AB31: =SUM(Q31:R31,U31) -> 0 | AC31: 1
A32: xx/xx/xxxx | B32: xxxx | C32: xxxx | H32: =G32-F32 -> 0 | M32: xxxx | N32: xxxx | O32: xxxx | P32: xxxx | Q32: xxxx | R32: xxxx | S32: xxxx | T32: xxxx | U32: xxxx | V32: xxxx | W32: xxxx | X32: xxxx | Y32: xxxx | Z32: xxxx | AA32: xxxx | AB32: xxxx | AC32: x
E33: Monthly total | H33: =SUM(H3:H32) -> 0.47222222 | I33: =SUM(I2:I32) -> 52 | M33: =SUM(M2:M32) -> 0 | N33: =SUM(N2:N32) -> 0 | O33: =SUM(O2:O32) -> 0 | P33: =SUM(P2:P32) -> 1 | Q33: =SUM(Q2:Q32) -> 11 | R33: =SUM(R2:R32) -> 21 | S33: =SUM(S2:S32) -> 0 | T33: =SUM(T2:T32) -> 1 | ... AB33: =SUM(AB2:AB32) -> 36
E34: Cumulative Total | H34: ='November 2017'!H$33+'December 2017'!H$33+'January 2018'!H$33+'February 2018'!H$33+'March 2018'!H$33+'April 2018'!H$33 -> 5.1930556 | I34: ='November 2017'!I$33+'December 2017'!I$33+'January 2018'!I$33+'February 2018'!I$33+'March 2018'!I$33+'April 2018'!I$33 -> 486.30986 | M34: ='November 2017'!M$33+'December 2017'!M$33+'January 2018'!M$33+'February 2018'!M$33+'March 2018'!M$33+'April 2018'!M$33 -> 135 | N34: ='November 2017'!N$33+'December 2017'!N$33+'January 2018'!N$33+'February 2018'!N$33+'March 2018'!N$33+'April 2018'!N$33 -> 281 | O34: ='November 2017'!O$33+'December 2017'!O$33+'January 2018'!O$33+'February 2018'!O$33+'March 2018'!O$33+'April 2018'!O$33 -> 7 | P34: ='November 2017'!P$33+'December 2017'!P$33+'January 2018'!P$33+'February 2018'!P$33+'March 2018'!P$33+'April 2018'!P$33 -> 10 | Q34: ='November 2017'!Q$33+'December 2017'!Q$33+'January 2018'!Q$33+'February 2018'!Q$33+'March 2018'!Q$33+'April 2018'!Q$33 -> 104 | R34: ='November 2017'!R$33+'December 2017'!R$33+'January 2018'!R$33+'February 2018'!R$33+'March 2018'!R$33+'April 2018'!R$33 -> 165 | S34: ='November 2017'!S$33+'December 2017'!S$33+'January 2018'!S$33+'February 2018'!S$33+'March 2018'!S$33+'April 2018'!S$33 -> 9 | T34: ='November 2017'!T$33+'December 2017'!T$33+'January 2018'!T$33+'February 2018'!T$33+'March 2018'!T$33+'April 2018'!T$33 -> 7 | ... Z34: ='November 2017'!Z$33+'December 2017'!Z$33+'January 2018'!Z$33+'February 2018'!Z$33+'March 2018'!Z$33+'April 2018'!Z$33 -> 297 | AA34: ='November 2017'!AA33+'December 2017'!AA33+'January 2018'!AA33+'February 2018'!AA33+'March 2018'!AA33+'April 2018'!AA33 -> 416 | AB34: ='November 2017'!AB33+'December 2017'!AB33+'January 2018'!AB33+'February 2018'!AB33+'March 2018'!AB33+'April 2018'!AB33 -> 282
E35: Season Total | H35: ='November 2017'!H$33+'December 2017'!H$33+'January 2018'!H$33+'February 2018'!H$33+'March 2018'!H$33+'April 2018'!H$33 -> 5.1930556 | I35: ='November 2017'!I33+'December 2017'!I33+'January 2018'!I33+'February 2018'!I33+'March 2018'!I33+'April 2018'!I33 -> 486.30986 | M35: ='November 2017'!M33+'December 2017'!M33+'January 2018'!M33+'February 2018'!M33+'March 2018'!M33+'April 2018'!M33 -> 135 | N35: ='November 2017'!N33+'December 2017'!N33+'January 2018'!N33+'February 2018'!N33+'March 2018'!N33+'April 2018'!N33 -> 281 | O35: ='November 2017'!O33+'December 2017'!O33+'January 2018'!O33+'February 2018'!O33+'March 2018'!O33+'April 2018'!O33 -> 7 | P35: ='November 2017'!P33+'December 2017'!P33+'January 2018'!P33+'February 2018'!P33+'March 2018'!P33+'April 2018'!P33 -> 10 | Q35: ='November 2017'!Q33+'December 2017'!Q33+'January 2018'!Q33+'February 2018'!Q33+'March 2018'!Q33+'April 2018'!Q33 -> 104 | R35: ='November 2017'!R33+'December 2017'!R33+'January 2018'!R33+'February 2018'!R33+'March 2018'!R33+'April 2018'!R33 -> 165 | S35: ='November 2017'!S33+'December 2017'!S33+'January 2018'!S33+'February 2018'!S33+'March 2018'!S33+'April 2018'!S33 -> 9 | T35: ='November 2017'!T33+'December 2017'!T33+'January 2018'!T33+'February 2018'!T33+'March 2018'!T33+'April 2018'!T33 -> 7 | ... AB35: ='November 2017'!AB33+'December 2017'!AB33+'January 2018'!AB33+'February 2018'!AB33+'March 2018'!AB33+'April 2018'!AB33 -> 282
E36: 2016-17 Total | Y36: 834 | Z36: 751
E37: 2015-16 Total | Y37: 688 | Z37: 1040
E38: 2014-15 Total | Y38: 695 | Z38: 750
E39: 2013-14 Total | M39: 135 | N39: 281 | O39: 7 | P39: 10 | Q39: 104 | R39: 165 | S39: 9 | T39: 7 | Y39: 580 | Z39: 572

Sheet Sheet22

Sheet November 2017
A1: Date | B1: Sunset | C1: Civil Twilight | D1: Captain | E1: Monitored (Y/N) | F1: Start time HH:MM | G1: End time HH:MM | H1: Hours Monitored | I1: Team Hrs. | J1: Start Temp | K1: End Temp | L1: Weather | M1: Females assisted down | N1: Males assisted down | O1: Females unassisted down | P1: Males unassisted down | Q1: Females assisted up | R1: Males assisted up | S1: Females unassisted up | T1: Males unassisted up | U1: Juveniles | V1: Roadkills female | W1: Roadkills male | X1: Roadkills unk | Y1: Total Frogs down | Z1: Total Frogs up | AA1: Total Frogs Assisted Down | AB1: Total Frogs Assisted Up | AC1: % moon visible | AD1: Comments
A2: 43040 | B2: 1657 | C2: 1728 | H2: =G2-F2 -> 0 | M2: 0 | N2: 0 | O2: 0 | P2: 0 | Q2: 0 | R2: 0 | S2: 0 | T2: 0 | U2: 0 | V2: 0 | W2: 0 | X2: 0 | Y2: =SUM(M2:P2) -> 0 | Z2: =SUM(Q2:U2) -> 0 | AA2: =SUM(M2:N2) -> 0 | AB2: =SUM(Q2:R2,U2) -> 0 | AC2: 0.89
A3: 43041 | B3: 1656 | C3: 1727 | D3: =CHOOSE(WEEKDAY(A3),"Fred/Anne", "Jane", "Phil","Sue/Panos","Shawn/Orem","Jeff", "Rob") -> Shawn/Orem | H3: =G3-F3 -> 0 | M3: 0 | N3: 0 | O3: 0 | P3: 0 | Q3: 0 | R3: 0 | S3: 0 | T3: 0 | U3: 0 | V3: 0 | W3: 0 | X3: 0 | Y3: =SUM(M3:P3) -> 0 | Z3: =SUM(Q3:U3) -> 0 | AA3: =SUM(M3:N3) -> 0 | AB3: =SUM(Q3:R3,U3) -> 0 | AC3: 0.95
A4: 43042 | B4: 1654 | C4: 1725 | D4: =CHOOSE(WEEKDAY(A4),"Fred/Anne", "Jane", "Phil","Sue/Panos","Shawn/Owens","Jeff", "Rob") -> Jeff | H4: =G4-F4 -> 0 | M4: 0 | N4: 0 | O4: 0 | P4: 0 | Q4: 0 | R4: 0 | S4: 0 | T4: 0 | U4: 0 | V4: 0 | W4: 0 | X4: 0 | Y4: =SUM(M4:P4) -> 0 | Z4: =SUM(Q4:U4) -> 0 | AA4: =SUM(M4:N4) -> 0 | AB4: =SUM(Q4:R4,U4) -> 0 | AC4: 0.99
A5: 43043 | B5: 1653 | C5: 1724 | D5: =CHOOSE(WEEKDAY(A5),"Fred/Anne", "Jane", "Phil","Sue/Panos","Shawn/Owens","Jeff", "Rob") -> Rob | H5: =G5-F5 -> 0 | M5: 0 | N5: 0 | O5: 0 | P5: 0 | Q5: 0 | R5: 0 | S5: 0 | T5: 0 | U5: 0 | V5: 0 | W5: 0 | X5: 0 | Y5: =SUM(M5:P5) -> 0 | Z5: =SUM(Q5:U5) -> 0 | AA5: =SUM(M5:N5) -> 0 | AB5: =SUM(Q5:R5,U5) -> 0 | AC5: 1
A6: 43044 | B6: 1652 | C6: 1723 | D6: =CHOOSE(WEEKDAY(A6),"Fred/Anne", "Jane", "Phil","Sue/Panos","Shawn/Owens","Jeff", "Rob") -> Fred/Anne | H6: =G6-F6 -> 0 | M6: 0 | N6: 0 | O6: 0 | P6: 0 | Q6: 0 | R6: 0 | S6: 0 | T6: 0 | U6: 0 | V6: 0 | W6: 0 | X6: 0 | Y6: =SUM(M6:P6) -> 0 | Z6: =SUM(Q6:U6) -> 0 | AA6: =SUM(M6:N6) -> 0 | AB6: =SUM(Q6:R6,U6) -> 0 | AC6: 0.98
A7: 43045 | B7: 1650 | C7: 1722 | D7: =CHOOSE(WEEKDAY(A7),"Fred/Anne", "Jane", "Phil","Sue/Panos","Shawn/Owens","Jeff", "Rob") -> Jane | H7: =G7-F7 -> 0 | M7: 0 | N7: 0 | O7: 0 | P7: 0 | Q7: 0 | R7: 0 | S7: 0 | T7: 0 | U7: 0 | V7: 0 | W7: 0 | X7: 0 | Y7: =SUM(M7:P7) -> 0 | Z7: =SUM(Q7:U7) -> 0 | AA7: =SUM(M7:N7) -> 0 | AB7: =SUM(Q7:R7,U7) -> 0 | AC7: 0.93
A8: 43046 | B8: 1649 | C8: 1720 | D8: =CHOOSE(WEEKDAY(A8),"Fred/Anne", "Jane", "Phil","Sue/Panos","Shawn/Owens","Jeff", "Rob") -> Phil | H8: =G8-F8 -> 0 | M8: 0 | N8: 0 | O8: 0 | P8: 0 | Q8: 0 | R8: 0 | S8: 0 | T8: 0 | U8: 0 | V8: 0 | W8: 0 | X8: 0 | Y8: =SUM(M8:P8) -> 0 | Z8: =SUM(Q8:U8) -> 0 | AA8: =SUM(M8:N8) -> 0 | AB8: =SUM(Q8:R8,U8) -> 0 | AC8: 0.86
A9: 43047 | B9: 1648 | C9: 1719 | D9: =CHOOSE(WEEKDAY(A9),"Fred/Anne", "Jane", "Phil","Sue/Panos","Shawn/Owens","Jeff", "Rob") -> Sue/Panos | E9: y | F9: 0.70833333 | G9: 0.70833333 | H9: =G9-F9 -> 0 | J9: 43 | L9: wet | M9: 0 | N9: 0 | O9: 0 | P9: 0 | Q9: 0 | R9: 0 | S9: 0 | T9: 0 | U9: 0 | V9: 0 | W9: 0 | X9: 0 | Y9: =SUM(M9:P9) -> 0 | Z9: =SUM(Q9:U9) -> 0 | AA9: =SUM(M9:N9) -> 0 | AB9: =SUM(Q9:R9,U9) -> 0 | AC9: 0.77 | AD9: Rob's checking
A10: 43048 | B10: 1647 | C10: 1718 | D10: =CHOOSE(WEEKDAY(A10),"Fred/Anne", "Jane", "Phil","Sue/Panos","Shawn/Orem","Jeff", "Rob") -> Shawn/Orem | E10: y | F10: 0.72916667 | G10: 0.72916667 | H10: =G10-F10 -> 0 | J10: 49 | L10: showery | M10: 0 | N10: 0 | O10: 0 | P10: 0 | Q10: 0 | R10: 0 | S10: 0 | T10: 0 | U10: 0 | V10: 0 | W10: 0 | X10: 0 | Y10: =SUM(M10:P10) -> 0 | Z10: =SUM(Q10:U10) -> 0 | AA10: =SUM(M10:N10) -> 0 | AB10: =SUM(Q10:R10,U10) -> 0 | AC10: 0.67 | AD10: ditto
A11: 43049 | B11: 1645 | C11: 1717 | D11: =CHOOSE(WEEKDAY(A11),"Fred/Anne", "Jane", "Phil","Sue/Panos","Shawn/Owens","Jeff", "Rob") -> Jeff | E11: Y | F11: 0.72916667 | G11: 0.77638889 | H11: =G11-F11 -> 0.047222222 | I11: 1.13 | J11: 49 | K11: 49 | L11: overcast, not raining, pvmnt wet | M11: 0 | N11: 0 | O11: 0 | P11: 0 | Q11: 0 | R11: 0 | S11: 0 | T11: 0 | U11: 0 | V11: 0 | W11: 0 | X11: 0 | Y11: =SUM(M11:P11) -> 0 | Z11: =SUM(Q11:U11) -> 0 | AA11: =SUM(M11:N11) -> 0 | AB11: =SUM(Q11:R11,U11) -> 0 | AC11: 0.56 | AD11: ditto - Hrborton / Jeff checked
A12: 43050 | B12: 1644 | C12: 1716 | D12: =CHOOSE(WEEKDAY(A12),"Fred/Anne", "Jane", "Phil","Sue/Panos","Shawn/Owens","Jeff", "Rob") -> Rob | E12: Y | F12: 0.72916667 | G12: 0.77083333 | H12: =G12-F12 -> 0.041666667 | I12: 1 | J12: 48 | K12: 48 | L12: wet pavement, intermittent drizzle | M12: 1 | N12: 0 | O12: 0 | P12: 0 | Q12: 0 | R12: 0 | S12: 0 | T12: 0 | U12: 0 | V12: 0 | W12: 0 | X12: 0 | Y12: =SUM(M12:P12) -> 1 | Z12: =SUM(Q12:U12) -> 0 | AA12: =SUM(M12:N12) -> 1 | AB12: =SUM(Q12:R12,U12) -> 0 | AC12: 0.45 | AD12: Maggie caught a frog in the ditch
A13: 43051 | B13: 1643 | C13: 1715 | D13: =CHOOSE(WEEKDAY(A13),"Fred/Anne", "Jane", "Phil","Sue/Panos","Shawn/Owens","Jeff", "Rob") -> Fred/Anne | E13: y | F13: 0.70833333 | G13: 0.73958333 | H13: =G13-F13 -> 0.03125 | J13: 50 | K13: 50 | L13: wet pavement | M13: 0 | N13: 0 | O13: 0 | P13: 0 | Q13: 0 | R13: 0 | S13: 0 | T13: 0 | U13: 0 | V13: 0 | W13: 0 | X13: 0 | Y13: =SUM(M13:P13) -> 0 | Z13: =SUM(Q13:U13) -> 0 | AA13: =SUM(M13:N13) -> 0 | AB13: =SUM(Q13:R13,U13) -> 0 | AC13: 0.34 | AD13: Rob checked
A14: 43052 | B14: 1642 | C14: 1714 | D14: =CHOOSE(WEEKDAY(A14),"Fred/Anne", "Jane", "Phil","Sue/Panos","Shawn/Owens","Jeff", "Rob") -> Jane | E14: y | F14: 0.21875 | G14: 0.22916667 | H14: =G14-F14 -> 0.010416667 | I14: 0.15 | J14: 48 | L14: drying pavement | M14: 0 | N14: 0 | O14: 0 | P14: 0 | Q14: 0 | R14: 0 | S14: 0 | T14: 0 | U14: 0 | V14: 0 | W14: 0 | X14: 0 | Y14: =SUM(M14:P14) -> 0 | Z14: =SUM(Q14:U14) -> 0 | AA14: =SUM(M14:N14) -> 0 | AB14: =SUM(Q14:R14,U14) -> 0 | AC14: 0.25 | AD14: ditto
A15: 43053 | B15: 1641 | C15: 1713 | D15: =CHOOSE(WEEKDAY(A15),"Fred/Anne", "Jane", "Phil","Sue/Panos","Shawn/Owens","Jeff", "Rob") -> Phil | E15: y | F15: 0.83333333 | G15: 0.84722222 | H15: =G15-F15 -> 0.013888889 | L15: light rain / wet pavement | M15: 0 | N15: 0 | O15: 0 | P15: 0 | Q15: 0 | R15: 0 | S15: 0 | T15: 0 | U15: 0 | V15: 0 | W15: 0 | X15: 0 | Y15: =SUM(M15:P15) -> 0 | Z15: =SUM(Q15:U15) -> 0 | AA15: =SUM(M15:N15) -> 0 | AB15: =SUM(Q15:R15,U15) -> 0 | AC15: 0.16 | AD15: met with John earlier, went home, returned when rain seemed to pick up.
A16: 43054 | B16: 1640 | C16: 1712 | D16: =CHOOSE(WEEKDAY(A16),"Fred/Anne", "Jane", "Phil","Sue/Panos","Shawn/Owens","Jeff", "Rob") -> Sue/Panos | E16: Y | F16: 0.72916667 | G16: 0.72916667 | H16: =G16-F16 -> 0 | J16: 44 | K16: 44 | L16: light rain / wet pavement | M16: 0 | N16: 0 | O16: 0 | P16: 0 | Q16: 0 | R16: 0 | S16: 0 | T16: 0 | U16: 0 | V16: 0 | W16: 0 | X16: 0 | Y16: =SUM(M16:P16) -> 0 | Z16: =SUM(Q16:U16) -> 0 | AA16: =SUM(M16:N16) -> 0 | AB16: =SUM(Q16:R16,U16) -> 0 | AC16: 0.1 | AD16: Sue, Rob, & Panos checked
A17: 43055 | B17: 1639 | C17: 1711 | D17: =CHOOSE(WEEKDAY(A17),"Fred/Anne", "Jane", "Phil","Sue/Panos","Shawn/Orem","Jeff", "Rob") -> Shawn/Orem | E17: y | F17: 0.70833333 | G17: 0.72916667 | H17: =G17-F17 -> 0.020833333 | J17: 42 | L17: wet pavemnt, intermittent drizzle | M17: 0 | N17: 0 | O17: 0 | P17: 0 | Q17: 0 | R17: 0 | S17: 0 | T17: 0 | U17: 0 | V17: 0 | W17: 0 | X17: 0 | Y17: =SUM(M17:P17) -> 0 | Z17: =SUM(Q17:U17) -> 0 | AA17: =SUM(M17:N17) -> 0 | AB17: =SUM(Q17:R17,U17) -> 0 | AC17: 0.05 | AD17: John checked
A18: 43056 | B18: 1638 | C18: 1710 | D18: =CHOOSE(WEEKDAY(A18),"Fred/Anne", "Jane", "Phil","Sue/Panos","Shawn/Owens","Jeff", "Rob") -> Jeff | E18: N | H18: =G18-F18 -> 0 | M18: 0 | N18: 0 | O18: 0 | P18: 0 | Q18: 0 | R18: 0 | S18: 0 | T18: 0 | U18: 0 | V18: 0 | W18: 0 | X18: 0 | Y18: =SUM(M18:P18) -> 0 | Z18: =SUM(Q18:U18) -> 0 | AA18: =SUM(M18:N18) -> 0 | AB18: =SUM(Q18:R18,U18) -> 0 | AC18: 0.01
A19: 43057 | B19: 1637 | C19: 1709 | D19: =CHOOSE(WEEKDAY(A19),"Fred/Anne", "Jane", "Phil","Sue/Panos","Shawn/Owens","Jeff", "Rob") -> Rob | E19: n | H19: =G19-F19 -> 0 | L19: dry | M19: 0 | N19: 0 | O19: 0 | P19: 0 | Q19: 0 | R19: 0 | S19: 0 | T19: 0 | U19: 0 | V19: 0 | W19: 0 | X19: 0 | Y19: =SUM(M19:P19) -> 0 | Z19: =SUM(Q19:U19) -> 0 | AA19: =SUM(M19:N19) -> 0 | AB19: =SUM(Q19:R19,U19) -> 0 | AC19: 0
A20: 43058 | B20: 1636 | C20: 1709 | D20: =CHOOSE(WEEKDAY(A20),"Fred/Anne", "Jane", "Phil","Sue/Panos","Shawn/Owens","Jeff", "Rob") -> Fred/Anne | E20: Y | F20: 0.70833333 | G20: 0.75 | H20: =G20-F20 -> 0.041666667 | I20: 4.3 | J20: 44 | K20: 44 | L20: Dry. Rain predicted. Check later | M20: 0 | N20: 0 | O20: 0 | P20: 0 | Q20: 0 | R20: 0 | S20: 0 | T20: 0 | U20: 0 | V20: 0 | W20: 0 | X20: 0 | Y20: =SUM(M20:P20) -> 0 | Z20: =SUM(Q20:U20) -> 0 | AA20: =SUM(M20:N20) -> 0 | AB20: =SUM(Q20:R20,U20) -> 0 | AC20: 0.01 | AD20: Checked again at 8 after an hour of steady rain. Nothing. Temp 44.
A21: 43059 | B21: 1635 | C21: 1708 | D21: =CHOOSE(WEEKDAY(A21),"Fred/Anne", "Jane", "Phil","Sue/Panos","Shawn/Owens","Jeff", "Rob") -> Jane | E21: Y | H21: =G21-F21 -> 0 | I21: 0.3 | J21: 48 | K21: 46 | L21: Moist air, very light rain later | M21: 0 | N21: 0 | O21: 0 | P21: 0 | Q21: 0 | R21: 0 | S21: 0 | T21: 0 | U21: 0 | V21: 0 | W21: 0 | X21: 0 | Y21: =SUM(M21:P21) -> 0 | Z21: =SUM(Q21:U21) -> 0 | AA21: =SUM(M21:N21) -> 0 | AB21: =SUM(Q21:R21,U21) -> 0 | AC21: 0.03 | AD21: Checked at 6:15 and 9 and 2:45 AM.
A22: 43060 | B22: 1634 | C22: 1707 | D22: =CHOOSE(WEEKDAY(A22),"Fred/Anne", "Jane", "Phil","Sue/Panos","Shawn/Owens","Jeff", "Rob") -> Phil | E22: Y | F22: 0.70833333 | G22: 0.875 | H22: =G22-F22 -> 0.16666667 | I22: 10.75 | J22: 52 | K22: 52 | L22: Rain | M22: 2 | N22: 2 | O22: 0 | P22: 0 | Q22: 0 | R22: 0 | S22: 0 | T22: 0 | U22: 0 | V22: 0 | W22: 0 | X22: 0 | Y22: =SUM(M22:P22) -> 4 | Z22: =SUM(Q22:U22) -> 0 | AA22: =SUM(M22:N22) -> 4 | AB22: =SUM(Q22:R22,U22) -> 0 | AC22: 0.07 | AD22: warm rain. found first male just after 7pm in pothole puddle at bottom of Harborton.
A23: 43061 | B23: 1634 | C23: 1706 | D23: =CHOOSE(WEEKDAY(A23),"Fred/Anne", "Jane", "Phil","Sue/Panos","Shawn/Owens","Jeff", "Rob") -> Sue/Panos | E23: Y | F23: 0.70833333 | G23: 0.875 | H23: =G23-F23 -> 0.16666667 | I23: 20.1 | J23: 57 | K23: 59 | L23: mist / wet pavement / showers | M23: 0 | N23: 5 | O23: 0 | P23: 0 | Q23: 0 | R23: 0 | S23: 0 | T23: 0 | U23: 0 | V23: 0 | W23: 1 | X23: 0 | Y23: =SUM(M23:P23) -> 5 | Z23: =SUM(Q23:U23) -> 0 | AA23: =SUM(M23:N23) -> 5 | AB23: =SUM(Q23:R23,U23) -> 0 | AC23: 0.13 | AD23: Panos captured first 3 frogs within 15 mins during short mist event right after dusk.
A24: 43062 | B24: 1633 | C24: 1706 | D24: =CHOOSE(WEEKDAY(A24),"Fred/Anne", "Jane", "Phil","Sue/Panos","Shawn/Orem","Jeff", "Rob") -> Shawn/Orem | E24: Y | F24: 0.75 | G24: 0.76041667 | H24: =G24-F24 -> 0.010416667 | I24: 0.25 | J24: 52 | L24: Dry (Still dry 9:30 PM) | M24: 0 | N24: 0 | O24: 0 | P24: 0 | Q24: 0 | R24: 0 | S24: 0 | T24: 0 | U24: 0 | V24: 0 | W24: 0 | X24: 0 | Y24: =SUM(M24:P24) -> 0 | Z24: =SUM(Q24:U24) -> 0 | AA24: =SUM(M24:N24) -> 0 | AB24: =SUM(Q24:R24,U24) -> 0 | AC24: 0.2 | AD24: No rain since late morning.
A25: 43063 | B25: 1632 | C25: 1705 | D25: =CHOOSE(WEEKDAY(A25),"Fred/Anne", "Jane", "Phil","Sue/Panos","Shawn/Owens","Jeff", "Rob") -> Jeff | E25: Y | F25: 0.72222222 | G25: 0.73263889 | H25: =G25-F25 -> 0.010416667 | I25: 0.25 | J25: 46 | K25: 46 | L25: Dry pvmnt, clear skies | M25: 0 | N25: 0 | O25: 0 | P25: 0 | Q25: 0 | R25: 0 | S25: 0 | T25: 0 | U25: 0 | V25: 0 | W25: 0 | X25: 0 | Y25: =SUM(M25:P25) -> 0 | Z25: =SUM(Q25:U25) -> 0 | AA25: =SUM(M25:N25) -> 0 | AB25: =SUM(Q25:R25,U25) -> 0 | AC25: 0.28 | AD25: 8PM, 45, no frogs
A26: 43064 | B26: 1632 | C26: 1705 | D26: =CHOOSE(WEEKDAY(A26),"Fred/Anne", "Jane", "Phil","Sue/Panos","Shawn/Owens","Jeff", "Rob") -> Rob | E26: y | F26: 0.69791667 | G26: 0.73958333 | H26: =G26-F26 -> 0.041666667 | I26: 2 | J26: 46 | K26: 46 | L26: showery tapering off | M26: 0 | N26: 0 | O26: 0 | P26: 0 | Q26: 0 | R26: 0 | S26: 0 | T26: 0 | U26: 0 | V26: 0 | W26: 0 | X26: 0 | Y26: =SUM(M26:P26) -> 0 | Z26: =SUM(Q26:U26) -> 0 | AA26: =SUM(M26:N26) -> 0 | AB26: =SUM(Q26:R26,U26) -> 0 | AC26: 0.37
A27: 43065 | B27: 1631 | C27: 1704 | D27: =CHOOSE(WEEKDAY(A27),"Fred/Anne", "Jane", "Phil","Sue/Panos","Shawn/Owens","Jeff", "Rob") -> Fred/Anne | H27: =G27-F27 -> 0 | M27: 0 | N27: 0 | O27: 0 | P27: 0 | Q27: 0 | R27: 0 | S27: 0 | T27: 0 | U27: 0 | V27: 0 | W27: 0 | X27: 0 | Y27: =SUM(M27:P27) -> 0 | Z27: =SUM(Q27:U27) -> 0 | AA27: =SUM(M27:N27) -> 0 | AB27: =SUM(Q27:R27,U27) -> 0 | AC27: 0.46
A28: 43066 | B28: 1630 | C28: 1704 | D28: =CHOOSE(WEEKDAY(A28),"Fred/Anne", "Jane", "Phil","Sue/Panos","Shawn/Owens","Jeff", "Rob") -> Jane | E28: N | H28: =G28-F28 -> 0 | J28: 45 | L28: Dry pavement | M28: 0 | N28: 0 | O28: 0 | P28: 0 | Q28: 0 | R28: 0 | S28: 0 | T28: 0 | U28: 0 | V28: 0 | W28: 0 | X28: 0 | Y28: =SUM(M28:P28) -> 0 | Z28: =SUM(Q28:U28) -> 0 | AA28: =SUM(M28:N28) -> 0 | AB28: =SUM(Q28:R28,U28) -> 0 | AC28: 0.56
A29: 43067 | B29: 1630 | C29: 1703 | D29: =CHOOSE(WEEKDAY(A29),"Fred/Anne", "Jane", "Phil","Sue/Panos","Shawn/Owens","Jeff", "Rob") -> Phil | E29: y | F29: 0.6875 | G29: 0.72916667 | H29: =G29-F29 -> 0.041666667 | I29: 1 | J29: ? | K29: ? | L29: wet pavement. no rain. | M29: 0 | N29: 0 | O29: 0 | P29: 0 | Q29: 0 | R29: 0 | S29: 0 | T29: 0 | U29: 0 | V29: 0 | W29: 0 | X29: 0 | Y29: =SUM(M29:P29) -> 0 | Z29: =SUM(Q29:U29) -> 0 | AA29: =SUM(M29:N29) -> 0 | AB29: =SUM(Q29:R29,U29) -> 0 | AC29: 0.66 | AD29: temperature for "Linnton, OR" seems to be malfunctioning on Weather Underground.
A30: 43068 | B30: 1629 | C30: 1703 | D30: =CHOOSE(WEEKDAY(A30),"Fred/Anne", "Jane", "Phil","Sue/Panos","Shawn/Owens","Jeff", "Rob") -> Sue/Panos | E30: N | H30: =G30-F30 -> 0 | J30: 44 | L30: Dry pavement, no rain | M30: 0 | N30: 0 | O30: 0 | P30: 0 | Q30: 0 | R30: 0 | S30: 0 | T30: 0 | U30: 0 | V30: 0 | W30: 0 | X30: 0 | Y30: =SUM(M30:P30) -> 0 | Z30: =SUM(Q30:U30) -> 0 | AA30: =SUM(M30:N30) -> 0 | AB30: =SUM(Q30:R30,U30) -> 0 | AC30: 0.76
A31: 43069 | B31: 1629 | C31: 1702 | D31: =CHOOSE(WEEKDAY(A31),"Fred/Anne", "Jane", "Phil","Sue/Panos","Shawn/Orem","Jeff", "Rob") -> Shawn/Orem | E31: Y | F31: 0.20138889 | G31: 0.21180556 | H31: =G31-F31 -> 0.010416667 | I31: 0.5 | J31: 44 | K31: 43 | L31: Wet pavement, no rain. | M31: 0 | N31: 0 | O31: 0 | P31: 0 | Q31: 0 | R31: 0 | S31: 0 | T31: 0 | U31: 0 | V31: 0 | W31: 0 | X31: 0 | Y31: =SUM(M31:P31) -> 0 | Z31: =SUM(Q31:U31) -> 0 | AA31: =SUM(M31:N31) -> 0 | AB31: =SUM(Q31:R31,U31) -> 0 | AC31: 0.85
A32: XX/XX/XX | C32: 1702 | W32: x | X32: x | Y32: x | Z32: x | AC32: x
E33: Monthly total | H33: =SUM(H2:H32) -> 0.65486111 | I33: =SUM(I2:I32) -> 41.73 | M33: =SUM(M2:M32) -> 3 | N33: =SUM(N2:N32) -> 7 | O33: =SUM(O2:O32) -> 0 | P33: =SUM(P2:P32) -> 0 | Q33: =SUM(Q2:Q32) -> 0 | R33: =SUM(R2:R32) -> 0 | S33: =SUM(S2:S32) -> 0 | T33: =SUM(T2:T32) -> 0 | ... AB33: =SUM(AB2:AB32) -> 0
E34: Cumulative Total | H34: ='November 2017'!H$33 -> 0.65486111 | I34: ='November 2017'!I$33 -> 41.73 | M34: ='November 2017'!M$33 -> 3 | N34: ='November 2017'!N$33 -> 7 | O34: ='November 2017'!O$33 -> 0 | P34: ='November 2017'!P$33 -> 0 | Q34: ='November 2017'!Q$33 -> 0 | R34: ='November 2017'!R$33 -> 0 | S34: ='November 2017'!S$33 -> 0 | T34: ='November 2017'!T$33 -> 0 | ... AA34: ='November 2017'!AA$33 -> 10 | AB34: ='November 2017'!AB33 -> 0
E35: Season Total | H35: ='November 2017'!H$33+'December 2017'!H$33+'January 2018'!H$33+'February 2018'!H$33+'March 2018'!H$33+'April 2018'!H$33 -> 5.1930556 | I35: ='November 2017'!I33+'December 2017'!I33+'January 2018'!I33+'February 2018'!I33+'March 2018'!I33+'April 2018'!I33 -> 486.30986 | M35: ='November 2017'!M33+'December 2017'!M33+'January 2018'!M33+'February 2018'!M33+'March 2018'!M33+'April 2018'!M33 -> 135 | N35: ='November 2017'!N33+'December 2017'!N33+'January 2018'!N33+'February 2018'!N33+'March 2018'!N33+'April 2018'!N33 -> 281 | O35: ='November 2017'!O33+'December 2017'!O33+'January 2018'!O33+'February 2018'!O33+'March 2018'!O33+'April 2018'!O33 -> 7 | P35: ='November 2017'!P33+'December 2017'!P33+'January 2018'!P33+'February 2018'!P33+'March 2018'!P33+'April 2018'!P33 -> 10 | Q35: ='November 2017'!Q33+'December 2017'!Q33+'January 2018'!Q33+'February 2018'!Q33+'March 2018'!Q33+'April 2018'!Q33 -> 104 | R35: ='November 2017'!R33+'December 2017'!R33+'January 2018'!R33+'February 2018'!R33+'March 2018'!R33+'April 2018'!R33 -> 165 | S35: ='November 2017'!S33+'December 2017'!S33+'January 2018'!S33+'February 2018'!S33+'March 2018'!S33+'April 2018'!S33 -> 9 | T35: ='November 2017'!T33+'December 2017'!T33+'January 2018'!T33+'February 2018'!T33+'March 2018'!T33+'April 2018'!T33 -> 7 | ... AB35: ='November 2017'!AB33+'December 2017'!AB33+'January 2018'!AB33+'February 2018'!AB33+'March 2018'!AB33+'April 2018'!AB33 -> 282
E36: 2016-17 Total | Y36: 834 | Z36: 751
E37: 2015-16 Total | Y37: 688 | Z37: 1040
E38: 2014-15 Total | Y38: 695 | Z38: 750
E39: 2013-14 Total | Y39: 580 | Z39: 572
A40: 43107 | B40: 1645 | D40: Fred/Anne | E40: Y | F40: 4;45 | G40: 6;15 | H40: 0.0625 | J40: 45 | K40: 44.2 | L40: Rain | M40: 0 | N40: 0

Sheet December 2017
A1: Date | B1: Sunset | C1: Civil Twilight | D1: Captain | E1: Monitored (Y/N) | F1: Start time HH:MM | G1: End time HH:MM | H1: Hours Monitored | I1: Team Hrs. | J1: Start Temp | K1: End Temp | L1: Weather | M1: Females assisted down | N1: Males assisted down | O1: Females unassisted down | P1: Males unassisted down | Q1: Females assisted up | R1: Males assisted up | S1: Females unassisted up | T1: Males unassisted up | U1: Juveniles | V1: Roadkills female | W1: Roadkills male | X1: Roadkills unk | Y1: Total Frogs down | Z1: Total Frogs up | AA1: Total Frogs Assisted Down | AB1: Total Frogs Assisted Up | AC1: % moon visible | AD1: Comments
A2: 43070 | B2: 1629 | C2: 1702 | D2: =CHOOSE(WEEKDAY(A2),"Fred/Anne", "Jane", "Phil","Sue/Panos","Shawn/Owens","Jeff", "Rob") -> Jeff | E2: Y | F2: 0.72916667 | G2: 0.80208333 | H2: =G2-F2 -> 0.072916667 | I2: 1.75 | J2: 47 | K2: 46 | L2: Light rain | M2: 0 | N2: 0 | O2: 0 | P2: 0 | Q2: 0 | R2: 0 | S2: 0 | T2: 0 | U2: 0 | V2: 0 | W2: 0 | X2: 0 | Y2: =SUM(M2:P2) -> 0 | Z2: =SUM(Q2:U2) -> 0 | AA2: =SUM(M2:N2) -> 0 | AB2: =SUM(Q2:R2,U2) -> 0 | AC2: 0.92 | AD2: Heard chorus frog at bottom of Harborton.
A3: 43071 | B3: 1628 | C3: 1702 | D3: =CHOOSE(WEEKDAY(A3),"Fred/Anne", "Jane", "Phil","Sue/Panos","Shawn/Owens","Jeff", "Rob") -> Rob | E3: y | F3: 0.70833333 | G3: 0.75 | H3: =G3-F3 -> 0.041666667 | I3: 1 | J3: 44 | K3: 42 | L3: showery on & off | M3: 0 | N3: 0 | O3: 0 | P3: 0 | Q3: 0 | R3: 0 | S3: 0 | T3: 0 | U3: 0 | V3: 0 | W3: 0 | X3: 0 | Y3: =SUM(M3:P3) -> 0 | Z3: =SUM(Q3:U3) -> 0 | AA3: =SUM(M3:N3) -> 0 | AB3: =SUM(Q3:R3,U3) -> 0 | AC3: 0.97
A4: 43072 | B4: 1628 | C4: 1702 | D4: =CHOOSE(WEEKDAY(A4),"Fred/Anne", "Jane", "Phil","Sue/Panos","Shawn/Owens","Jeff", "Rob") -> Fred/Anne | E4: Y | F4: 0.70486111 | G4: 0.71527778 | H4: =G4-F4 -> 0.010416667 | I4: 0.25 | J4: 41 | K4: 41 | L4: dry partial clear/cloud | M4: 0 | N4: 0 | O4: 0 | P4: 0 | Q4: 0 | R4: 0 | S4: 0 | T4: 0 | U4: 0 | V4: 0 | W4: 0 | X4: 0 | Y4: =SUM(M4:P4) -> 0 | Z4: =SUM(Q4:U4) -> 0 | AA4: =SUM(M4:N4) -> 0 | AB4: =SUM(Q4:R4,U4) -> 0 | AC4: 1 | AD4: road somewhat moist but no puddles/wetness
A5: 43073 | B5: 1628 | C5: 1701 | D5: =CHOOSE(WEEKDAY(A5),"Fred/Anne", "Jane", "Phil","Sue/Panos","Shawn/Owens","Jeff", "Rob") -> Jane | E5: N | H5: =G5-F5 -> 0 | I5: 0 | J5: 44 | L5: dry | M5: 0 | N5: 0 | O5: 0 | P5: 0 | Q5: 0 | R5: 0 | S5: 0 | T5: 0 | U5: 0 | V5: 0 | W5: 0 | X5: 0 | Y5: =SUM(M5:P5) -> 0 | Z5: =SUM(Q5:U5) -> 0 | AA5: =SUM(M5:N5) -> 0 | AB5: =SUM(Q5:R5,U5) -> 0 | AC5: 0.99
A6: 43074 | B6: 1627 | C6: 1701 | D6: =CHOOSE(WEEKDAY(A6),"Fred/Anne", "Jane", "Phil/Tom","Sue/Panos","Shawn/Owens","Jeff", "Rob") -> Phil/Tom | E6: N | F6: 0.70833333 | G6: 0.70833333 | H6: =G6-F6 -> 0 | I6: 0 | J6: 45 | K6: 45 | L6: Clear, dry, and cold | M6: 0 | N6: 0 | O6: 0 | P6: 0 | Q6: 0 | R6: 0 | S6: 0 | T6: 0 | U6: 0 | V6: 0 | W6: 0 | X6: 0 | Y6: =SUM(M6:P6) -> 0 | Z6: =SUM(Q6:U6) -> 0 | AA6: =SUM(M6:N6) -> 0 | AB6: =SUM(Q6:R6,U6) -> 0 | AC6: 0.96
A7: 43075 | B7: 1627 | C7: 1701 | D7: =CHOOSE(WEEKDAY(A7),"Fred/Anne", "Jane", "Phil","Sue/Panos","Shawn/Owens","Jeff", "Rob") -> Sue/Panos | E7: N | F7: 0.70833333 | G7: 0.70833333 | H7: =G7-F7 -> 0 | J7: 48 | K7: 48 | L7: Clear and dry | M7: 0 | N7: 0 | O7: 0 | P7: 0 | Q7: 0 | R7: 0 | S7: 0 | T7: 0 | U7: 0 | V7: 0 | W7: 0 | X7: 0 | Y7: =SUM(M7:P7) -> 0 | Z7: =SUM(Q7:U7) -> 0 | AA7: =SUM(M7:N7) -> 0 | AB7: =SUM(Q7:R7,U7) -> 0 | AC7: 0.9
A8: 43076 | B8: 1627 | C8: 1701 | D8: =CHOOSE(WEEKDAY(A8),"Fred/Anne", "Jane", "Phil","Sue/Panos","Shawn/Orem","Jeff", "Rob") -> Shawn/Orem | E8: N | F8: 0.70833333 | G8: 0.70833333 | H8: =G8-F8 -> 0 | J8: 42 | L8: Clear, dry, cold. | M8: 0 | N8: 0 | O8: 0 | P8: 0 | Q8: 0 | R8: 0 | S8: 0 | T8: 0 | U8: 0 | V8: 0 | W8: 0 | X8: 0 | Y8: =SUM(M8:P8) -> 0 | Z8: =SUM(Q8:U8) -> 0 | AA8: =SUM(M8:N8) -> 0 | AB8: =SUM(Q8:R8,U8) -> 0 | AC8: 0.81
A9: 43077 | B9: 1627 | C9: 1701 | D9: =CHOOSE(WEEKDAY(A9),"Fred/Anne", "Jane", "Phil","Sue/Panos","Shawn/Owens","Jeff", "Rob") -> Jeff | E9: N | F9: 0.77083333 | G9: 0.77083333 | H9: =G9-F9 -> 0 | I9: 0 | J9: 39 | L9: Clear, dry and cold. | M9: 0 | N9: 0 | O9: 0 | P9: 0 | Q9: 0 | R9: 0 | S9: 0 | T9: 0 | U9: 0 | V9: 0 | W9: 0 | X9: 0 | Y9: =SUM(M9:P9) -> 0 | Z9: =SUM(Q9:U9) -> 0 | AA9: =SUM(M9:N9) -> 0 | AB9: =SUM(Q9:R9,U9) -> 0 | AC9: 0.71
A10: 43078 | B10: 1627 | C10: 1701 | D10: =CHOOSE(WEEKDAY(A10),"Fred/Anne", "Jane", "Phil","Sue/Panos","Shawn/Owens","Jeff", "Rob") -> Rob | E10: n | H10: =G10-F10 -> 0 | J10: 39 | L10: Clear, dry, cold. | M10: 0 | N10: 0 | O10: 0 | P10: 0 | Q10: 0 | R10: 0 | S10: 0 | T10: 0 | U10: 0 | V10: 0 | W10: 0 | X10: 0 | Y10: =SUM(M10:P10) -> 0 | Z10: =SUM(Q10:U10) -> 0 | AA10: =SUM(M10:N10) -> 0 | AB10: =SUM(Q10:R10,U10) -> 0 | AC10: 0.61
A11: 43079 | B11: 1627 | C11: 1701 | D11: =CHOOSE(WEEKDAY(A11),"Fred/Anne", "Jane", "Phil","Sue/Panos","Shawn/Owens","Jeff", "Rob") -> Fred/Anne | E11: N | F11: 0.70833333 | G11: 0.70833333 | H11: =G11-F11 -> 0 | J11: 38 | L11: Clear, dry and cold. | M11: 0 | N11: 0 | O11: 0 | P11: 0 | Q11: 0 | R11: 0 | S11: 0 | T11: 0 | U11: 0 | V11: 0 | W11: 0 | X11: 0 | Y11: =SUM(M11:P11) -> 0 | Z11: =SUM(Q11:U11) -> 0 | AA11: =SUM(M11:N11) -> 0 | AB11: =SUM(Q11:R11,U11) -> 0 | AC11: 0.5
A12: 43080 | B12: 1627 | C12: 1701 | D12: =CHOOSE(WEEKDAY(A12),"Fred/Anne", "Jane", "Phil","Sue/Panos","Shawn/Owens","Jeff", "Rob") -> Jane | E12: N | H12: =G12-F12 -> 0 | I12: 0 | J12: 36 | L12: Clear, dry and cold. | M12: 0 | N12: 0 | O12: 0 | P12: 0 | Q12: 0 | R12: 0 | S12: 0 | T12: 0 | U12: 0 | V12: 0 | W12: 0 | X12: 0 | Y12: =SUM(M12:P12) -> 0 | Z12: =SUM(Q12:U12) -> 0 | AA12: =SUM(M12:N12) -> 0 | AB12: =SUM(Q12:R12,U12) -> 0 | AC12: 0.4
A13: 43081 | B13: 1627 | C13: 1701 | D13: =CHOOSE(WEEKDAY(A13),"Fred/Anne", "Jane", "Phil/Tom","Sue/Panos","Shawn/Owens","Jeff", "Rob") -> Phil/Tom | E13: N | F13: 0.70833333 | G13: 0.70833333 | H13: =G13-F13 -> 0 | I13: 0 | J13: 40 | K13: 40 | L13: Clear, dry, and cold | M13: 0 | N13: 0 | O13: 0 | P13: 0 | Q13: 0 | R13: 0 | S13: 0 | T13: 0 | U13: 0 | V13: 0 | W13: 0 | X13: 0 | Y13: =SUM(M13:P13) -> 0 | Z13: =SUM(Q13:U13) -> 0 | AA13: =SUM(M13:N13) -> 0 | AB13: =SUM(Q13:R13,U13) -> 0 | AC13: 0.3
A14: 43082 | B14: 1627 | C14: 1701 | D14: =CHOOSE(WEEKDAY(A14),"Fred/Anne", "Jane", "Phil","Sue/Panos","Shawn/Owens","Jeff", "Rob") -> Sue/Panos | E14: N | F14: 0.70833333 | G14: 0.70833333 | H14: =G14-F14 -> 0 | J14: 39 | K14: 39 | L14: Mostly clear, dry, cold | M14: 0 | N14: 0 | O14: 0 | P14: 0 | Q14: 0 | R14: 0 | S14: 0 | T14: 0 | U14: 0 | V14: 0 | W14: 0 | X14: 0 | Y14: =SUM(M14:P14) -> 0 | Z14: =SUM(Q14:U14) -> 0 | AA14: =SUM(M14:N14) -> 0 | AB14: =SUM(Q14:R14,U14) -> 0 | AC14: 0.21
A15: 43083 | B15: 1627 | C15: 1702 | D15: =CHOOSE(WEEKDAY(A15),"Fred/Anne", "Jane", "Phil","Sue/Panos","Shawn/Orem","Jeff", "Rob") -> Shawn/Orem | E15: N | F15: 0.70833333 | G15: 0.70833333 | H15: =G15-F15 -> 0 | J15: 40 | L15: Clear, dry, cold. | M15: 0 | N15: 0 | O15: 0 | P15: 0 | Q15: 0 | R15: 0 | S15: 0 | T15: 0 | U15: 0 | V15: 0 | W15: 0 | X15: 0 | Y15: =SUM(M15:P15) -> 0 | Z15: =SUM(Q15:U15) -> 0 | AA15: =SUM(M15:N15) -> 0 | AB15: =SUM(Q15:R15,U15) -> 0 | AC15: 0.14
A16: 43084 | B16: 1628 | C16: 1702 | D16: =CHOOSE(WEEKDAY(A16),"Fred/Anne", "Jane", "Phil","Sue/Panos","Shawn/Owens","Jeff", "Rob") -> Jeff | E16: N | F16: 0.70833333 | G16: 0.70833333 | H16: =G16-F16 -> 0 | I16: 0 | J16: 39 | K16: 39 | L16: Partially cloudy, dry | M16: 0 | N16: 0 | O16: 0 | P16: 0 | Q16: 0 | R16: 0 | S16: 0 | T16: 0 | U16: 0 | V16: 0 | W16: 0 | X16: 0 | Y16: =SUM(M16:P16) -> 0 | Z16: =SUM(Q16:U16) -> 0 | AA16: =SUM(M16:N16) -> 0 | AB16: =SUM(Q16:R16,U16) -> 0 | AC16: 0.08
A17: 43085 | B17: 1628 | C17: 1702 | D17: =CHOOSE(WEEKDAY(A17),"Fred/Anne", "Jane", "Phil","Sue/Panos","Shawn/Owens","Jeff", "Rob") -> Rob | E17: y | F17: 0.69791667 | G17: 0.71875 | H17: =G17-F17 -> 0.020833333 | I17: 0.5 | J17: 42 | K17: 41 | L17: misty, cold | M17: 0 | N17: 0 | O17: 0 | P17: 0 | Q17: 0 | R17: 0 | S17: 0 | T17: 0 | U17: 0 | V17: 0 | W17: 0 | X17: 0 | Y17: =SUM(M17:P17) -> 0 | Z17: =SUM(Q17:U17) -> 0 | AA17: =SUM(M17:N17) -> 0 | AB17: =SUM(Q17:R17,U17) -> 0 | AC17: 0.04
A18: 43086 | B18: 1628 | C18: 1703 | D18: =CHOOSE(WEEKDAY(A18),"Fred/Anne", "Jane", "Phil","Sue/Panos","Shawn/Owens","Jeff", "Rob") -> Fred/Anne | E18: Y | F18: 0.70138889 | G18: 0.75 | H18: =G18-F18 -> 0.048611111 | I18: 1.1 | J18: 46 | K18: 41 | L18: dry, cold | M18: 0 | N18: 0 | O18: 0 | P18: 0 | Q18: 0 | R18: 0 | S18: 0 | T18: 0 | U18: 0 | V18: 0 | W18: 0 | X18: 0 | Y18: =SUM(M18:P18) -> 0 | Z18: =SUM(Q18:U18) -> 0 | AA18: =SUM(M18:N18) -> 0 | AB18: =SUM(Q18:R18,U18) -> 0 | AC18: 0.01
A19: 43087 | B19: 1629 | C19: 1703 | D19: =CHOOSE(WEEKDAY(A19),"Fred/Anne", "Jane", "Phil","Sue/Panos","Shawn/Owens","Jeff", "Rob") -> Jane | E19: Y | F19: 0.69444444 | G19: 0.85416667 | H19: =G19-F19 -> 0.15972222 | I19: 0.46527778 | J19: 49 | K19: 48 | L19: light rain, then just mist | M19: 0 | N19: 1 | O19: 0 | P19: 0 | Q19: 0 | R19: 0 | S19: 0 | T19: 0 | U19: 0 | V19: 0 | W19: 0 | X19: 0 | Y19: =SUM(M19:P19) -> 1 | Z19: =SUM(Q19:U19) -> 0 | AA19: =SUM(M19:N19) -> 1 | AB19: =SUM(Q19:R19,U19) -> 0 | AC19: 0 | AD19: Checked Harborton at 6;20 a.m. to see if there was any evidence of movement after rain started at 5 a.m., but there was not.
A20: 43088 | B20: 1629 | C20: 1703 | D20: =CHOOSE(WEEKDAY(A20),"Fred/Anne", "Jane", "Phil/Tom","Sue/Panos","Shawn/Owens","Jeff", "Rob") -> Phil/Tom | E20: Y | F20: 0.64583333 | G20: 0.69791667 | H20: =G20-F20 -> 0.052083333 | I20: 7 | J20: 40 | K20: 40 | L20: steady rain and cold | M20: 0 | N20: 0 | O20: 0 | P20: 0 | Q20: 0 | R20: 0 | S20: 0 | T20: 0 | U20: 0 | V20: 0 | W20: 0 | X20: 0 | Y20: =SUM(M20:P20) -> 0 | Z20: =SUM(Q20:U20) -> 0 | AA20: =SUM(M20:N20) -> 0 | AB20: =SUM(Q20:R20,U20) -> 0 | AC20: 0.01
A21: 43089 | B21: 1630 | C21: 1704 | D21: =CHOOSE(WEEKDAY(A21),"Fred/Anne", "Jane", "Phil","Sue/Panos","Shawn/Owens","Jeff", "Rob") -> Sue/Panos | E21: N | F21: 0.70833333 | G21: 0.70833333 | H21: =G21-F21 -> 0 | J21: 42 | K21: 42 | L21: Partially cloudy | M21: 0 | N21: 0 | O21: 0 | P21: 0 | Q21: 0 | R21: 0 | S21: 0 | T21: 0 | U21: 0 | V21: 0 | W21: 0 | X21: 0 | Y21: =SUM(M21:P21) -> 0 | Z21: =SUM(Q21:U21) -> 0 | AA21: =SUM(M21:N21) -> 0 | AB21: =SUM(Q21:R21,U21) -> 0 | AC21: 0.04
A22: 43090 | B22: 1630 | C22: 1704 | D22: =CHOOSE(WEEKDAY(A22),"Fred/Anne", "Jane", "Phil","Sue/Panos","Shawn/Orem","Jeff", "Rob") -> Shawn/Orem | E22: N | F22: 0.70833333 | G22: 0.70833333 | H22: =G22-F22 -> 0 | J22: 33 | L22: Foggy, cold. | M22: 0 | N22: 0 | O22: 0 | P22: 0 | Q22: 0 | R22: 0 | S22: 0 | T22: 0 | U22: 0 | V22: 0 | W22: 0 | X22: 0 | Y22: =SUM(M22:P22) -> 0 | Z22: =SUM(Q22:U22) -> 0 | AA22: =SUM(M22:N22) -> 0 | AB22: =SUM(Q22:R22,U22) -> 0 | AC22: 0.08
A23: 43091 | B23: 1631 | C23: 1705 | D23: =CHOOSE(WEEKDAY(A23),"Fred/Anne", "Jane", "Phil","Sue/Panos","Shawn/Owens","Jeff", "Rob") -> Jeff | E23: N | H23: =G23-F23 -> 0 | J23: 37 | L23: Light rain | M23: 0 | N23: 0 | O23: 0 | P23: 0 | Q23: 0 | R23: 0 | S23: 0 | T23: 0 | U23: 0 | V23: 0 | W23: 0 | X23: 0 | Y23: =SUM(M23:P23) -> 0 | Z23: =SUM(Q23:U23) -> 0 | AA23: =SUM(M23:N23) -> 0 | AB23: =SUM(Q23:R23,U23) -> 0 | AC23: 0.14
A24: 43092 | B24: 1631 | C24: 1705 | D24: =CHOOSE(WEEKDAY(A24),"Fred/Anne", "Jane", "Phil","Sue/Panos","Shawn/Owens","Jeff", "Rob") -> Rob | E24: n | H24: =G24-F24 -> 0 | J24: 34 | L24: winter mix | M24: 0 | N24: 0 | O24: 0 | P24: 0 | Q24: 0 | R24: 0 | S24: 0 | T24: 0 | U24: 0 | V24: 0 | W24: 0 | X24: 0 | Y24: =SUM(M24:P24) -> 0 | Z24: =SUM(Q24:U24) -> 0 | AA24: =SUM(M24:N24) -> 0 | AB24: =SUM(Q24:R24,U24) -> 0 | AC24: 0.21
A25: 43093 | B25: 1632 | C25: 1706 | D25: =CHOOSE(WEEKDAY(A25),"Fred/Anne", "Jane", "Phil","Sue/Panos","Shawn/Owens","Jeff", "Rob") -> Fred/Anne | H25: =G25-F25 -> 0 | M25: 0 | N25: 0 | O25: 0 | P25: 0 | Q25: 0 | R25: 0 | S25: 0 | T25: 0 | U25: 0 | V25: 0 | W25: 0 | X25: 0 | Y25: =SUM(M25:P25) -> 0 | Z25: =SUM(Q25:U25) -> 0 | AA25: =SUM(M25:N25) -> 0 | AB25: =SUM(Q25:R25,U25) -> 0 | AC25: 0.3
A26: 43094 | B26: 1632 | C26: 1707 | D26: =CHOOSE(WEEKDAY(A26),"Fred/Anne", "Jane", "Phil","Sue/Panos","Shawn/Owens","Jeff", "Rob") -> Jane | E26: N | F26: 0.70833333 | G26: 0.70833333 | H26: =G26-F26 -> 0 | J26: 31 | L26: Dry | M26: 0 | N26: 0 | O26: 0 | P26: 0 | Q26: 0 | R26: 0 | S26: 0 | T26: 0 | U26: 0 | V26: 0 | X26: 0 | Y26: =SUM(M26:P26) -> 0 | Z26: =SUM(Q26:U26) -> 0 | AA26: =SUM(M26:N26) -> 0 | AB26: =SUM(Q26:R26,U26) -> 0 | AC26: 0.39
A27: 43095 | B27: 1633 | C27: 1707 | D27: =CHOOSE(WEEKDAY(A27),"Fred/Anne", "Jane", "Phil/Tom","Sue/Panos","Shawn/Owens","Jeff", "Rob") -> Phil/Tom | E27: N | H27: =G27-F27 -> 0 | J27: 33 | M27: 0 | N27: 0 | O27: 0 | P27: 0 | Q27: 0 | R27: 0 | S27: 0 | T27: 0 | U27: 0 | V27: 0 | W27: 0 | X27: 0 | Y27: =SUM(M27:P27) -> 0 | Z27: =SUM(Q27:U27) -> 0 | AA27: =SUM(M27:N27) -> 0 | AB27: =SUM(Q27:R27,U27) -> 0 | AC27: 0.5
A28: 43096 | B28: 1634 | C28: 1708 | D28: =CHOOSE(WEEKDAY(A28),"Fred/Anne", "Jane", "Phil","Sue/Panos","Shawn/Owens","Jeff", "Rob") -> Sue/Panos | E28: N | F28: 0.70833333 | G28: 0.70833333 | H28: =G28-F28 -> 0 | J28: 34 | K28: 34 | L28: Overcast, foggy, cold | M28: 0 | N28: 0 | O28: 0 | P28: 0 | Q28: 0 | R28: 0 | S28: 0 | T28: 0 | U28: 0 | V28: 0 | W28: 0 | X28: 0 | Y28: =SUM(M28:P28) -> 0 | Z28: =SUM(Q28:U28) -> 0 | AA28: =SUM(M28:N28) -> 0 | AB28: =SUM(Q28:R28,U28) -> 0 | AC28: 0.6
A29: 43097 | B29: 1635 | C29: 1709 | D29: =CHOOSE(WEEKDAY(A29),"Fred/Anne", "Jane", "Phil","Sue/Panos","Shawn/Orem","Jeff", "Rob") -> Shawn/Orem | E29: Y | F29: 0.6875 | G29: 0.97916667 | H29: =G29-F29 -> 0.29166667 | I29: 18 | J29: 45 | K29: 48 | L29: Rain, to light rain | M29: 0 | N29: 36 | O29: 0 | P29: 0 | Q29: 0 | R29: 0 | S29: 0 | T29: 0 | U29: 0 | V29: 0 | W29: 1 | X29: 0 | Y29: =SUM(M29:P29) -> 36 | Z29: =SUM(Q29:U29) -> 0 | AA29: =SUM(M29:N29) -> 36 | AB29: =SUM(Q29:R29,U29) -> 0 | AC29: 0.7 | AD29: plus 2 long-toed salamanders
A30: 43098 | B30: 1635 | C30: 1710 | D30: =CHOOSE(WEEKDAY(A30),"Fred/Anne", "Jane", "Phil","Sue/Panos","Shawn/Owens","Jeff", "Rob") -> Jeff | E30: Y | F30: 0.6875 | G30: 0.91666667 | H30: =G30-F30 -> 0.22916667 | I30: 30.7 | J30: 51 | K30: 46 | L30: Rain to clearing | M30: 20 | N30: 160 | O30: 0 | P30: 1 | Q30: 0 | R30: 0 | S30: 0 | T30: 0 | U30: 0 | V30: 0 | W30: 2 | X30: 0 | Y30: =SUM(M30:P30) -> 181 | Z30: =SUM(Q30:U30) -> 0 | AA30: =SUM(M30:N30) -> 180 | AB30: =SUM(Q30:R30,U30) -> 0 | AC30: 0.8
A31: 43099 | B31: 1636 | C31: 1710 | D31: =CHOOSE(WEEKDAY(A31),"Fred/Anne", "Jane", "Phil","Sue/Panos","Shawn/Owens","Jeff", "Rob") -> Rob | E31: y | F31: 0.69791667 | G31: 0.72916667 | H31: =G31-F31 -> 0.03125 | I31: 1.25 | J31: 42 | K31: 38 | L31: Damp, clear sky | M31: 0 | N31: 0 | O31: 0 | P31: 0 | Q31: 0 | R31: 0 | S31: 0 | T31: 0 | U31: 0 | V31: 0 | W31: 0 | X31: 0 | Y31: =SUM(M31:P31) -> 0 | Z31: =SUM(Q31:U31) -> 0 | AA31: =SUM(M31:N31) -> 0 | AB31: =SUM(Q31:R31,U31) -> 0 | AC31: 0.89
A32: 43100 | B32: 1637 | C32: 1711 | D32: =CHOOSE(WEEKDAY(A32),"Fred/Anne", "Jane", "Phil","Sue/Panos","Shawn/Owens","Jeff", "Rob") -> Fred/Anne | E32: Y | F32: 0.70833333 | G32: 0.71875 | H32: =G32-F32 -> 0.010416667 | J32: 39 | K32: 39 | L32: Dry; Full Moon | M32: 0 | N32: 0 | O32: 0 | P32: 0 | Q32: 0 | R32: 0 | S32: 0 | T32: 0 | U32: 0 | V32: 0 | W32: 0 | X32: 0 | Y32: =SUM(M32:P32) -> 0 | Z32: =SUM(Q32:U32) -> 0 | AA32: =SUM(M32:N32) -> 0 | AB32: =SUM(Q32:R32,U32) -> 0 | AC32: 0.95 | AD32: Walked road 1X; no sign of road kill or action.
E33: Monthly total | H33: =SUM(H3:H32) -> 0.89583333 | I33: =SUM(I2:I32) -> 62.015278 | M33: =SUM(M2:M32) -> 20 | N33: =SUM(N2:N32) -> 197 | O33: =SUM(O2:O32) -> 0 | P33: =SUM(P2:P32) -> 1 | Q33: =SUM(Q2:Q32) -> 0 | R33: =SUM(R2:R32) -> 0 | S33: =SUM(S2:S32) -> 0 | T33: =SUM(T2:T32) -> 0 | ... AB33: =SUM(AB2:AB32) -> 0
E34: Cumulative Total | H34: ='November 2017'!H$33+'December 2017'!H$33 -> 1.5506944 | I34: ='November 2017'!I$33+'December 2017'!I$33 -> 103.74528 | M34: ='November 2017'!M$33+'December 2017'!M$33 -> 23 | N34: ='November 2017'!N$33+'December 2017'!N$33 -> 204 | O34: ='November 2017'!O$33+'December 2017'!O$33 -> 0 | P34: ='November 2017'!P$33+'December 2017'!P$33 -> 1 | Q34: ='November 2017'!Q$33+'December 2017'!Q$33 -> 0 | R34: ='November 2017'!R$33+'December 2017'!R$33 -> 0 | S34: ='November 2017'!S$33+'December 2017'!S$33 -> 0 | T34: ='November 2017'!T$33+'December 2017'!T$33 -> 0 | ... Z34: ='November 2017'!Z$33+'December 2017'!Z$33 -> 0 | AA34: ='November 2017'!AA33+'December 2017'!AA33 -> 227 | AB34: ='November 2017'!AB33+'December 2017'!AB33 -> 0
E35: Season Total | H35: ='November 2017'!H$33+'December 2017'!H$33+'January 2018'!H$33+'February 2018'!H$33+'March 2018'!H$33+'April 2018'!H$33 -> 5.1930556 | I35: ='November 2017'!I33+'December 2017'!I33+'January 2018'!I33+'February 2018'!I33+'March 2018'!I33+'April 2018'!I33 -> 486.30986 | M35: ='November 2017'!M33+'December 2017'!M33+'January 2018'!M33+'February 2018'!M33+'March 2018'!M33+'April 2018'!M33 -> 135 | N35: ='November 2017'!N33+'December 2017'!N33+'January 2018'!N33+'February 2018'!N33+'March 2018'!N33+'April 2018'!N33 -> 281 | O35: ='November 2017'!O33+'December 2017'!O33+'January 2018'!O33+'February 2018'!O33+'March 2018'!O33+'April 2018'!O33 -> 7 | P35: ='November 2017'!P33+'December 2017'!P33+'January 2018'!P33+'February 2018'!P33+'March 2018'!P33+'April 2018'!P33 -> 10 | Q35: ='November 2017'!Q33+'December 2017'!Q33+'January 2018'!Q33+'February 2018'!Q33+'March 2018'!Q33+'April 2018'!Q33 -> 104 | R35: ='November 2017'!R33+'December 2017'!R33+'January 2018'!R33+'February 2018'!R33+'March 2018'!R33+'April 2018'!R33 -> 165 | S35: ='November 2017'!S33+'December 2017'!S33+'January 2018'!S33+'February 2018'!S33+'March 2018'!S33+'April 2018'!S33 -> 9 | T35: ='November 2017'!T33+'December 2017'!T33+'January 2018'!T33+'February 2018'!T33+'March 2018'!T33+'April 2018'!T33 -> 7 | ... AB35: ='November 2017'!AB33+'December 2017'!AB33+'January 2018'!AB33+'February 2018'!AB33+'March 2018'!AB33+'April 2018'!AB33 -> 282
E36: 2016-17 Total | Y36: 834 | Z36: 751
E37: 2015-16 Total | Y37: 688 | Z37: 1040
E38: 2014-15 Total | Y38: 695 | Z38: 750
E39: 2013-14 Total | Y39: 580 | Z39: 572

Sheet January 2018
A1: Date | B1: Sunset | C1: Civil Twilight | D1: Captain | E1: Monitored (Y/N) | F1: Start time HH:MM | G1: End time HH:MM | H1: Hours monitored | I1: Team Hrs. | J1: Start Temp. | K1: End Temp | L1: Weather | M1: Females assisted down | N1: Males assisted down | O1: Unassisted Females down | P1: Unasissted Males down | Q1: Females assisted up | R1: Males assisted up | S1: Unassisted females up | T1: Unassisted males up | U1: Juveniles | V1: Roadkill Females | W1: Roadkill Males | X1: Roadkill Unk | Y1: Total frogs down | Z1: Total frogs up | AA1: Total Frogs Assisted Down | AB1: Total Frogs Assisted Up | AD1: Comments
A2: 43101 | B2: 1638 | C2: 1712 | D2: =CHOOSE(WEEKDAY(A2),"Fred/Anne", "Jane", "Phil","Sue/Panos","Shawn/Owens","Jeff", "Rob") -> Jane | E2: N | F2: 0.70833333 | G2: 0.70833333 | H2: =G2-F2 -> 0 | I2: 0 | J2: 35 | K2: 35 | L2: Dry | M2: 0 | N2: 0 | O2: 0 | P2: 0 | Q2: 0 | R2: 0 | S2: 0 | T2: 0 | U2: 0 | V2: 0 | W2: 0 | X2: 0 | Y2: =SUM(M2:P2) -> 0 | Z2: =SUM(Q2:U2) -> 0 | AA2: =SUM(M2:N2) -> 0 | AB2: =SUM(Q2:R2,U2) -> 0
A3: 43102 | B3: 1639 | C3: 1713 | D3: =CHOOSE(WEEKDAY(A3),"Fred/Anne", "Jane", "Phil/Tom","Sue/Panos","Shawn/Owens","Jeff", "Rob") -> Phil/Tom | E3: N | F3: 0.70833333 | G3: 0.70833333 | H3: =G3-F3 -> 0 | I3: 0 | J3: 39 | K3: 39 | L3: dry | M3: 0 | N3: 0 | O3: 0 | P3: 0 | Q3: 0 | R3: 0 | S3: 0 | T3: 0 | U3: 0 | V3: 0 | W3: 0 | X3: 0 | Y3: =SUM(M3:P3) -> 0 | Z3: =SUM(Q3:U3) -> 0 | AA3: =SUM(M3:N3) -> 0 | AB3: =SUM(Q3:R3,U3) -> 0
A4: 43103 | B4: 1640 | C4: 1714 | D4: =CHOOSE(WEEKDAY(A4),"Fred/Anne", "Jane", "Phil","Sue/Panos","Shawn/Owens","Jeff", "Rob") -> Sue/Panos | E4: N | F4: 0.70833333 | G4: 0.70833333 | H4: =G4-F4 -> 0 | I4: 0 | J4: 37 | K4: 37 | L4: Dry & clear sky | M4: 0 | N4: 0 | O4: 0 | P4: 0 | Q4: 0 | R4: 0 | S4: 0 | T4: 0 | U4: 0 | V4: 0 | W4: 0 | X4: 0 | Y4: =SUM(M4:P4) -> 0 | Z4: =SUM(Q4:U4) -> 0 | AA4: =SUM(M4:N4) -> 0 | AB4: =SUM(Q4:R4,U4) -> 0
A5: 43104 | B5: 1641 | C5: 1715 | D5: =CHOOSE(WEEKDAY(A5),"Fred/Anne", "Jane", "Phil","Sue/Panos","Shawn/Orem","Jeff", "Rob") -> Shawn/Orem | E5: Y | F5: 0.71180556 | G5: 0.73263889 | H5: =G5-F5 -> 0.020833333 | I5: 0.5 | J5: 44 | K5: 42 | L5: Light rain | M5: 0 | N5: 0 | O5: 0 | P5: 0 | Q5: 0 | R5: 0 | S5: 0 | T5: 0 | U5: 0 | V5: 0 | W5: 0 | X5: 0 | Y5: =SUM(M5:P5) -> 0 | Z5: =SUM(Q5:U5) -> 0 | AA5: =SUM(M5:N5) -> 0 | AB5: =SUM(Q5:R5,U5) -> 0 | AD5: Dry til 4 PM; started raining; temp dropping
A6: 43105 | B6: 1642 | C6: 1716 | D6: =CHOOSE(WEEKDAY(A6),"Fred/Anne", "Jane", "Phil","Sue/Panos","Shawn/Owens","Jeff", "Rob") -> Jeff | E6: Y | F6: 0.69791667 | G6: 0.78472222 | H6: =G6-F6 -> 0.086805556 | J6: 42 | K6: 44 | L6: Wet pvmnt, spotty rain | M6: 0 | N6: 0 | O6: 0 | P6: 1 | Q6: 0 | R6: 0 | S6: 0 | T6: 0 | U6: 0 | V6: 0 | W6: 5 | X6: 0 | Y6: =SUM(M6:P6) -> 1 | Z6: =SUM(Q6:U6) -> 0 | AA6: =SUM(M6:N6) -> 0 | AB6: =SUM(Q6:R6,U6) -> 0 | AD6: Monitored 21:45-23:00. 49-48F. Rain returned at 22:30.
A7: 43106 | B7: 1643 | C7: 1717 | D7: =CHOOSE(WEEKDAY(A7),"Fred/Anne", "Jane", "Phil","Sue/Panos","Shawn/Owens","Jeff", "Rob") -> Rob | E7: y | F7: 0.70833333 | G7: 0.73958333 | H7: =G7-F7 -> 0.03125 | I7: 0.75 | J7: 45 | K7: 42 | L7: Drying, clear | M7: 0 | N7: 0 | O7: 0 | P7: 0 | Q7: 0 | R7: 0 | S7: 0 | T7: 0 | U7: 0 | V7: 0 | W7: 0 | X7: 0 | Y7: =SUM(M7:P7) -> 0 | Z7: =SUM(Q7:U7) -> 0 | AA7: =SUM(M7:N7) -> 0 | AB7: =SUM(Q7:R7,U7) -> 0
A8: 43107 | B8: 1644 | C8: 1718 | D8: =CHOOSE(WEEKDAY(A8),"Fred/Anne", "Jane", "Phil","Sue/Panos","Shawn/Owens","Jeff", "Rob") -> Fred/Anne | E8: Y | F8: 0.69791667 | G8: 0.76388889 | H8: =G8-F8 -> 0.065972222 | I8: 0.065972222 | J8: 45 | K8: 44.2 | L8: Rain | M8: 0 | N8: 0 | O8: 0 | P8: 0 | Q8: 0 | R8: 0 | S8: 0 | T8: 0 | U8: 0 | V8: 0 | W8: 0 | X8: 0 | Y8: =SUM(M8:P8) -> 0 | Z8: =SUM(Q8:U8) -> 0 | AA8: =SUM(M8:N8) -> 0 | AB8: =SUM(Q8:R8,U8) -> 0
A9: 43108 | B9: 1645 | C9: 1719 | D9: =CHOOSE(WEEKDAY(A9),"Fred/Anne", "Jane", "Phil","Sue/Panos","Shawn/Owens","Jeff", "Rob") -> Jane | E9: Y | F9: 0.69444444 | G9: 0.73611111 | H9: =G9-F9 -> 0.041666667 | I9: 1 | J9: 44 | K9: 43 | L9: Light drizzle | M9: 0 | N9: 0 | O9: 0 | P9: 0 | Q9: 0 | R9: 0 | S9: 0 | T9: 0 | U9: 0 | V9: 0 | W9: 0 | X9: 0 | Y9: =SUM(M9:P9) -> 0 | Z9: =SUM(Q9:U9) -> 0 | AA9: =SUM(M9:N9) -> 0 | AB9: =SUM(Q9:R9,U9) -> 0
A10: 43109 | B10: 1646 | C10: 1720 | D10: =CHOOSE(WEEKDAY(A10),"Fred/Anne", "Jane", "Phil/Tom","Sue/Panos","Shawn/Owens","Jeff", "Rob") -> Phil/Tom | E10: Y | F10: 0.70833333 | G10: 0.72916667 | H10: =G10-F10 -> 0.020833333 | I10: 1.5 | J10: 44.7 | K10: 44.2 | L10: no rain. Wet pavement | M10: 0 | N10: 0 | O10: 0 | P10: 0 | Q10: 0 | R10: 0 | S10: 0 | T10: 0 | U10: 0 | V10: 0 | W10: 0 | X10: 0 | Y10: =SUM(M10:P10) -> 0 | Z10: =SUM(Q10:U10) -> 0 | AA10: =SUM(M10:N10) -> 0 | AB10: =SUM(Q10:R10,U10) -> 0
A11: 43110 | B11: 1648 | C11: 1721 | D11: =CHOOSE(WEEKDAY(A11),"Fred/Anne", "Jane", "Phil","Sue/Panos","Shawn/Owens","Jeff", "Rob") -> Sue/Panos | E11: Y | F11: 0.70833333 | G11: 0.80208333 | H11: =G11-F11 -> 0.09375 | I11: 9.1 | J11: 45.5 | K11: 45.3 | L11: Light rain, wet pavement | M11: 0 | N11: 0 | O11: 0 | P11: 0 | Q11: 0 | R11: 0 | S11: 0 | T11: 0 | U11: 0 | V11: 0 | W11: 0 | X11: 0 | Y11: =SUM(M11:P11) -> 0 | Z11: =SUM(Q11:U11) -> 0 | AA11: =SUM(M11:N11) -> 0 | AB11: =SUM(Q11:R11,U11) -> 0
