Workbook
Name dec_tot_down: 'December 2018'!$Z$33
Name apr_tot_down: #REF!
Name jan_tot_down: 'January 2019'!$Z$33
Name jan_tot_hrs: 'January 2019'!$J$33
Name mar_tot_up: 'April 2019'!$AA$33
Name apr_tot_up: #REF!
Name mar_tot_down: 'March 2019'!$Z$33
Name feb_tot_hrs: 'February 2019'!$J$33
Name nov_tot_up: 'November 2018'!$AA$34
Name feb_tot_down: 'February 2019'!$Z$33
Name nov_tot_down: 'November 2018'!$Z$34
Name mar_tot_hrs: 'March 2019'!$J$33
Name nov_tot_hrs: 'November 2018'!$J$34
Name MAR_F_A_DN: 'March 2019'!$N$33
Name MAR_F_A_DN: 'April 2019'!$N$33
Name mar_tot_hrs: 'April 2019'!$J$33
Name jan_tot_up: 'January 2019'!$AA$33
Name dec_tot_up: 'December 2018'!$AA$33
Name feb_tot_up: 'February 2019'!$AA$33
Name mar_tot_down: 'April 2019'!$Z$33
Name mar_tot_up: 'March 2019'!$AA$33
Name dec_tot_hrs: 'December 2018'!$J$33

Sheet December 2018
A1: sds | B1: Sunset | C1: Civil Twilight | D1: Captain | E1: Monitored (Y/N) | F1: Start time HH:MM | G1: End Date | H1: End time HH:MM | I1: Hours Monitored | J1: Team Hrs. | K1: Start Temp | L1: End Temp | M1: Weather | N1: Females assisted down | O1: Males assisted down | P1: Females unassisted down | Q1: Males unassisted down | R1: Females assisted up | S1: Males assisted up | T1: Females unassisted up | U1: Males unassisted up | V1: Juveniles | W1: Roadkills female | X1: Roadkills male | Y1: Roadkills unk | Z1: Total Frogs down | AA1: Total Frogs up | AB1: Total Frogs Assisted Down | AC1: Total Frogs Assisted Up | AD1: % moon visible | AE1: Comments
A2: 43435 | B2: 1629 | C2: 1702 | D2: =choose(weekday(A2),"Fred/Phil", "Jane/Murr", "Tom","Sue/Anne","Shawn/Orems","Jeff", "Rob") -> Rob | E2: n | G2: 43435 | I2: =iferror(24*( DATEDIF(A2,G2,"D")+TIMEVALUE(H2)-TIMEVALUE(F2)),0) -> 0 | K2: 42 | M2: dry | N2: 0 | O2: 0 | P2: 0 | Q2: 0 | R2: 0 | S2: 0 | T2: 0 | U2: 0 | V2: 0 | W2: 0 | X2: 0 | Y2: 0 | Z2: =sum(N2:Q2) -> 0 | AA2: =sum(R2:V2) -> 0 | AB2: =sum(N2:O2) -> 0 | AC2: =sum(R2:S2,V2) -> 0 | AD2: 0.36
A3: 43436 | B3: 1628 | C3: 1702 | D3: =choose(weekday(A3),"Fred/Phil", "Jane/Murr", "Tom","Sue/Anne","Shawn/Orems","Jeff", "Rob") -> Fred/Phil | G3: 43436 | I3: =iferror(24*( DATEDIF(A3,G3,"D")+TIMEVALUE(H3)-TIMEVALUE(F3)),0) -> 0 | N3: 0 | O3: 0 | P3: 0 | Q3: 0 | R3: 0 | S3: 0 | T3: 0 | U3: 0 | V3: 0 | W3: 0 | X3: 0 | Y3: 0 | Z3: =sum(N3:Q3) -> 0 | AA3: =sum(R3:V3) -> 0 | AB3: =sum(N3:O3) -> 0 | AC3: =sum(R3:S3,V3) -> 0 | AD3: 0.25
A4: 43437 | B4: 1628 | C4: 1702 | D4: =choose(weekday(A4),"Fred/Phil", "Jane/Murr", "Tom","Sue/Anne","Shawn/Orems","Jeff", "Rob") -> Jane/Murr | E4: N | F4: 0.71875 | G4: 43437 | I4: =iferror(24*( DATEDIF(A4,G4,"D")+TIMEVALUE(H4)-TIMEVALUE(F4)),0) -> 0 | K4: 43 | M4: dry and clear | N4: 0 | O4: 0 | P4: 0 | Q4: 0 | R4: 0 | S4: 0 | T4: 0 | U4: 0 | V4: 0 | W4: 0 | X4: 0 | Y4: 0 | Z4: =sum(N4:Q4) -> 0 | AA4: =sum(R4:V4) -> 0 | AB4: =sum(N4:O4) -> 0 | AC4: =sum(R4:S4,V4) -> 0 | AD4: 0.17
A5: 43438 | B5: 1628 | C5: 1701 | D5: =choose(weekday(A5),"Fred/Phil", "Jane/Murr", "Tom","Sue/Anne","Shawn/Orems","Jeff", "Rob") -> Tom | G5: 43438 | I5: =iferror(24*( DATEDIF(A5,G5,"D")+TIMEVALUE(H5)-TIMEVALUE(F5)),0) -> 0 | N5: 0 | O5: 0 | P5: 0 | Q5: 0 | R5: 0 | S5: 0 | T5: 0 | U5: 0 | V5: 0 | W5: 0 | X5: 0 | Y5: 0 | Z5: =sum(N5:Q5) -> 0 | AA5: =sum(R5:V5) -> 0 | AB5: =sum(N5:O5) -> 0 | AC5: =sum(R5:S5,V5) -> 0 | AD5: 0.09
A6: 43439 | B6: 1627 | C6: 1701 | D6: =choose(weekday(A6),"Fred/Phil", "Jane/Murr", "Tom","Sue/Anne","Shawn/Orems","Jeff", "Rob") -> Sue/Anne | E6: N | G6: 43439 | I6: =iferror(24*( DATEDIF(A6,G6,"D")+TIMEVALUE(H6)-TIMEVALUE(F6)),0) -> 0 | N6: 0 | O6: 0 | P6: 0 | Q6: 0 | R6: 0 | S6: 0 | T6: 0 | U6: 0 | V6: 0 | W6: 0 | X6: 0 | Y6: 0 | Z6: =sum(N6:Q6) -> 0 | AA6: =sum(R6:V6) -> 0 | AB6: =sum(N6:O6) -> 0 | AC6: =sum(R6:S6,V6) -> 0 | AD6: 0.04
A7: 43440 | B7: 1627 | C7: 1701 | D7: =choose(weekday(A7),"Fred/Phil", "Jane/Murr", "Tom","Sue/Anne","Shawn/Orems","Jeff", "Rob") -> Shawn/Orems | E7: N | F7: 0.70833333 | G7: 43440 | H7: 0.70833333 | I7: =iferror(24*( DATEDIF(A7,G7,"D")+TIMEVALUE(H7)-TIMEVALUE(F7)),0) -> 0 | J7: 0 | K7: 40 | M7: Dry | N7: 0 | O7: 0 | P7: 0 | Q7: 0 | R7: 0 | S7: 0 | T7: 0 | U7: 0 | V7: 0 | W7: 0 | X7: 0 | Y7: 0 | Z7: =sum(N7:Q7) -> 0 | AA7: =sum(R7:V7) -> 0 | AB7: =sum(N7:O7) -> 0 | AC7: =sum(R7:S7,V7) -> 0 | AD7: 0.01
A8: 43441 | B8: 1627 | C8: 1701 | D8: =choose(weekday(A8),"Fred/Phil", "Jane/Murr", "Tom","Sue/Anne","Shawn/Orems","Jeff", "Rob") -> Jeff | E8: N | F8: 0.73263889 | G8: 43441 | H8: 0.73263889 | I8: =iferror(24*( DATEDIF(A8,G8,"D")+TIMEVALUE(H8)-TIMEVALUE(F8)),0) -> 0 | K8: 38 | L8: 38 | M8: Dry and cloudy | N8: 0 | O8: 0 | P8: 0 | Q8: 0 | R8: 0 | S8: 0 | T8: 0 | U8: 0 | V8: 0 | W8: 0 | X8: 0 | Y8: 0 | Z8: =sum(N8:Q8) -> 0 | AA8: =sum(R8:V8) -> 0 | AB8: =sum(N8:O8) -> 0 | AC8: =sum(R8:S8,V8) -> 0 | AD8: 0 | AE8: No visible or audible flow in creek.
A9: 43442 | B9: 1627 | C9: 1701 | D9: =choose(weekday(A9),"Fred/Phil", "Jane/Murr", "Tom","Sue/Anne","Shawn/Orems","Jeff", "Rob") -> Rob | E9: n | F9: 0.6875 | G9: 43442 | H9: 0.6875 | I9: =iferror(24*( DATEDIF(A9,G9,"D")+TIMEVALUE(H9)-TIMEVALUE(F9)),0) -> 0 | K9: 37 | M9: Dry and cloudy | N9: 0 | O9: 0 | P9: 0 | Q9: 0 | R9: 0 | S9: 0 | T9: 0 | U9: 0 | V9: 0 | W9: 0 | X9: 0 | Y9: 0 | Z9: =sum(N9:Q9) -> 0 | AA9: =sum(R9:V9) -> 0 | AB9: =sum(N9:O9) -> 0 | AC9: =sum(R9:S9,V9) -> 0 | AD9: 0.01
A10: 43443 | B10: 1627 | C10: 1701 | D10: =choose(weekday(A10),"Fred/Phil", "Jane/Murr", "Tom","Sue/Anne","Shawn/Orems","Jeff", "Rob") -> Fred/Phil | E10: N | F10: 0.72916667 | G10: 43443 | H10: 0.72916667 | I10: =iferror(24*( DATEDIF(A10,G10,"D")+TIMEVALUE(H10)-TIMEVALUE(F10)),0) -> 0 | K10: 37 | M10: Rain | N10: 0 | O10: 0 | P10: 0 | Q10: 0 | R10: 0 | S10: 0 | T10: 0 | U10: 0 | V10: 0 | W10: 0 | X10: 0 | Y10: 0 | Z10: =sum(N10:Q10) -> 0 | AA10: =sum(R10:V10) -> 0 | AB10: =sum(N10:O10) -> 0 | AC10: =sum(R10:S10,V10) -> 0 | AD10: 0.04
A11: 43444 | B11: 1627 | C11: 1701 | D11: =choose(weekday(A11),"Fred/Phil", "Jane/Murr", "Tom","Sue/Anne","Shawn/Orems","Jeff", "Rob") -> Jane/Murr | E11: N | F11: 0.70833333 | G11: 43444 | I11: =iferror(24*( DATEDIF(A11,G11,"D")+TIMEVALUE(H11)-TIMEVALUE(F11)),0) -> 0 | K11: 42 | M11: fog | N11: 0 | O11: 0 | P11: 0 | Q11: 0 | R11: 0 | S11: 0 | T11: 0 | U11: 0 | V11: 0 | W11: 0 | X11: 0 | Y11: 0 | Z11: =sum(N11:Q11) -> 0 | AA11: =sum(R11:V11) -> 0 | AB11: =sum(N11:O11) -> 0 | AC11: =sum(R11:S11,V11) -> 0 | AD11: 0.09
A12: 43445 | B12: 1627 | C12: 1701 | D12: =choose(weekday(A12),"Fred/Phil", "Jane/Murr", "Tom","Sue/Anne","Shawn/Orems","Jeff", "Rob") -> Tom | E12: Y | F12: 0.6875 | G12: 43445 | H12: 0.80555556 | I12: =iferror(24*( DATEDIF(A12,G12,"D")+TIMEVALUE(H12)-TIMEVALUE(F12)),0) -> 2.8333333 | J12: 7.75 | K12: 51 | L12: 47 | M12: rain | N12: 0 | O12: 2 | P12: 0 | Q12: 0 | R12: 0 | S12: 0 | T12: 0 | U12: 0 | V12: 0 | W12: 0 | X12: 0 | Y12: 0 | Z12: =sum(N12:Q12) -> 2 | AA12: =sum(R12:V12) -> 0 | AB12: =sum(N12:O12) -> 2 | AC12: =sum(R12:S12,V12) -> 0 | AD12: 0.15 | AE12: 1 chorus frog roadkill; rough skinned newt down
A13: 43446 | B13: 1627 | C13: 1701 | D13: =choose(weekday(A13),"Fred/Phil", "Jane/Murr", "Tom","Sue/Anne","Shawn/Orems","Jeff", "Rob") -> Sue/Anne | E13: Y | F13: 0.70833333 | G13: 43446 | H13: 0.71875 | I13: =iferror(24*( DATEDIF(A13,G13,"D")+TIMEVALUE(H13)-TIMEVALUE(F13)),0) -> 0.25 | J13: 0.25 | K13: 44 | M13: Damp pavement; dry | N13: 0 | O13: 0 | P13: 0 | Q13: 0 | R13: 0 | S13: 0 | T13: 0 | U13: 0 | V13: 0 | W13: 0 | X13: 0 | Y13: 0 | Z13: =sum(N13:Q13) -> 0 | AA13: =sum(R13:V13) -> 0 | AB13: =sum(N13:O13) -> 0 | AC13: =sum(R13:S13,V13) -> 0 | AD13: 0.22
A14: 43447 | B14: 1627 | C14: 1701 | D14: =choose(weekday(A14),"Fred/Phil", "Jane/Murr", "Tom","Sue/Anne","Shawn/Orems","Jeff", "Rob") -> Shawn/Orems | E14: N | F14: 0.70833333 | G14: 43447 | H14: 0.70833333 | I14: =iferror(24*( DATEDIF(A14,G14,"D")+TIMEVALUE(H14)-TIMEVALUE(F14)),0) -> 0 | K14: 48 | M14: Dry all day | N14: 0 | O14: 0 | P14: 0 | Q14: 0 | R14: 0 | S14: 0 | T14: 0 | U14: 0 | V14: 0 | W14: 0 | X14: 0 | Y14: 0 | Z14: =sum(N14:Q14) -> 0 | AA14: =sum(R14:V14) -> 0 | AB14: =sum(N14:O14) -> 0 | AC14: =sum(R14:S14,V14) -> 0 | AD14: 0.3
A15: 43448 | B15: 1627 | C15: 1702 | D15: =choose(weekday(A15),"Fred/Phil", "Jane/Murr", "Tom","Sue/Anne","Shawn/Orems","Jeff", "Rob") -> Jeff | E15: Y | F15: 0.6875 | G15: 43448 | H15: 0.76041667 | I15: =iferror(24*( DATEDIF(A15,G15,"D")+TIMEVALUE(H15)-TIMEVALUE(F15)),0) -> 1.75 | J15: 4.5 | K15: 48 | L15: 46 | M15: Wet pavemt; mist | N15: 0 | O15: 0 | P15: 0 | Q15: 0 | R15: 0 | S15: 0 | T15: 0 | U15: 0 | V15: 0 | W15: 0 | X15: 0 | Y15: 0 | Z15: =sum(N15:Q15) -> 0 | AA15: =sum(R15:V15) -> 0 | AB15: =sum(N15:O15) -> 0 | AC15: =sum(R15:S15,V15) -> 0 | AD15: 0.39
A16: 43449 | B16: 1628 | C16: 1702 | D16: =choose(weekday(A16),"Fred/Phil", "Jane/Murr", "Tom","Sue/Anne","Shawn/Orems","Jeff", "Rob") -> Rob | E16: y | F16: 0.6875 | G16: 43449 | H16: 0.72916667 | I16: =iferror(24*( DATEDIF(A16,G16,"D")+TIMEVALUE(H16)-TIMEVALUE(F16)),0) -> 1 | J16: 2 | K16: 43 | L16: 43 | M16: drying pavemnt | N16: 0 | O16: 0 | P16: 0 | Q16: 0 | R16: 0 | S16: 0 | T16: 0 | U16: 0 | V16: 0 | W16: 0 | X16: 0 | Y16: 0 | Z16: =sum(N16:Q16) -> 0 | AA16: =sum(R16:V16) -> 0 | AB16: =sum(N16:O16) -> 0 | AC16: =sum(R16:S16,V16) -> 0 | AD16: 0.49
A17: 43450 | B17: 1628 | C17: 1702 | D17: =choose(weekday(A17),"Fred/Phil", "Jane/Murr", "Tom","Sue/Anne","Shawn/Orems","Jeff", "Rob") -> Fred/Phil | E17: Y | F17: 0.6875 | G17: 43450 | H17: 0.76041667 | I17: =iferror(24*( DATEDIF(A17,G17,"D")+TIMEVALUE(H17)-TIMEVALUE(F17)),0) -> 1.75 | J17: 5.25 | K17: 47 | L17: 48 | M17: wet pavement | N17: 0 | O17: 0 | P17: 0 | Q17: 0 | R17: 0 | S17: 0 | T17: 0 | U17: 0 | V17: 0 | W17: 0 | X17: 0 | Y17: 0 | Z17: =sum(N17:Q17) -> 0 | AA17: =sum(R17:V17) -> 0 | AB17: =sum(N17:O17) -> 0 | AC17: =sum(R17:S17,V17) -> 0 | AD17: 0.58
A18: 43451 | B18: 1628 | C18: 1702 | D18: =choose(weekday(A18),"Fred/Phil", "Jane/Murr", "Tom","Sue/Anne","Shawn/Orems","Jeff", "Rob") -> Jane/Murr | E18: Y | F18: 0.6875 | G18: 43451 | H18: 0.8125 | I18: =iferror(24*( DATEDIF(A18,G18,"D")+TIMEVALUE(H18)-TIMEVALUE(F18)),0) -> 3 | J18: 13.25 | K18: 49 | L18: 51 | M18: light rain | N18: 0 | O18: 1 | P18: 0 | Q18: 0 | R18: 0 | S18: 0 | T18: 0 | U18: 0 | V18: 0 | W18: 0 | X18: 0 | Y18: 0 | Z18: =sum(N18:Q18) -> 1 | AA18: =sum(R18:V18) -> 0 | AB18: =sum(N18:O18) -> 1 | AC18: =sum(R18:S18,V18) -> 0 | AD18: 0.68
A19: 43452 | B19: 1629 | C19: 1703 | D19: =choose(weekday(A19),"Fred/Phil", "Jane/Murr", "Tom","Sue/Anne","Shawn/Orems","Jeff", "Rob") -> Tom | E19: Y | F19: 0.6875 | G19: 43452 | H19: 0.79166667 | I19: =iferror(24*( DATEDIF(A19,G19,"D")+TIMEVALUE(H19)-TIMEVALUE(F19)),0) -> 2.5 | J19: 4.25 | K19: 51 | L19: 48 | M19: wet pav/rain/wetpav | N19: 1 | O19: 1 | P19: 0 | Q19: 0 | R19: 0 | S19: 0 | T19: 0 | U19: 0 | V19: 0 | W19: 0 | X19: 2 | Y19: 0 | Z19: =sum(N19:Q19) -> 2 | AA19: =sum(R19:V19) -> 0 | AB19: =sum(N19:O19) -> 2 | AC19: =sum(R19:S19,V19) -> 0 | AD19: 0.77
A20: 43453 | B20: 1629 | C20: 1703 | D20: =choose(weekday(A20),"Fred/Phil", "Jane/Murr", "Tom","Sue/Anne","Shawn/Orems","Jeff", "Rob") -> Sue/Anne | E20: Y | F20: 0.69791667 | G20: 43453 | H20: 0.78819444 | I20: =iferror(24*( DATEDIF(A20,G20,"D")+TIMEVALUE(H20)-TIMEVALUE(F20)),0) -> 2.1666667 | J20: 3.83 | K20: 49.2 | L20: 48.4 | M20: Damp pav/2 lt shwrs | N20: 0 | O20: 0 | P20: 0 | Q20: 0 | R20: 0 | S20: 0 | T20: 0 | U20: 0 | V20: 0 | W20: 0 | X20: 0 | Y20: 0 | Z20: =sum(N20:Q20) -> 0 | AA20: =sum(R20:V20) -> 0 | AB20: =sum(N20:O20) -> 0 | AC20: =sum(R20:S20,V20) -> 0 | AD20: 0.85
A21: 43454 | B21: 1629 | C21: 1704 | D21: =choose(weekday(A21),"Fred/Phil", "Jane/Murr", "Tom","Sue/Anne","Shawn/Orems","Jeff", "Rob") -> Shawn/Orems | E21: Y | F21: 0.69791667 | G21: 43454 | H21: 0.80208333 | I21: =iferror(24*( DATEDIF(A21,G21,"D")+TIMEVALUE(H21)-TIMEVALUE(F21)),0) -> 2.5 | J21: 7 | K21: 48 | L21: 45 | M21: Mist; dry; light rain | N21: 0 | O21: 0 | P21: 0 | Q21: 0 | R21: 0 | S21: 0 | T21: 0 | U21: 0 | V21: 0 | W21: 0 | X21: 0 | Y21: 0 | Z21: =sum(N21:Q21) -> 0 | AA21: =sum(R21:V21) -> 0 | AB21: =sum(N21:O21) -> 0 | AC21: =sum(R21:S21,V21) -> 0 | AD21: 0.92 | AE21: 2 long-toed salamanders; audible creek flow,puddled water in wetlands
A22: 43455 | B22: 1630 | C22: 1704 | D22: =choose(weekday(A22),"Fred/Phil", "Jane/Murr", "Tom","Sue/Anne","Shawn/Orems","Jeff", "Rob") -> Jeff | E22: N | F22: 0.71388889 | G22: 43455 | H22: 0.71388889 | I22: =iferror(24*( DATEDIF(A22,G22,"D")+TIMEVALUE(H22)-TIMEVALUE(F22)),0) -> 0 | J22: 0 | K22: 43 | L22: 43 | M22: Clear, dry all day | N22: 0 | O22: 0 | P22: 0 | Q22: 0 | R22: 0 | S22: 0 | T22: 0 | U22: 0 | V22: 0 | W22: 0 | X22: 0 | Y22: 0 | Z22: =sum(N22:Q22) -> 0 | AA22: =sum(R22:V22) -> 0 | AB22: =sum(N22:O22) -> 0 | AC22: =sum(R22:S22,V22) -> 0 | AD22: 0.97 | AE22: Thin stream flowing in creek, audible in capture basin. Wetland has large patches of open water visible from Harborton.
A23: 43456 | B23: 1630 | C23: 1705 | D23: =choose(weekday(A23),"Fred/Phil", "Jane/Murr", "Tom","Sue/Anne","Shawn/Orems","Jeff", "Rob") -> Rob | E23: y | F23: 0.6875 | G23: 43456 | H23: 0.75 | I23: =iferror(24*( DATEDIF(A23,G23,"D")+TIMEVALUE(H23)-TIMEVALUE(F23)),0) -> 1.5 | J23: 1.5 | K23: 41 | L23: 40 | M23: drying, then rain | N23: 0 | O23: 0 | P23: 0 | Q23: 0 | R23: 0 | S23: 0 | T23: 0 | U23: 0 | V23: 0 | W23: 0 | X23: 0 | Y23: 0 | Z23: =sum(N23:Q23) -> 0 | AA23: =sum(R23:V23) -> 0 | AB23: =sum(N23:O23) -> 0 | AC23: =sum(R23:S23,V23) -> 0 | AD23: 1 | AE23: 4AM. 42. no sign of frogs
A24: 43457 | B24: 1631 | C24: 1705 | D24: =choose(weekday(A24),"Fred/Phil", "Jane/Murr", "Tom","Sue/Anne","Shawn/Orems","Jeff", "Rob") -> Fred/Phil | E24: Y | F24: 0.70833333 | G24: 43457 | H24: 0.79166667 | I24: =iferror(24*( DATEDIF(A24,G24,"D")+TIMEVALUE(H24)-TIMEVALUE(F24)),0) -> 2 | J24: 4.75 | K24: 47.8 | L24: 46.9 | M24: Steady rain | N24: 0 | O24: 1 | P24: 0 | Q24: 0 | R24: 0 | S24: 0 | T24: 0 | U24: 0 | V24: 0 | W24: 0 | X24: 0 | Y24: 0 | Z24: =sum(N24:Q24) -> 1 | AA24: =sum(R24:V24) -> 0 | AB24: =sum(N24:O24) -> 1 | AC24: =sum(R24:S24,V24) -> 0 | AD24: 0.99 | AE24: there are several highly degraded roadkill. Creek flowing strong
A25: 43458 | B25: 1632 | C25: 1706 | D25: =choose(weekday(A25),"Fred/Phil", "Jane/Murr", "Tom","Sue/Anne","Shawn/Orems","Jeff", "Rob") -> Jane/Murr | E25: Y | F25: 0.69791667 | G25: 43458 | H25: 0.70833333 | I25: =iferror(24*( DATEDIF(A25,G25,"D")+TIMEVALUE(H25)-TIMEVALUE(F25)),0) -> 0.25 | J25: 0.25 | K25: 46 | L25: 46 | M25: Dry | N25: 0 | O25: 0 | P25: 0 | Q25: 0 | R25: 0 | S25: 0 | T25: 0 | U25: 0 | V25: 0 | W25: 0 | X25: 0 | Y25: 0 | Z25: =sum(N25:Q25) -> 0 | AA25: =sum(R25:V25) -> 0 | AB25: =sum(N25:O25) -> 0 | AC25: =sum(R25:S25,V25) -> 0 | AD25: 0.96 | AE25: Stream was flowing.
A26: 43459 | B26: 1632 | C26: 1706 | D26: =choose(weekday(A26),"Fred/Phil", "Jane/Murr", "Tom","Sue/Anne","Shawn/Orems","Jeff", "Rob") -> Tom | E26: N | F26: 0.69791667 | G26: 43459 | H26: 0.69791667 | I26: =iferror(24*( DATEDIF(A26,G26,"D")+TIMEVALUE(H26)-TIMEVALUE(F26)),0) -> 0 | J26: 0 | K26: 45 | L26: 45 | M26: dry | N26: 0 | O26: 0 | P26: 0 | Q26: 0 | R26: 0 | S26: 0 | T26: 0 | U26: 0 | V26: 0 | W26: 0 | X26: 0 | Y26: 0 | Z26: =sum(N26:Q26) -> 0 | AA26: =sum(R26:V26) -> 0 | AB26: =sum(N26:O26) -> 0 | AC26: =sum(R26:S26,V26) -> 0 | AD26: 0.91
A27: 43460 | B27: 1633 | C27: 1707 | D27: =choose(weekday(A27),"Fred/Phil", "Jane/Murr", "Tom","Sue/Anne","Shawn/Orems","Jeff", "Rob") -> Sue/Anne | E27: Y | F27: 0.70138889 | G27: 43460 | H27: 0.71875 | I27: =iferror(24*( DATEDIF(A27,G27,"D")+TIMEVALUE(H27)-TIMEVALUE(F27)),0) -> 0.41666667 | J27: 0.42 | K27: 43.1 | L27: 43 | M27: Heavy Rain | N27: 0 | O27: 0 | P27: 0 | Q27: 0 | R27: 0 | S27: 0 | T27: 0 | U27: 0 | V27: 0 | W27: 0 | X27: 0 | Y27: 0 | Z27: =sum(N27:Q27) -> 0 | AA27: =sum(R27:V27) -> 0 | AB27: =sum(N27:O27) -> 0 | AC27: =sum(R27:S27,V27) -> 0 | AD27: 0.82
A28: 43461 | B28: 1634 | C28: 1708 | D28: =choose(weekday(A28),"Fred/Phil", "Jane/Murr", "Tom","Sue/Anne","Shawn/Orems","Jeff", "Rob") -> Shawn/Orems | E28: N | F28: 0.70833333 | G28: 43461 | H28: 0.70833333 | I28: =iferror(24*( DATEDIF(A28,G28,"D")+TIMEVALUE(H28)-TIMEVALUE(F28)),0) -> 0 | J28: 0 | K28: 43 | M28: No rain; cold | N28: 0 | O28: 0 | P28: 0 | Q28: 0 | R28: 0 | S28: 0 | T28: 0 | U28: 0 | V28: 0 | W28: 0 | X28: 0 | Y28: 0 | Z28: =sum(N28:Q28) -> 0 | AA28: =sum(R28:V28) -> 0 | AB28: =sum(N28:O28) -> 0 | AC28: =sum(R28:S28,V28) -> 0 | AD28: 0.73
A29: 43462 | B29: 1634 | C29: 1709 | D29: =choose(weekday(A29),"Fred/Phil", "Jane/Murr", "Tom","Sue/Anne","Shawn/Orems","Jeff", "Rob") -> Jeff | E29: Y | F29: 0.70138889 | G29: 43462 | H29: 0.72916667 | I29: =iferror(24*( DATEDIF(A29,G29,"D")+TIMEVALUE(H29)-TIMEVALUE(F29)),0) -> 0.66666667 | J29: 0.67 | K29: 44 | L29: 43 | M29: wet, not raining | N29: 0 | O29: 0 | P29: 0 | Q29: 0 | R29: 0 | S29: 0 | T29: 0 | U29: 0 | V29: 0 | W29: 0 | X29: 0 | Y29: 0 | Z29: =sum(N29:Q29) -> 0 | AA29: =sum(R29:V29) -> 0 | AB29: =sum(N29:O29) -> 0 | AC29: =sum(R29:S29,V29) -> 0 | AD29: 0.62
A30: 43463 | B30: 1635 | C30: 1709 | D30: =choose(weekday(A30),"Fred/Phil", "Jane/Murr", "Tom","Sue/Anne","Shawn/Orems","Jeff", "Rob") -> Rob | E30: y | F30: 0.6875 | G30: 43463 | H30: 0.97916667 | I30: =iferror(24*( DATEDIF(A30,G30,"D")+TIMEVALUE(H30)-TIMEVALUE(F30)),0) -> 7 | J30: 30.5 | K30: 49 | L30: 49 | M30: rain, warm | N30: 19 | O30: 320 | P30: 0 | Q30: 1 | R30: 0 | S30: 0 | T30: 0 | U30: 0 | V30: 0 | W30: 0 | X30: 0 | Y30: 0 | Z30: =sum(N30:Q30) -> 340 | AA30: =sum(R30:V30) -> 0 | AB30: =sum(N30:O30) -> 339 | AC30: =sum(R30:S30,V30) -> 0 | AD30: 0.51
A31: 43464 | B31: 1636 | C31: 1710 | D31: =choose(weekday(A31),"Fred/Phil", "Jane/Murr", "Tom","Sue/Anne","Shawn/Orems","Jeff", "Rob") -> Fred/Phil | E31: Y | F31: 0.69097222 | G31: 43464 | H31: 0.75347222 | I31: =iferror(24*( DATEDIF(A31,G31,"D")+TIMEVALUE(H31)-TIMEVALUE(F31)),0) -> 1.5 | J31: 3 | K31: 42.8 | L31: 41.4 | M31: wet Pave, lt rain 5:30-6 | N31: 0 | O31: 0 | P31: 0 | Q31: 0 | R31: 0 | S31: 0 | T31: 0 | U31: 0 | V31: 0 | W31: 0 | X31: 0 | Y31: 0 | Z31: =sum(N31:Q31) -> 0 | AA31: =sum(R31:V31) -> 0 | AB31: =sum(N31:O31) -> 0 | AC31: =sum(R31:S31,V31) -> 0 | AD31: 0.4
A32: 43465 | B32: 1637 | C32: 1711 | D32: =choose(weekday(A32),"Fred/Phil", "Jane/Murr", "Tom","Sue/Anne","Shawn/Orems","Jeff", "Rob") -> Jane/Murr | E32: N | F32: 0.70833333 | G32: 43465 | I32: =iferror(24*( DATEDIF(A32,G32,"D")+TIMEVALUE(H32)-TIMEVALUE(F32)),0) -> 0 | K32: 39 | M32: Dry | N32: 0 | O32: 0 | P32: 0 | Q32: 0 | R32: 0 | S32: 0 | T32: 0 | U32: 0 | V32: 0 | W32: 0 | X32: 0 | Y32: 0 | Z32: =sum(N32:Q32) -> 0 | AA32: =sum(R32:V32) -> 0 | AB32: =sum(N32:O32) -> 0 | AC32: =sum(R32:S32,V32) -> 0 | AD32: 0.3
E33: Monthly total | I33: =SUM(I3:I32) -> 31.083333 | J33: =SUM(J2:J32) -> 89.17 | N33: =sum(N2:N32) -> 20 | O33: =sum(O2:O32) -> 325 | P33: =sum(P2:P32) -> 0 | Q33: =sum(Q2:Q32) -> 1 | R33: =sum(R2:R32) -> 0 | S33: =sum(S2:S32) -> 0 | T33: =sum(T2:T32) -> 0 | U33: =sum(U2:U32) -> 0 | ... Y33: =sum(Y2:Y32) -> 0 | Z33: =SUM(Z2:Z32) -> 346 | AA33: =SUM(AA2:AA32) -> 0 | AB33: =sum(AB2:AB32) -> 345 | AC33: =sum(AC2:AC32) -> 0
E34: Cumulative Total | I34: ='November 2018'!I$34+'December 2018'!I$33 -> 36.1 | J34: ='November 2018'!J$34+'December 2018'!J$33 -> 89.17 | N34: ='November 2018'!N$34+'December 2018'!N$33 -> 20 | O34: ='November 2018'!O$34+'December 2018'!O$33 -> 325 | P34: ='November 2018'!P$34+'December 2018'!P$33 -> 0 | Q34: ='November 2018'!Q$34+'December 2018'!Q$33 -> 1 | R34: ='November 2018'!R$34+'December 2018'!R$33 -> 0 | S34: ='November 2018'!S$34+'December 2018'!S$33 -> 0 | T34: ='November 2018'!T$34+'December 2018'!T$33 -> 0 | U34: ='November 2018'!U$34+'December 2018'!U$33 -> 0 | ... AA34: ='November 2018'!AA$34+'December 2018'!AA$33 -> 0 | AB34: ='November 2018'!AB34+'December 2018'!AB33 -> 345 | AC34: ='November 2018'!AC34+'December 2018'!AC33 -> 0
E35: Season Total | I35: ='November 2018'!I$34+'December 2018'!I$33+'January 2019'!I$33+'February 2019'!I$33+'March 2019'!I$33+'April 2019'!I$33 -> 145.81028 | J35: ='November 2018'!J34+'December 2018'!J33+'January 2019'!J33+'February 2019'!J33+'March 2019'!J33+'April 2019'!J33 -> 558.96167 | N35: ='November 2018'!N34+'December 2018'!N33+'January 2019'!N33+'February 2019'!N33+'March 2019'!N33+'April 2019'!N33 -> 90 | O35: ='November 2018'!O34+'December 2018'!O33+'January 2019'!O33+'February 2019'!O33+'March 2019'!O33+'April 2019'!O33 -> 1134 | P35: ='November 2018'!P34+'December 2018'!P33+'January 2019'!P33+'February 2019'!P33+'March 2019'!P33+'April 2019'!P33 -> 3 | Q35: ='November 2018'!Q34+'December 2018'!Q33+'January 2019'!Q33+'February 2019'!Q33+'March 2019'!Q33+'April 2019'!Q33 -> 4 | R35: ='November 2018'!R34+'December 2018'!R33+'January 2019'!R33+'February 2019'!R33+'March 2019'!R33+'April 2019'!R33 -> 124 | S35: ='November 2018'!S34+'December 2018'!S33+'January 2019'!S33+'February 2019'!S33+'March 2019'!S33+'April 2019'!S33 -> 791 | T35: ='November 2018'!T34+'December 2018'!T33+'January 2019'!T33+'February 2019'!T33+'March 2019'!T33+'April 2019'!T33 -> 6 | U35: ='November 2018'!U34+'December 2018'!U33+'January 2019'!U33+'February 2019'!U33+'March 2019'!U33+'April 2019'!U33 -> 17 | ... AC35: ='November 2018'!AC34+'December 2018'!AC33+'January 2019'!AC33+'February 2019'!AC33+'March 2019'!AC33+'April 2019'!AC33 -> 921
E36: 2017-18 Total | Z36: 433 | AA36: 297
E37: 2016-17 Total | Z37: 834 | AA37: 751
E38: 2015-16 Total | Z38: 688 | AA38: 1040
E39: 2014-15 Total | Z39: 695 | AA39: 750
E40: 2013-14 Total | Z40: 580 | AA40: 572

Sheet April 2019
A1: Date | B1: Sunset | C1: Civil Twilight | D1: Captain | E1: Monitored (Y/N) | F1: Start time HH:MM | G1: End Date | H1: End time HH:MM | I1: Hours monitored | J1: Team Hrs. | K1: Start temp | L1: End temp | M1: Weather | N1: Females assisted down | O1: Males assisted down | P1: Unassisted Females down | Q1: Unasissted Males down | R1: Females assisted up | S1: Males assisted up | T1: Unassisted females up | U1: Unassisted males up | V1: Juveniles assisted up | W1: Roadkill Females | X1: Roadkill Males | Y1: Roadkill Unk | Z1: Total frogs down | AA1: Total frogs up | AB1: Total Frogs Assisted Down | AC1: Total Frogs Assisted Up | AD1: % moon visible | AE1: Comments
A2: 43556 | B2: 1939 | C2: 2009 | D2: =choose(weekday(A2),"Fred/Phil", "Jane/Murr", "Tom","Sue/Anne","Shawn/Orems","Jeff", "Rob") -> Jane/Murr | E2: Y | F2: 0.8125 | G2: 43556 | H2: 0.88541667 | I2: =iferror(24*( DATEDIF(A2,G2,"D")+TIMEVALUE(H2)-TIMEVALUE(F2)),0) -> 1.75 | J2: 3.25 | K2: 63.4 | L2: 60 | M2: A few sprinkles, then dry | N2: 0 | O2: 0 | P2: 0 | Q2: 0 | R2: 0 | S2: 2 | T2: 0 | U2: 0 | V2: 0 | W2: 0 | X2: 0 | Y2: 0 | Z2: =sum(N2:Q2) -> 0 | AA2: =sum(R2:V2) -> 2 | AB2: =sum(N2:O2) -> 0 | AC2: =sum(R2:S2,V2) -> 2 | AD2: 0.15 | AE2: Five Dunns salamanders in a seepy area on Harborton!
A3: 43557 | B3: 1940 | C3: 2010 | D3: Tom/Kris/Rob | E3: y | F3: 0.8125 | G3: 43557 | H3: 0.95833333 | I3: =iferror(24*( DATEDIF(A3,G3,"D")+TIMEVALUE(H3)-TIMEVALUE(F3)),0) -> 3.5 | J3: 16.75 | K3: 56 | L3: 52 | N3: 0 | O3: 0 | P3: 0 | Q3: 0 | R3: 17 | S3: 279 | T3: 0 | U3: 0 | V3: 2 | W3: 0 | X3: 0 | Y3: 0 | Z3: =sum(N3:Q3) -> 0 | AA3: =sum(R3:V3) -> 298 | AB3: =sum(N3:O3) -> 0 | AC3: =sum(R3:S3,V3) -> 298 | AD3: 0.09 | AE3: over 30 chorus up, very lively frogs
A4: 43558 | B4: 1941 | C4: 2011 | D4: =choose(weekday(A4),"Fred/Phil", "Jane/Murr", "Tom","Sue/Anne","Shawn/Orems","Jeff", "Rob") -> Sue/Anne | E4: Y | F4: 0.8125 | G4: 43558 | H4: 0.875 | I4: =iferror(24*( DATEDIF(A4,G4,"D")+TIMEVALUE(H4)-TIMEVALUE(F4)),0) -> 1.5 | J4: 2.65 | K4: 49 | L4: 47 | M4: Dry; sky clearing | N4: 0 | O4: 0 | P4: 0 | Q4: 0 | R4: 0 | S4: 0 | T4: 0 | U4: 0 | V4: 0 | W4: 0 | X4: 0 | Y4: 0 | Z4: =sum(N4:Q4) -> 0 | AA4: =sum(R4:V4) -> 0 | AB4: =sum(N4:O4) -> 0 | AC4: =sum(R4:S4,V4) -> 0 | AD4: 0.04
A5: 43559 | B5: 1943 | C5: 2013 | D5: =choose(weekday(A5),"Fred/Phil", "Jane/Murr", "Tom","Sue/Anne","Shawn/Orems","Jeff", "Rob") -> Shawn/Orems | E5: Y | F5: 0.82291667 | G5: 43559 | H5: 0.95833333 | I5: =iferror(24*( DATEDIF(A5,G5,"D")+TIMEVALUE(H5)-TIMEVALUE(F5)),0) -> 3.25 | J5: 10.5 | K5: 54 | L5: 52 | M5: Dry early then mostly rainy | N5: 0 | O5: 0 | P5: 0 | Q5: 0 | R5: 0 | S5: 10 | T5: 0 | U5: 0 | V5: 3 | W5: 0 | X5: 0 | Y5: 0 | Z5: =sum(N5:Q5) -> 0 | AA5: =sum(R5:V5) -> 13 | AB5: =sum(N5:O5) -> 0 | AC5: =sum(R5:S5,V5) -> 13 | AD5: 0.01 | AE5: About 60 chorus frogs uphill; 2 chorus frogs down
A6: 43560 | B6: 1944 | C6: 2014 | D6: =choose(weekday(A6),"Fred/Phil", "Jane/Murr", "Tom","Sue/Anne","Shawn/Orems","Jeff", "Rob") -> Jeff | E6: Y | F6: 0.79166667 | G6: 43561 | H6: 0 | I6: =iferror(24*( DATEDIF(A6,G6,"D")+TIMEVALUE(H6)-TIMEVALUE(F6)),0) -> 5 | J6: 21.5 | K6: 48.6 | L6: 45 | M6: Wet,cloudy turns clear by 8:30 | N6: 0 | O6: 0 | P6: 0 | Q6: 0 | R6: 0 | S6: 2 | T6: 0 | U6: 0 | V6: 0 | W6: 0 | X6: 0 | Y6: 0 | Z6: =sum(N6:Q6) -> 0 | AA6: =sum(R6:V6) -> 2 | AB6: =sum(N6:O6) -> 0 | AC6: =sum(R6:S6,V6) -> 2 | AD6: 0 | AE6: 1 Lt Sal, 3 chorus frogs, 2 extremely small red legged - checked sex but hard to tell. Assumed male.
A7: 43561 | B7: 1945 | C7: 2015 | D7: =choose(weekday(A7),"Fred/Phil", "Jane/Murr", "Tom","Sue/Anne","Shawn/Orems","Jeff", "Rob") -> Rob | E7: y | F7: 0.82291667 | G7: 43561 | H7: 0.85416667 | I7: =iferror(24*( DATEDIF(A7,G7,"D")+TIMEVALUE(H7)-TIMEVALUE(F7)),0) -> 0.75 | J7: 3.75 | K7: 51 | L7: 50 | M7: raining | N7: 0 | O7: 0 | P7: 0 | Q7: 0 | R7: 0 | S7: 0 | T7: 0 | U7: 0 | V7: 0 | W7: 0 | X7: 0 | Y7: 0 | Z7: =sum(N7:Q7) -> 0 | AA7: =sum(R7:V7) -> 0 | AB7: =sum(N7:O7) -> 0 | AC7: =sum(R7:S7,V7) -> 0 | AD7: 0.01 | AE7: season appears to be over.
A8: 43562 | B8: 1946 | C8: 2017 | D8: =choose(weekday(A8),"Fred/Phil", "Jane/Murr", "Tom","Sue/Anne","Shawn/Orems","Jeff", "Rob") -> Fred/Phil | E8: Y | F8: 0.8125 | G8: 43562 | H8: 0.875 | I8: =iferror(24*( DATEDIF(A8,G8,"D")+TIMEVALUE(H8)-TIMEVALUE(F8)),0) -> 1.5 | J8: 3 | K8: 50 | L8: 47 | M8: Light rain | N8: 0 | O8: 0 | P8: 0 | Q8: 0 | R8: 0 | S8: 0 | T8: 0 | U8: 0 | V8: 0 | W8: 0 | X8: 0 | Y8: 2 | Z8: =sum(N8:Q8) -> 0 | AA8: =sum(R8:V8) -> 0 | AB8: =sum(N8:O8) -> 0 | AC8: =sum(R8:S8,V8) -> 0 | AD8: 0.04 | AE8: 2 chorus frogs headed down, one injured, one gravid female
A9: 43563 | B9: 1948 | C9: 2018 | D9: =choose(weekday(A9),"Fred/Phil", "Jane/Murr", "Tom","Sue/Anne","Shawn/Orems","Jeff", "Rob") -> Jane/Murr | E9: Y | F9: 0.82291667 | G9: 43563 | H9: 0.88541667 | I9: =iferror(24*( DATEDIF(A9,G9,"D")+TIMEVALUE(H9)-TIMEVALUE(F9)),0) -> 1.5 | J9: 1.5 | K9: 54 | L9: 53 | M9: wet pavement, cloudy | N9: 0 | O9: 0 | P9: 0 | Q9: 0 | R9: 0 | S9: 1 | T9: 0 | U9: 0 | V9: 0 | W9: 0 | X9: 0 | Y9: 0 | Z9: =sum(N9:Q9) -> 0 | AA9: =sum(R9:V9) -> 1 | AB9: =sum(N9:O9) -> 0 | AC9: =sum(R9:S9,V9) -> 1 | AD9: 0.09 | AE9: 1 chorus frog uphill, one headed down
A10: 43564 | B10: 1949 | C10: 2020 | D10: =choose(weekday(A10),"Fred/Phil", "Jane/Murr", "Tom","Sue/Anne","Shawn/Orems","Jeff", "Rob") -> Tom | E10: N | F10: 0.79166667 | G10: 43564 | H10: 0.79166667 | I10: =iferror(24*( DATEDIF(A10,G10,"D")+TIMEVALUE(H10)-TIMEVALUE(F10)),0) -> 0 | J10: 0 | K10: 55 | L10: 55 | M10: mostly dry, cloudy | N10: 0 | O10: 0 | P10: 0 | Q10: 0 | R10: 0 | S10: 0 | T10: 0 | U10: 0 | V10: 0 | W10: 0 | X10: 0 | Y10: 0 | Z10: =sum(N10:Q10) -> 0 | AA10: =sum(R10:V10) -> 0 | AB10: =sum(N10:O10) -> 0 | AC10: =sum(R10:S10,V10) -> 0 | AD10: 0.16
A11: 43565 | B11: 1950 | C11: 2021 | D11: =choose(weekday(A11),"Fred/Phil", "Jane/Murr", "Tom","Sue/Anne","Shawn/Orems","Jeff", "Rob") -> Sue/Anne | G11: 43565 | I11: =iferror(24*( DATEDIF(A11,G11,"D")+TIMEVALUE(H11)-TIMEVALUE(F11)),0) -> 0 | N11: 0 | O11: 0 | P11: 0 | Q11: 0 | R11: 0 | S11: 0 | T11: 0 | U11: 0 | V11: 0 | W11: 0 | X11: 0 | Y11: 0 | Z11: =sum(N11:Q11) -> 0 | AA11: =sum(R11:V11) -> 0 | AB11: =sum(N11:O11) -> 0 | AC11: =sum(R11:S11,V11) -> 0 | AD11: 0.24
A12: 43566 | B12: 1952 | C12: 2022 | D12: =choose(weekday(A12),"Fred/Phil", "Jane/Murr", "Tom","Sue/Anne","Shawn/Orems","Jeff", "Rob") -> Shawn/Orems | E12: Y | F12: 0.84027778 | G12: 43566 | H12: 0.84722222 | I12: =iferror(24*( DATEDIF(A12,G12,"D")+TIMEVALUE(H12)-TIMEVALUE(F12)),0) -> 0.16666667 | J12: .l7 | K12: 52 | L12: 52 | M12: Dry, wet pavement | N12: 0 | O12: 0 | P12: 0 | Q12: 0 | R12: 0 | S12: 0 | T12: 0 | U12: 0 | V12: 0 | W12: 0 | X12: 0 | Y12: 0 | Z12: =sum(N12:Q12) -> 0 | AA12: =sum(R12:V12) -> 0 | AB12: =sum(N12:O12) -> 0 | AC12: =sum(R12:S12,V12) -> 0 | AD12: 0.34 | AE12: Very little sound in the wetlands
A13: 43567 | B13: 1953 | C13: 2024 | D13: =choose(weekday(A13),"Fred/Phil", "Jane/Murr", "Tom","Sue/Anne","Shawn/Orems","Jeff", "Rob") -> Jeff | E13: Y | F13: 0.85069444 | G13: 43567 | H13: 0.86458333 | I13: =iferror(24*( DATEDIF(A13,G13,"D")+TIMEVALUE(H13)-TIMEVALUE(F13)),0) -> 0.33333333 | J13: 0.33 | K13: 53 | L13: 53 | M13: Dry, clear w/ few clouds | N13: 0 | O13: 0 | P13: 0 | Q13: 0 | R13: 0 | S13: 0 | T13: 0 | U13: 0 | V13: 0 | W13: 0 | X13: 0 | Y13: 0 | Z13: =sum(N13:Q13) -> 0 | AA13: =sum(R13:V13) -> 0 | AB13: =sum(N13:O13) -> 0 | AC13: =sum(R13:S13,V13) -> 0 | AD13: 0.45
A14: 43568 | B14: 1954 | C14: 2025 | D14: =choose(weekday(A14),"Fred/Phil", "Jane/Murr", "Tom","Sue/Anne","Shawn/Orems","Jeff", "Rob") -> Rob | G14: 43568 | I14: =iferror(24*( DATEDIF(A14,G14,"D")+TIMEVALUE(H14)-TIMEVALUE(F14)),0) -> 0 | N14: 0 | O14: 0 | P14: 0 | Q14: 0 | R14: 0 | S14: 0 | T14: 0 | U14: 0 | V14: 0 | W14: 0 | X14: 0 | Y14: 0 | Z14: =sum(N14:Q14) -> 0 | AA14: =sum(R14:V14) -> 0 | AB14: =sum(N14:O14) -> 0 | AC14: =sum(R14:S14,V14) -> 0 | AD14: 0.56
A15: 43569 | B15: 1956 | C15: 2026 | D15: =choose(weekday(A15),"Fred/Phil", "Jane/Murr", "Tom","Sue/Anne","Shawn/Orems","Jeff", "Rob") -> Fred/Phil | G15: 43569 | I15: =iferror(24*( DATEDIF(A15,G15,"D")+TIMEVALUE(H15)-TIMEVALUE(F15)),0) -> 0 | N15: 0 | O15: 0 | P15: 0 | Q15: 0 | R15: 0 | S15: 0 | T15: 0 | U15: 0 | V15: 0 | W15: 0 | X15: 0 | Y15: 0 | Z15: =sum(N15:Q15) -> 0 | AA15: =sum(R15:V15) -> 0 | AB15: =sum(N15:O15) -> 0 | AC15: =sum(R15:S15,V15) -> 0 | AD15: 0.67
A16: 43570 | B16: 1957 | C16: 2028 | D16: =choose(weekday(A16),"Fred/Phil", "Jane/Murr", "Tom","Sue/Anne","Shawn/Orems","Jeff", "Rob") -> Jane/Murr | G16: 43570 | I16: =iferror(24*( DATEDIF(A16,G16,"D")+TIMEVALUE(H16)-TIMEVALUE(F16)),0) -> 0 | N16: 0 | O16: 0 | P16: 0 | Q16: 0 | R16: 0 | S16: 0 | T16: 0 | U16: 0 | V16: 0 | W16: 0 | X16: 0 | Y16: 0 | Z16: =sum(N16:Q16) -> 0 | AA16: =sum(R16:V16) -> 0 | AB16: =sum(N16:O16) -> 0 | AC16: =sum(R16:S16,V16) -> 0 | AD16: 0.78
A17: 43571 | B17: 1958 | C17: 2029 | D17: =choose(weekday(A17),"Fred/Phil", "Jane/Murr", "Tom","Sue/Anne","Shawn/Orems","Jeff", "Rob") -> Tom | G17: 43571 | I17: =iferror(24*( DATEDIF(A17,G17,"D")+TIMEVALUE(H17)-TIMEVALUE(F17)),0) -> 0 | N17: 0 | O17: 0 | P17: 0 | Q17: 0 | R17: 0 | S17: 0 | T17: 0 | U17: 0 | V17: 0 | W17: 0 | X17: 0 | Y17: 0 | Z17: =sum(N17:Q17) -> 0 | AA17: =sum(R17:V17) -> 0 | AB17: =sum(N17:O17) -> 0 | AC17: =sum(R17:S17,V17) -> 0 | AD17: 0.87
A18: 43572 | B18: 1959 | C18: 2031 | D18: =choose(weekday(A18),"Fred/Phil", "Jane/Murr", "Tom","Sue/Anne","Shawn/Orems","Jeff", "Rob") -> Sue/Anne | G18: 43572 | I18: =iferror(24*( DATEDIF(A18,G18,"D")+TIMEVALUE(H18)-TIMEVALUE(F18)),0) -> 0 | N18: 0 | O18: 0 | P18: 0 | Q18: 0 | R18: 0 | S18: 0 | T18: 0 | U18: 0 | V18: 0 | W18: 0 | X18: 0 | Y18: 0 | Z18: =sum(N18:Q18) -> 0 | AA18: =sum(R18:V18) -> 0 | AB18: =sum(N18:O18) -> 0 | AC18: =sum(R18:S18,V18) -> 0 | AD18: 0.94
A19: 43573 | B19: 2001 | C19: 2032 | D19: =choose(weekday(A19),"Fred/Phil", "Jane/Murr", "Tom","Sue/Anne","Shawn/Orems","Jeff", "Rob") -> Shawn/Orems | G19: 43573 | I19: =iferror(24*( DATEDIF(A19,G19,"D")+TIMEVALUE(H19)-TIMEVALUE(F19)),0) -> 0 | N19: 0 | O19: 0 | P19: 0 | Q19: 0 | R19: 0 | S19: 0 | T19: 0 | U19: 0 | V19: 0 | W19: 0 | X19: 0 | Y19: 0 | Z19: =sum(N19:Q19) -> 0 | AA19: =sum(R19:V19) -> 0 | AB19: =sum(N19:O19) -> 0 | AC19: =sum(R19:S19,V19) -> 0 | AD19: 0.98
A20: 43574 | B20: 2002 | C20: 2033 | D20: =choose(weekday(A20),"Fred/Phil", "Jane/Murr", "Tom","Sue/Anne","Shawn/Orems","Jeff", "Rob") -> Jeff | G20: 43574 | I20: =iferror(24*( DATEDIF(A20,G20,"D")+TIMEVALUE(H20)-TIMEVALUE(F20)),0) -> 0 | N20: 0 | O20: 0 | P20: 0 | Q20: 0 | R20: 0 | S20: 0 | T20: 0 | U20: 0 | V20: 0 | W20: 0 | X20: 0 | Y20: 0 | Z20: =sum(N20:Q20) -> 0 | AA20: =sum(R20:V20) -> 0 | AB20: =sum(N20:O20) -> 0 | AC20: =sum(R20:S20,V20) -> 0 | AD20: 1
A21: 43575 | B21: 2003 | C21: 2035 | D21: =choose(weekday(A21),"Fred/Phil", "Jane/Murr", "Tom","Sue/Anne","Shawn/Orems","Jeff", "Rob") -> Rob | G21: 43575 | I21: =iferror(24*( DATEDIF(A21,G21,"D")+TIMEVALUE(H21)-TIMEVALUE(F21)),0) -> 0 | N21: 0 | O21: 0 | P21: 0 | Q21: 0 | R21: 0 | S21: 0 | T21: 0 | U21: 0 | V21: 0 | W21: 0 | X21: 0 | Y21: 0 | Z21: =sum(N21:Q21) -> 0 | AA21: =sum(R21:V21) -> 0 | AB21: =sum(N21:O21) -> 0 | AC21: =sum(R21:S21,V21) -> 0 | AD21: 0.99
A22: 43576 | B22: 2005 | C22: 2036 | D22: =choose(weekday(A22),"Fred/Phil", "Jane/Murr", "Tom","Sue/Anne","Shawn/Orems","Jeff", "Rob") -> Fred/Phil | G22: 43576 | I22: =iferror(24*( DATEDIF(A22,G22,"D")+TIMEVALUE(H22)-TIMEVALUE(F22)),0) -> 0 | N22: 0 | O22: 0 | P22: 0 | Q22: 0 | R22: 0 | S22: 0 | T22: 0 | U22: 0 | V22: 0 | W22: 0 | X22: 0 | Y22: 0 | Z22: =sum(N22:Q22) -> 0 | AA22: =sum(R22:V22) -> 0 | AB22: =sum(N22:O22) -> 0 | AC22: =sum(R22:S22,V22) -> 0 | AD22: 0.95
A23: 43577 | B23: 2006 | C23: 2038 | D23: =choose(weekday(A23),"Fred/Phil", "Jane/Murr", "Tom","Sue/Anne","Shawn/Orems","Jeff", "Rob") -> Jane/Murr | G23: 43577 | I23: =iferror(24*( DATEDIF(A23,G23,"D")+TIMEVALUE(H23)-TIMEVALUE(F23)),0) -> 0 | N23: 0 | O23: 0 | P23: 0 | Q23: 0 | R23: 0 | S23: 0 | T23: 0 | U23: 0 | V23: 0 | W23: 0 | X23: 0 | Y23: 0 | Z23: =sum(N23:Q23) -> 0 | AA23: =sum(R23:V23) -> 0 | AB23: =sum(N23:O23) -> 0 | AC23: =sum(R23:S23,V23) -> 0 | AD23: 0.9
A24: 43578 | B24: 2007 | C24: 2039 | D24: =choose(weekday(A24),"Fred/Phil", "Jane/Murr", "Tom","Sue/Anne","Shawn/Orems","Jeff", "Rob") -> Tom | G24: 43578 | I24: =iferror(24*( DATEDIF(A24,G24,"D")+TIMEVALUE(H24)-TIMEVALUE(F24)),0) -> 0 | N24: 0 | O24: 0 | P24: 0 | Q24: 0 | R24: 0 | S24: 0 | T24: 0 | U24: 0 | V24: 0 | W24: 0 | X24: 0 | Y24: 0 | Z24: =sum(N24:Q24) -> 0 | AA24: =sum(R24:V24) -> 0 | AB24: =sum(N24:O24) -> 0 | AC24: =sum(R24:S24,V24) -> 0 | AD24: 0.83
A25: 43579 | B25: 2008 | C25: 2040 | D25: =choose(weekday(A25),"Fred/Phil", "Jane/Murr", "Tom","Sue/Anne","Shawn/Orems","Jeff", "Rob") -> Sue/Anne | G25: 43579 | I25: =iferror(24*( DATEDIF(A25,G25,"D")+TIMEVALUE(H25)-TIMEVALUE(F25)),0) -> 0 | N25: 0 | O25: 0 | P25: 0 | Q25: 0 | R25: 0 | S25: 0 | T25: 0 | U25: 0 | V25: 0 | W25: 0 | X25: 0 | Y25: 0 | Z25: =sum(N25:Q25) -> 0 | AA25: =sum(R25:V25) -> 0 | AB25: =sum(N25:O25) -> 0 | AC25: =sum(R25:S25,V25) -> 0 | AD25: 0.74
... A31: 43585 | B31: 2016 | C31: 2049 | D31: =choose(weekday(A31),"Fred/Phil", "Jane/Murr", "Tom","Sue/Anne","Shawn/Orems","Jeff", "Rob") -> Tom | G31: 43585 | I31: =iferror(24*( DATEDIF(A31,G31,"D")+TIMEVALUE(H31)-TIMEVALUE(F31)),0) -> 0 | N31: 0 | O31: 0 | P31: 0 | Q31: 0 | R31: 0 | S31: 0 | T31: 0 | U31: 0 | V31: 0 | W31: 0 | X31: 0 | Y31: 0 | Z31: =sum(N31:Q31) -> 0 | AA31: =sum(R31:V31) -> 0 | AB31: =sum(N31:O31) -> 0 | AC31: =sum(R31:S31,V31) -> 0 | AD31: 0.2
A32: xx/xx/xxxx | B32: X | C32: X | I32: =H32-F32 -> 0 | N32: xxxx | O32: xxxx | P32: xxxx | Q32: xxxx | R32: xxxx | S32: xxxx | T32: xxxx | U32: xxxx | V32: xxxx | W32: xxxx | X32: xxxx | Y32: xxxx | Z32: xxxx | AA32: xxxx | AB32: xxxx | AC32: xxxx | AD32: X
D33: Monthly total | I33: =SUM(I3:I32) -> 17.5 | J33: =SUM(J2:J32) -> 63.23 | N33: =sum(N2:N32) -> 0 | O33: =sum(O2:O32) -> 0 | P33: =sum(P2:P32) -> 0 | Q33: =sum(Q2:Q32) -> 0 | R33: =sum(R2:R32) -> 17 | S33: =sum(S2:S32) -> 294 | T33: =sum(T2:T32) -> 0 | U33: =sum(U2:U32) -> 0 | ... Y33: =sum(Y2:Y32) -> 2 | Z33: =SUM(Z2:Z32) -> 0 | AA33: =SUM(AA2:AA32) -> 316 | AB33: =sum(AB2:AB32) -> 0 | AC33: =sum(AC2:AC32) -> 316
D34: Cumulative Total | I34: ='November 2018'!I$34+'December 2018'!I$33+'January 2019'!I$33+'February 2019'!I$33+'March 2019'!I$33+'April 2019'!I$33 -> 145.81028 | J34: ='November 2018'!J$34+'December 2018'!J$33+'January 2019'!J$33+'February 2019'!J$33+'March 2019'!J$33+'April 2019'!J$33 -> 558.96167 | N34: ='November 2018'!N$34+'December 2018'!N$33+'January 2019'!N$33+'February 2019'!N$33+'March 2019'!N$33+'April 2019'!N$33 -> 90 | O34: ='November 2018'!O$34+'December 2018'!O$33+'January 2019'!O$33+'February 2019'!O$33+'March 2019'!O$33+'April 2019'!O$33 -> 1134 | P34: ='November 2018'!P$34+'December 2018'!P$33+'January 2019'!P$33+'February 2019'!P$33+'March 2019'!P$33+'April 2019'!P$33 -> 3 | Q34: ='November 2018'!Q$34+'December 2018'!Q$33+'January 2019'!Q$33+'February 2019'!Q$33+'March 2019'!Q$33+'April 2019'!Q$33 -> 4 | R34: ='November 2018'!R$34+'December 2018'!R$33+'January 2019'!R$33+'February 2019'!R$33+'March 2019'!R$33+'April 2019'!R$33 -> 124 | S34: ='November 2018'!S$34+'December 2018'!S$33+'January 2019'!S$33+'February 2019'!S$33+'March 2019'!S$33+'April 2019'!S$33 -> 791 | T34: ='November 2018'!T$34+'December 2018'!T$33+'January 2019'!T$33+'February 2019'!T$33+'March 2019'!T$33+'April 2019'!T$33 -> 6 | U34: ='November 2018'!U$34+'December 2018'!U$33+'January 2019'!U$33+'February 2019'!U$33+'March 2019'!U$33+'April 2019'!U$33 -> 17 | ... AA34: ='November 2018'!AA$34+'December 2018'!AA$33+'January 2019'!AA$33+'February 2019'!AA$33+'March 2019'!AA$33+'April 2019'!AA$33 -> 944 | AB34: ='November 2018'!AB34+'December 2018'!AB33+'January 2019'!AB33+'February 2019'!AB33+'March 2019'!AB33+'April 2019'!AB33 -> 1224 | AC34: ='November 2018'!AC34+'December 2018'!AC33+'January 2019'!AC33+'February 2019'!AC33+'March 2019'!AC33+'April 2019'!AC33 -> 921
D35: Season Total | I35: ='November 2018'!I$34+'December 2018'!I$33+'January 2019'!I$33+'February 2019'!I$33+'March 2019'!I$33+'April 2019'!I$33 -> 145.81028 | J35: ='November 2018'!J34+'December 2018'!J33+'January 2019'!J33+'February 2019'!J33+'March 2019'!J33+'April 2019'!J33 -> 558.96167 | N35: ='November 2018'!N34+'December 2018'!N33+'January 2019'!N33+'February 2019'!N33+'March 2019'!N33+'April 2019'!N33 -> 90 | O35: ='November 2018'!O34+'December 2018'!O33+'January 2019'!O33+'February 2019'!O33+'March 2019'!O33+'April 2019'!O33 -> 1134 | P35: ='November 2018'!P34+'December 2018'!P33+'January 2019'!P33+'February 2019'!P33+'March 2019'!P33+'April 2019'!P33 -> 3 | Q35: ='November 2018'!Q34+'December 2018'!Q33+'January 2019'!Q33+'February 2019'!Q33+'March 2019'!Q33+'April 2019'!Q33 -> 4 | R35: ='November 2018'!R34+'December 2018'!R33+'January 2019'!R33+'February 2019'!R33+'March 2019'!R33+'April 2019'!R33 -> 124 | S35: ='November 2018'!S34+'December 2018'!S33+'January 2019'!S33+'February 2019'!S33+'March 2019'!S33+'April 2019'!S33 -> 791 | T35: ='November 2018'!T34+'December 2018'!T33+'January 2019'!T33+'February 2019'!T33+'March 2019'!T33+'April 2019'!T33 -> 6 | U35: ='November 2018'!U34+'December 2018'!U33+'January 2019'!U33+'February 2019'!U33+'March 2019'!U33+'April 2019'!U33 -> 17 | ... AC35: ='November 2018'!AC34+'December 2018'!AC33+'January 2019'!AC33+'February 2019'!AC33+'March 2019'!AC33+'April 2019'!AC33 -> 921 | AE35: =Z35+AA35 -> 2175 | AF35: =(AA35-Z35)/Z35 -> -0.23314379
D36: 2017-18 Total | N36: 135 | O36: 281 | P36: 7 | Q36: 10 | R36: 104 | S36: 165 | T36: 9 | U36: 7 | Z36: 433 | AA36: 297 | AB36: =sum(N36:O36) -> 416 | AC36: =sum(R36:S36) -> 269 | AE36: =Z36+AA36 -> 730 | AF36: =(AA36-Z36)/Z36 -> -0.31408776
D37: 2016-17 Total | N37: 465 | O37: 340 | P37: 24 | Q37: 5 | R37: 387 | S37: 343 | T37: 16 | U37: 5 | Z37: 834 | AA37: 751 | AB37: 805 | AC37: =sum(R37:S37) -> 730 | AE37: =Z37+AA37 -> 1585 | AF37: =(AA37-Z37)/Z37 -> -0.099520384
D38: 2015-16 Total | Z38: 688 | AA38: 1040 | AE38: =Z38+AA38 -> 1728 | AF38: =(AA38-Z38)/Z38 -> 0.51162791
D39: 2014-15 Total | Z39: 695 | AA39: 750 | AE39: =Z39+AA39 -> 1445 | AF39: =(AA39-Z39)/Z39 -> 0.079136691
D40: 2013-14 Total | Z40: 580 | AA40: 572 | AE40: =Z40+AA40 -> 1152 | AF40: =(AA40-Z40)/Z40 -> -0.013793103

Sheet November 2018
A1: Date | B1: Sunset | C1: Civil Twilight | D1: Captain | E1: Monitored (Y/N) | F1: Start time HH:MM | G1: End Date | H1: End time HH:MM | I1: Hours Monitored | J1: Team Hrs. | K1: Start Temp | L1: End Temp | M1: Weather | N1: Females assisted down | O1: Males assisted down | P1: Females unassisted down | Q1: Males unassisted down | R1: Females assisted up | S1: Males assisted up | T1: Females unassisted up | U1: Males unassisted up | V1: Juveniles | W1: Roadkills female | X1: Roadkills male | Y1: Roadkills unk | Z1: Total Frogs down | AA1: Total Frogs up | AB1: Total Frogs Assisted Down | AC1: Total Frogs Assisted Up | AD1: % moon visible | AE1: Comments
A2: 43405 | B2: 1757 | C2: 1828 | D2: =choose(weekday(A2),"Fred/Phil", "Jane/Murr", "Tom","Sue/Anne","Shawn/Orems","Jeff", "Rob") -> Shawn/Orems | G2: 43405 | I2: =iferror(24*( DATEDIF(A2,G2,"D")+TIMEVALUE(H2)-TIMEVALUE(F2)),0) -> 0 | N2: 0 | O2: 0 | P2: 0 | Q2: 0 | R2: 0 | S2: 0 | T2: 0 | U2: 0 | V2: 0 | W2: 0 | X2: 0 | Y2: 0 | Z2: =sum(N2:Q2) -> 0 | AA2: =sum(R2:V2) -> 0 | AB2: =sum(N2:O2) -> 0 | AC2: =sum(R2:S2,V2) -> 0 | AD2: 0.43
A3: 43406 | B3: 1756 | C3: 1827 | D3: =choose(weekday(A3),"Fred/Phil", "Jane/Murr", "Tom","Sue/Anne","Shawn/Orems","Jeff", "Rob") -> Jeff | E3: N | F3: 0.8125 | G3: 43406 | H3: 0.8125 | I3: =iferror(24*( DATEDIF(A3,G3,"D")+TIMEVALUE(H3)-TIMEVALUE(F3)),0) -> 0 | J3: 0 | K3: 60 | L3: 60 | M3: Dry and clear all day | N3: 0 | O3: 0 | P3: 0 | Q3: 0 | R3: 0 | S3: 0 | T3: 0 | U3: 0 | V3: 0 | W3: 0 | X3: 0 | Y3: 0 | Z3: =sum(N3:Q3) -> 0 | AA3: =sum(R3:V3) -> 0 | AB3: =sum(N3:O3) -> 0 | AC3: =sum(R3:S3,V3) -> 0 | AD3: 0.32 | AE3: Walked the wetland. Standing water is collecting but is concealed by the grass in most areas. NW corner near western dike has open, reflecting water, << 1% of total wetland area.
A4: 43407 | B4: 1755 | C4: 1826 | D4: =choose(weekday(A4),"Fred/Phil", "Jane/Murr", "Tom","Sue/Anne","Shawn/Orems","Jeff", "Rob") -> Rob | G4: 43407 | I4: =iferror(24*( DATEDIF(A4,G4,"D")+TIMEVALUE(H4)-TIMEVALUE(F4)),0) -> 0 | N4: 0 | O4: 0 | P4: 0 | Q4: 0 | R4: 0 | S4: 0 | T4: 0 | U4: 0 | V4: 0 | W4: 0 | X4: 0 | Y4: 0 | Z4: =sum(N4:Q4) -> 0 | AA4: =sum(R4:V4) -> 0 | AB4: =sum(N4:O4) -> 0 | AC4: =sum(R4:S4,V4) -> 0 | AD4: 0.22
A5: 43408 | B5: 1653 | C5: 1724 | D5: =choose(weekday(A5),"Fred/Phil", "Jane/Murr", "Tom","Sue/Anne","Shawn/Orems","Jeff", "Rob") -> Fred/Phil | G5: 43408 | I5: =iferror(24*( DATEDIF(A5,G5,"D")+TIMEVALUE(H5)-TIMEVALUE(F5)),0) -> 0 | N5: 0 | O5: 0 | P5: 0 | Q5: 0 | R5: 0 | S5: 0 | T5: 0 | U5: 0 | V5: 0 | W5: 0 | X5: 0 | Y5: 0 | Z5: =sum(N5:Q5) -> 0 | AA5: =sum(R5:V5) -> 0 | AB5: =sum(N5:O5) -> 0 | AC5: =sum(R5:S5,V5) -> 0 | AD5: 0.13
A6: 43409 | B6: 1652 | C6: 1723 | D6: =choose(weekday(A6),"Fred/Phil", "Jane/Murr", "Tom","Sue/Anne","Shawn/Orems","Jeff", "Rob") -> Jane/Murr | E6: N | F6: 0.72916667 | G6: 43409 | I6: =iferror(24*( DATEDIF(A6,G6,"D")+TIMEVALUE(H6)-TIMEVALUE(F6)),0) -> 0 | K6: 47 | L6: 48 | M6: Dry | N6: 0 | O6: 0 | P6: 0 | Q6: 0 | R6: 0 | S6: 0 | T6: 0 | U6: 0 | V6: 0 | W6: 0 | X6: 0 | Y6: 0 | Z6: =sum(N6:Q6) -> 0 | AA6: =sum(R6:V6) -> 0 | AB6: =sum(N6:O6) -> 0 | AC6: =sum(R6:S6,V6) -> 0 | AD6: 0.07
A7: 43410 | B7: 1651 | C7: 1722 | D7: =choose(weekday(A7),"Fred/Phil", "Jane/Murr", "Tom","Sue/Anne","Shawn/Orems","Jeff", "Rob") -> Tom | G7: 43410 | I7: =iferror(24*( DATEDIF(A7,G7,"D")+TIMEVALUE(H7)-TIMEVALUE(F7)),0) -> 0 | N7: 0 | O7: 0 | P7: 0 | Q7: 0 | R7: 0 | S7: 0 | T7: 0 | U7: 0 | V7: 0 | W7: 0 | X7: 0 | Y7: 0 | Z7: =sum(N7:Q7) -> 0 | AA7: =sum(R7:V7) -> 0 | AB7: =sum(N7:O7) -> 0 | AC7: =sum(R7:S7,V7) -> 0 | AD7: 0.02
A8: 43411 | B8: 1649 | C8: 1721 | D8: =choose(weekday(A8),"Fred/Phil", "Jane/Murr", "Tom","Sue/Anne","Shawn/Orems","Jeff", "Rob") -> Sue/Anne | G8: 43411 | I8: =iferror(24*( DATEDIF(A8,G8,"D")+TIMEVALUE(H8)-TIMEVALUE(F8)),0) -> 0 | N8: 0 | O8: 0 | P8: 0 | Q8: 0 | R8: 0 | S8: 0 | T8: 0 | U8: 0 | V8: 0 | W8: 0 | X8: 0 | Y8: 0 | Z8: =sum(N8:Q8) -> 0 | AA8: =sum(R8:V8) -> 0 | AB8: =sum(N8:O8) -> 0 | AC8: =sum(R8:S8,V8) -> 0 | AD8: 0
A9: 43412 | B9: 1648 | C9: 1720 | D9: =choose(weekday(A9),"Fred/Phil", "Jane/Murr", "Tom","Sue/Anne","Shawn/Orems","Jeff", "Rob") -> Shawn/Orems | E9: N | G9: 43412 | I9: =iferror(24*( DATEDIF(A9,G9,"D")+TIMEVALUE(H9)-TIMEVALUE(F9)),0) -> 0 | N9: 0 | O9: 0 | P9: 0 | Q9: 0 | R9: 0 | S9: 0 | T9: 0 | U9: 0 | V9: 0 | W9: 0 | X9: 0 | Y9: 0 | Z9: =sum(N9:Q9) -> 0 | AA9: =sum(R9:V9) -> 0 | AB9: =sum(N9:O9) -> 0 | AC9: =sum(R9:S9,V9) -> 0 | AD9: 0.01
A10: 43413 | B10: 1647 | C10: 1718 | D10: =choose(weekday(A10),"Fred/Phil", "Jane/Murr", "Tom","Sue/Anne","Shawn/Orems","Jeff", "Rob") -> Jeff | E10: Y | F10: 0.77083333 | G10: 43413 | H10: 0.77430556 | I10: =iferror(24*( DATEDIF(A10,G10,"D")+TIMEVALUE(H10)-TIMEVALUE(F10)),0) -> 0.083333333 | K10: 47 | L10: 47 | M10: Dry, light overcast, no rain | N10: 0 | O10: 0 | P10: 0 | Q10: 0 | R10: 0 | S10: 0 | T10: 0 | U10: 0 | V10: 0 | W10: 0 | X10: 0 | Y10: 0 | Z10: =sum(N10:Q10) -> 0 | AA10: =sum(R10:V10) -> 0 | AB10: =sum(N10:O10) -> 0 | AC10: =sum(R10:S10,V10) -> 0 | AD10: 0.03
A11: 43414 | B11: 1646 | C11: 1717 | D11: =choose(weekday(A11),"Fred/Phil", "Jane/Murr", "Tom","Sue/Anne","Shawn/Orems","Jeff", "Rob") -> Rob | G11: 43414 | I11: =iferror(24*( DATEDIF(A11,G11,"D")+TIMEVALUE(H11)-TIMEVALUE(F11)),0) -> 0 | N11: 0 | O11: 0 | P11: 0 | Q11: 0 | R11: 0 | S11: 0 | T11: 0 | U11: 0 | V11: 0 | W11: 0 | X11: 0 | Y11: 0 | Z11: =sum(N11:Q11) -> 0 | AA11: =sum(R11:V11) -> 0 | AB11: =sum(N11:O11) -> 0 | AC11: =sum(R11:S11,V11) -> 0 | AD11: 0.08
A12: 43415 | B12: 1644 | C12: 1716 | D12: =choose(weekday(A12),"Fred/Phil", "Jane/Murr", "Tom","Sue/Anne","Shawn/Orems","Jeff", "Rob") -> Fred/Phil | G12: 43415 | I12: =iferror(24*( DATEDIF(A12,G12,"D")+TIMEVALUE(H12)-TIMEVALUE(F12)),0) -> 0 | N12: 0 | O12: 0 | P12: 0 | Q12: 0 | R12: 0 | S12: 0 | T12: 0 | U12: 0 | V12: 0 | W12: 0 | X12: 0 | Y12: 0 | Z12: =sum(N12:Q12) -> 0 | AA12: =sum(R12:V12) -> 0 | AB12: =sum(N12:O12) -> 0 | AC12: =sum(R12:S12,V12) -> 0 | AD12: 0.14
A13: 43416 | B13: 1643 | C13: 1715 | D13: =choose(weekday(A13),"Fred/Phil", "Jane/Murr", "Tom","Sue/Anne","Shawn/Orems","Jeff", "Rob") -> Jane/Murr | E13: N | F13: 0.72916667 | G13: 43416 | H13: 0.72916667 | I13: =iferror(24*( DATEDIF(A13,G13,"D")+TIMEVALUE(H13)-TIMEVALUE(F13)),0) -> 0 | K13: 48 | L13: 348 | M13: Very dry | N13: 0 | O13: 0 | P13: 0 | Q13: 0 | R13: 0 | S13: 0 | T13: 0 | U13: 0 | V13: 0 | W13: 0 | X13: 0 | Y13: 0 | Z13: =sum(N13:Q13) -> 0 | AA13: =sum(R13:V13) -> 0 | AB13: =sum(N13:O13) -> 0 | AC13: =sum(R13:S13,V13) -> 0 | AD13: 0.21
A14: 43417 | B14: 1642 | C14: 1714 | D14: =choose(weekday(A14),"Fred/Phil", "Jane/Murr", "Tom","Sue/Anne","Shawn/Orems","Jeff", "Rob") -> Tom | G14: 43417 | I14: =iferror(24*( DATEDIF(A14,G14,"D")+TIMEVALUE(H14)-TIMEVALUE(F14)),0) -> 0 | N14: 0 | O14: 0 | P14: 0 | Q14: 0 | R14: 0 | S14: 0 | T14: 0 | U14: 0 | V14: 0 | W14: 0 | X14: 0 | Y14: 0 | Z14: =sum(N14:Q14) -> 0 | AA14: =sum(R14:V14) -> 0 | AB14: =sum(N14:O14) -> 0 | AC14: =sum(R14:S14,V14) -> 0 | AD14: 0.29
A15: 43418 | B15: 1641 | C15: 1713 | D15: =choose(weekday(A15),"Fred/Phil", "Jane/Murr", "Tom","Sue/Anne","Shawn/Orems","Jeff", "Rob") -> Sue/Anne | G15: 43418 | I15: =iferror(24*( DATEDIF(A15,G15,"D")+TIMEVALUE(H15)-TIMEVALUE(F15)),0) -> 0 | N15: 0 | O15: 0 | P15: 0 | Q15: 0 | R15: 0 | S15: 0 | T15: 0 | U15: 0 | V15: 0 | W15: 0 | X15: 0 | Y15: 0 | Z15: =sum(N15:Q15) -> 0 | AA15: =sum(R15:V15) -> 0 | AB15: =sum(N15:O15) -> 0 | AC15: =sum(R15:S15,V15) -> 0 | AD15: 0.38
A16: 43419 | B16: 1640 | C16: 1712 | D16: =choose(weekday(A16),"Fred/Phil", "Jane/Murr", "Tom","Sue/Anne","Shawn/Orems","Jeff", "Rob") -> Shawn/Orems | E16: N | G16: 43419 | I16: =iferror(24*( DATEDIF(A16,G16,"D")+TIMEVALUE(H16)-TIMEVALUE(F16)),0) -> 0 | N16: 0 | O16: 0 | P16: 0 | Q16: 0 | R16: 0 | S16: 0 | T16: 0 | U16: 0 | V16: 0 | W16: 0 | X16: 0 | Y16: 0 | Z16: =sum(N16:Q16) -> 0 | AA16: =sum(R16:V16) -> 0 | AB16: =sum(N16:O16) -> 0 | AC16: =sum(R16:S16,V16) -> 0 | AD16: 0.47
A17: 43420 | B17: 1639 | C17: 1711 | D17: =choose(weekday(A17),"Fred/Phil", "Jane/Murr", "Tom","Sue/Anne","Shawn/Orems","Jeff", "Rob") -> Jeff | E17: N | F17: 0.725 | G17: 43420 | H17: 0.725 | I17: =iferror(24*( DATEDIF(A17,G17,"D")+TIMEVALUE(H17)-TIMEVALUE(F17)),0) -> 0 | K17: 54 | L17: 54 | M17: Dry, light overcast | N17: 0 | O17: 0 | P17: 0 | Q17: 0 | R17: 0 | S17: 0 | T17: 0 | U17: 0 | V17: 0 | W17: 0 | X17: 0 | Y17: 0 | Z17: =sum(N17:Q17) -> 0 | AA17: =sum(R17:V17) -> 0 | AB17: =sum(N17:O17) -> 0 | AC17: =sum(R17:S17,V17) -> 0 | AD17: 0.57
A18: 43421 | B18: 1638 | C18: 1710 | D18: =choose(weekday(A18),"Fred/Phil", "Jane/Murr", "Tom","Sue/Anne","Shawn/Orems","Jeff", "Rob") -> Rob | G18: 43421 | I18: =iferror(24*( DATEDIF(A18,G18,"D")+TIMEVALUE(H18)-TIMEVALUE(F18)),0) -> 0 | N18: 0 | O18: 0 | P18: 0 | Q18: 0 | R18: 0 | S18: 0 | T18: 0 | U18: 0 | V18: 0 | W18: 0 | X18: 0 | Y18: 0 | Z18: =sum(N18:Q18) -> 0 | AA18: =sum(R18:V18) -> 0 | AB18: =sum(N18:O18) -> 0 | AC18: =sum(R18:S18,V18) -> 0 | AD18: 0.66
A19: 43422 | B19: 1637 | C19: 1710 | D19: =choose(weekday(A19),"Fred/Phil", "Jane/Murr", "Tom","Sue/Anne","Shawn/Orems","Jeff", "Rob") -> Fred/Phil | G19: 43422 | I19: =iferror(24*( DATEDIF(A19,G19,"D")+TIMEVALUE(H19)-TIMEVALUE(F19)),0) -> 0 | N19: 0 | O19: 0 | P19: 0 | Q19: 0 | R19: 0 | S19: 0 | T19: 0 | U19: 0 | V19: 0 | W19: 0 | X19: 0 | Y19: 0 | Z19: =sum(N19:Q19) -> 0 | AA19: =sum(R19:V19) -> 0 | AB19: =sum(N19:O19) -> 0 | AC19: =sum(R19:S19,V19) -> 0 | AD19: 0.75
A20: 43423 | B20: 1636 | C20: 1709 | D20: =choose(weekday(A20),"Fred/Phil", "Jane/Murr", "Tom","Sue/Anne","Shawn/Orems","Jeff", "Rob") -> Jane/Murr | E20: N | F20: 0.72916667 | G20: 43423 | H20: 0.72916667 | I20: =iferror(24*( DATEDIF(A20,G20,"D")+TIMEVALUE(H20)-TIMEVALUE(F20)),0) -> 0 | K20: 48 | M20: Dry | N20: 0 | O20: 0 | P20: 0 | Q20: 0 | R20: 0 | S20: 0 | T20: 0 | U20: 0 | V20: 0 | W20: 0 | X20: 0 | Y20: 0 | Z20: =sum(N20:Q20) -> 0 | AA20: =sum(R20:V20) -> 0 | AB20: =sum(N20:O20) -> 0 | AC20: =sum(R20:S20,V20) -> 0 | AD20: 0.83
A21: 43424 | B21: 1635 | C21: 1708 | D21: =choose(weekday(A21),"Fred/Phil", "Jane/Murr", "Tom","Sue/Anne","Shawn/Orems","Jeff", "Rob") -> Tom | G21: 43424 | I21: =iferror(24*( DATEDIF(A21,G21,"D")+TIMEVALUE(H21)-TIMEVALUE(F21)),0) -> 0 | N21: 0 | O21: 0 | P21: 0 | Q21: 0 | R21: 0 | S21: 0 | T21: 0 | U21: 0 | V21: 0 | W21: 0 | X21: 0 | Y21: 0 | Z21: =sum(N21:Q21) -> 0 | AA21: =sum(R21:V21) -> 0 | AB21: =sum(N21:O21) -> 0 | AC21: =sum(R21:S21,V21) -> 0 | AD21: 0.9
A22: 43425 | B22: 1635 | C22: 1707 | D22: =choose(weekday(A22),"Fred/Phil", "Jane/Murr", "Tom","Sue/Anne","Shawn/Orems","Jeff", "Rob") -> Sue/Anne | E22: Y | F22: 0.77083333 | G22: 43425 | H22: 0.78125 | I22: =iferror(24*( DATEDIF(A22,G22,"D")+TIMEVALUE(H22)-TIMEVALUE(F22)),0) -> 0.25 | K22: 48 | L22: 47 | M22: Very slight mist on and off | N22: 0 | O22: 0 | P22: 0 | Q22: 0 | R22: 0 | S22: 0 | T22: 0 | U22: 0 | V22: 0 | W22: 0 | X22: 0 | Y22: 0 | Z22: =sum(N22:Q22) -> 0 | AA22: =sum(R22:V22) -> 0 | AB22: =sum(N22:O22) -> 0 | AC22: =sum(R22:S22,V22) -> 0 | AD22: 0.95
A23: 43426 | B23: 1634 | C23: 1707 | D23: =choose(weekday(A23),"Fred/Phil", "Jane/Murr", "Tom","Sue/Anne","Shawn/Orems","Jeff", "Rob") -> Shawn/Orems | E23: Y (x2) | F23: 0.21875 | G23: 43426 | H23: 0.22916667 | I23: =iferror(24*( DATEDIF(A23,G23,"D")+TIMEVALUE(H23)-TIMEVALUE(F23)),0) -> 0.25 | K23: 47 | M23: Dry, wet pavement | N23: 0 | O23: 0 | P23: 0 | Q23: 0 | R23: 0 | S23: 0 | T23: 0 | U23: 0 | V23: 0 | W23: 0 | X23: 0 | Y23: 0 | Z23: =sum(N23:Q23) -> 0 | AA23: =sum(R23:V23) -> 0 | AB23: =sum(N23:O23) -> 0 | AC23: =sum(R23:S23,V23) -> 0 | AD23: 0.99
A24: 43426 | D24: =choose(weekday(A24),"Fred/Phil", "Jane/Murr", "Tom","Sue/Anne","Shawn/Orems","Jeff", "Rob") -> Shawn/Orems | E24: Y | F24: 0.27083333 | H24: 0.28125 | I24: 0.25 | K24: 47 | M24: Raining | N24: 0 | O24: 0 | P24: 0 | Q24: 0 | R24: 0
A25: 43427 | B25: 1633 | C25: 1706 | D25: =choose(weekday(A25),"Fred/Phil", "Jane/Murr", "Tom","Sue/Anne","Shawn/Orems","Jeff", "Rob") -> Jeff | E25: Y | F25: 0.71111111 | G25: 43427 | H25: 0.75 | I25: =iferror(24*( DATEDIF(A25,G25,"D")+TIMEVALUE(H25)-TIMEVALUE(F25)),0) -> 0.93333333 | K25: 47 | L25: 46 | M25: Very wet, off and on heavy rain | N25: 0 | O25: 0 | P25: 0 | Q25: 0 | R25: 0 | S25: 0 | T25: 0 | U25: 0 | V25: 0 | W25: 0 | X25: 0 | Y25: 0 | Z25: =sum(N25:Q25) -> 0 | AA25: =sum(R25:V25) -> 0 | AB25: =sum(N25:O25) -> 0 | AC25: =sum(R25:S25,V25) -> 0 | AD25: 1 | AE25: No visible or audible flow in creek. Thin, weak sheet flow in culvert box.
A26: 43428 | B26: 1632 | C26: 1705 | D26: =choose(weekday(A26),"Fred/Phil", "Jane/Murr", "Tom","Sue/Anne","Shawn/Orems","Jeff", "Rob") -> Rob | E26: y | F26: 0.19791667 | G26: 43428 | I26: =iferror(24*( DATEDIF(A26,G26,"D")+TIMEVALUE(H26)-TIMEVALUE(F26)),0) -> 0 | K26: 43 | M26: foggy, dry road | N26: 0 | O26: 0 | P26: 0 | Q26: 0 | R26: 0 | S26: 0 | T26: 0 | U26: 0 | V26: 0 | W26: 0 | X26: 0 | Y26: 0 | Z26: =sum(N26:Q26) -> 0 | AA26: =sum(R26:V26) -> 0 | AB26: =sum(N26:O26) -> 0 | AC26: =sum(R26:S26,V26) -> 0 | AD26: 0.98
A27: 43429 | B27: 1632 | C27: 1705 | D27: =choose(weekday(A27),"Fred/Phil", "Jane/Murr", "Tom","Sue/Anne","Shawn/Orems","Jeff", "Rob") -> Fred/Phil | E27: Y | F27: 0.71527778 | G27: 43429 | H27: 0.75 | I27: =iferror(24*( DATEDIF(A27,G27,"D")+TIMEVALUE(H27)-TIMEVALUE(F27)),0) -> 0.83333333 | K27: 44 | L27: 43 | M27: Foggy, dry road | N27: 0 | O27: 0 | P27: 0 | Q27: 0 | R27: 0 | S27: 0 | T27: 0 | U27: 0 | V27: 0 | W27: 0 | X27: 0 | Y27: 0 | Z27: =sum(N27:Q27) -> 0 | AA27: =sum(R27:V27) -> 0 | AB27: =sum(N27:O27) -> 0 | AC27: =sum(R27:S27,V27) -> 0 | AD27: 0.94
A28: 43430 | B28: 1631 | C28: 1704 | D28: =choose(weekday(A28),"Fred/Phil", "Jane/Murr", "Tom","Sue/Anne","Shawn/Orems","Jeff", "Rob") -> Jane/Murr | E28: Y | F28: 0.71527778 | G28: 43430 | H28: 0.77083333 | I28: =iferror(24*( DATEDIF(A28,G28,"D")+TIMEVALUE(H28)-TIMEVALUE(F28)),0) -> 1.3333333 | K28: 50 | L28: 51 | M28: Quick shower, but otherwise no rain | N28: 0 | O28: 0 | P28: 0 | Q28: 0 | R28: 0 | S28: 0 | T28: 0 | U28: 0 | V28: 0 | W28: 0 | X28: 0 | Y28: 0 | Z28: =sum(N28:Q28) -> 0 | AA28: =sum(R28:V28) -> 0 | AB28: =sum(N28:O28) -> 0 | AC28: =sum(R28:S28,V28) -> 0 | AD28: 0.88
A29: 43431 | B29: 1631 | C29: 1704 | D29: =choose(weekday(A29),"Fred/Phil", "Jane/Murr", "Tom","Sue/Anne","Shawn/Orems","Jeff", "Rob") -> Tom | G29: 43431 | I29: =iferror(24*( DATEDIF(A29,G29,"D")+TIMEVALUE(H29)-TIMEVALUE(F29)),0) -> 0 | N29: 0 | O29: 0 | P29: 0 | Q29: 0 | R29: 0 | S29: 0 | T29: 0 | U29: 0 | V29: 0 | W29: 0 | X29: 0 | Y29: 0 | Z29: =sum(N29:Q29) -> 0 | AA29: =sum(R29:V29) -> 0 | AB29: =sum(N29:O29) -> 0 | AC29: =sum(R29:S29,V29) -> 0 | AD29: 0.79
A30: 43432 | B30: 1630 | C30: 1703 | D30: =choose(weekday(A30),"Fred/Phil", "Jane/Murr", "Tom","Sue/Anne","Shawn/Orems","Jeff", "Rob") -> Sue/Anne | G30: 43432 | I30: =iferror(24*( DATEDIF(A30,G30,"D")+TIMEVALUE(H30)-TIMEVALUE(F30)),0) -> 0 | N30: 0 | O30: 0 | P30: 0 | Q30: 0 | R30: 0 | S30: 0 | T30: 0 | U30: 0 | V30: 0 | W30: 0 | X30: 0 | Y30: 0 | Z30: =sum(N30:Q30) -> 0 | AA30: =sum(R30:V30) -> 0 | AB30: =sum(N30:O30) -> 0 | AC30: =sum(R30:S30,V30) -> 0 | AD30: 0.69
A31: 43433 | B31: 1630 | C31: 1703 | D31: =choose(weekday(A31),"Fred/Phil", "Jane/Murr", "Tom","Sue/Anne","Shawn/Orems","Jeff", "Rob") -> Shawn/Orems | E31: N | F31: 0.72916667 | G31: 43433 | I31: =iferror(24*( DATEDIF(A31,G31,"D")+TIMEVALUE(H31)-TIMEVALUE(F31)),0) -> 0 | K31: 47 | M31: Dry | N31: 0 | O31: 0 | P31: 0 | Q31: 0 | R31: 0 | S31: 0 | T31: 0 | U31: 0 | V31: 0 | W31: 0 | X31: 0 | Y31: 0 | Z31: =sum(N31:Q31) -> 0 | AA31: =sum(R31:V31) -> 0 | AB31: =sum(N31:O31) -> 0 | AC31: =sum(R31:S31,V31) -> 0 | AD31: 0.58
A32: 43434 | B32: 1629 | C32: 1703 | D32: =choose(weekday(A32),"Fred/Phil", "Jane/Murr", "Tom","Sue/Anne","Shawn/Orems","Jeff", "Rob") -> Jeff | E32: Y | F32: 0.70833333 | G32: 43434 | H32: 0.75347222 | I32: =iferror(24*( DATEDIF(A32,G32,"D")+TIMEVALUE(H32)-TIMEVALUE(F32)),0) -> 1.0833333 | K32: 44 | L32: 44 | M32: Dense low clouds, heavy rain turning to showers | N32: 0 | O32: 0 | P32: 0 | Q32: 0 | R32: 0 | S32: 0 | T32: 0 | U32: 0 | V32: 0 | W32: 0 | X32: 0 | Y32: 0 | Z32: =sum(N32:Q32) -> 0 | AA32: =sum(R32:V32) -> 0 | AB32: =sum(N32:O32) -> 0 | AC32: =sum(R32:S32,V32) -> 0 | AD32: 0.47 | AE32: No visible or audible flow in creek. Weak flow in culvert box.
A33: XX/XX/XX | X33: x | Y33: x | Z33: x | AA33: x | AD33: x
E34: Monthly total | I34: =sum(I2:I33) -> 5.0166667 | J34: =sum(J2:J33) -> 0 | N34: =sum(N2:N33) -> 0 | O34: =sum(O2:O33) -> 0 | P34: =sum(P2:P33) -> 0 | Q34: =sum(Q2:Q33) -> 0 | R34: =sum(R2:R33) -> 0 | S34: =sum(S2:S33) -> 0 | T34: =sum(T2:T33) -> 0 | U34: =sum(U2:U33) -> 0 | ... AC34: =sum(AC2:AC33) -> 0
E35: Cumulative Total | I35: ='November 2018'!I$34 -> 5.0166667 | J35: ='November 2018'!J$34 -> 0 | N35: ='November 2018'!N$34 -> 0 | O35: ='November 2018'!O$34 -> 0 | P35: ='November 2018'!P$34 -> 0 | Q35: ='November 2018'!Q$34 -> 0 | R35: ='November 2018'!R$34 -> 0 | S35: ='November 2018'!S$34 -> 0 | T35: ='November 2018'!T$34 -> 0 | U35: ='November 2018'!U$34 -> 0 | ... AB35: ='November 2018'!AB$34 -> 0 | AC35: ='November 2018'!AC34 -> 0
E36: Season Total | I36: ='November 2018'!I$34+'December 2018'!I$33+'January 2019'!I$33+'February 2019'!I$33+'March 2019'!I$33+'April 2019'!I$33 -> 145.81028 | J36: ='November 2018'!J34+'December 2018'!J33+'January 2019'!J33+'February 2019'!J33+'March 2019'!J33+'April 2019'!J33 -> 558.96167 | N36: ='November 2018'!N34+'December 2018'!N33+'January 2019'!N33+'February 2019'!N33+'March 2019'!N33+'April 2019'!N33 -> 90 | O36: ='November 2018'!O34+'December 2018'!O33+'January 2019'!O33+'February 2019'!O33+'March 2019'!O33+'April 2019'!O33 -> 1134 | P36: ='November 2018'!P34+'December 2018'!P33+'January 2019'!P33+'February 2019'!P33+'March 2019'!P33+'April 2019'!P33 -> 3 | Q36: ='November 2018'!Q34+'December 2018'!Q33+'January 2019'!Q33+'February 2019'!Q33+'March 2019'!Q33+'April 2019'!Q33 -> 4 | R36: ='November 2018'!R34+'December 2018'!R33+'January 2019'!R33+'February 2019'!R33+'March 2019'!R33+'April 2019'!R33 -> 124 | S36: ='November 2018'!S34+'December 2018'!S33+'January 2019'!S33+'February 2019'!S33+'March 2019'!S33+'April 2019'!S33 -> 791 | T36: ='November 2018'!T34+'December 2018'!T33+'January 2019'!T33+'February 2019'!T33+'March 2019'!T33+'April 2019'!T33 -> 6 | U36: ='November 2018'!U34+'December 2018'!U33+'January 2019'!U33+'February 2019'!U33+'March 2019'!U33+'April 2019'!U33 -> 17 | ... AC36: ='November 2018'!AC34+'December 2018'!AC33+'January 2019'!AC33+'February 2019'!AC33+'March 2019'!AC33+'April 2019'!AC33 -> 921
E37: 2017-18 Total | Z37: 433 | AA37: 297
E38: 2016-17 Total | Z38: 834 | AA38: 751
E39: 2015-16 Total | Z39: 688 | AA39: 1040
E40: 2014-15 Total | Z40: 695 | AA40: 750
...

Sheet January 2019
A1: Date | B1: Sunset | C1: Civil Twilight | D1: Captain | E1: Monitored (Y/N) | F1: Start time HH:MM | G1: End Date | H1: End time HH:MM | I1: Hours monitored | J1: Team Hrs. | K1: Start Temp. | L1: End Temp | M1: Weather | N1: Females assisted down | O1: Males assisted down | P1: Unassisted Females down | Q1: Unasissted Males down | R1: Females assisted up | S1: Males assisted up | T1: Unassisted females up | U1: Unassisted males up | V1: Juveniles | W1: Roadkill Females | X1: Roadkill Males | Y1: Roadkill Unk | Z1: Total frogs down | AA1: Total frogs up | AB1: Total Frogs Assisted Down | AC1: Total Frogs Assisted Up | AD1: % moon visible | AE1: Comments
A2: 43466 | B2: 1638 | C2: 1712 | D2: =choose(weekday(A2),"Fred/Phil", "Jane/Murr", "Tom","Sue/Anne","Shawn/Orems","Jeff", "Rob") -> Tom | E2: N | F2: 0.70833333 | G2: 43466 | H2: 0.70833333 | I2: =iferror(24*( DATEDIF(A2,G2,"D")+TIMEVALUE(H2)-TIMEVALUE(F2)),0) -> 0 | J2: 0 | K2: 44 | L2: 44 | M2: Cold and dry | N2: 0 | O2: 0 | P2: 0 | Q2: 0 | R2: 0 | S2: 0 | T2: 0 | U2: 0 | V2: 0 | W2: 0 | X2: 0 | Y2: 0 | Z2: =sum(N2:Q2) -> 0 | AA2: =sum(R2:V2) -> 0 | AB2: =sum(N2:O2) -> 0 | AC2: =sum(R2:S2,V2) -> 0 | AD2: 0.21
