Workbook
Name dec_tot_down: 'December 2020'!$Z$33
Name apr_tot_down: #REF!
Name jan_tot_down: 'January 2021'!$Z$33
Name jan_tot_hrs: 'January 2021'!$J$33
Name mar_tot_up: 'April 2021'!$AA$33
Name apr_tot_up: #REF!
Name mar_tot_down: 'March 2021'!$Z$33
Name feb_tot_hrs: 'February 2021'!$J$33
Name nov_tot_up: 'November 2020'!$AA$33
Name feb_tot_down: 'February 2021'!$Z$33
Name nov_tot_down: 'November 2020'!$Z$33
Name mar_tot_hrs: 'March 2021'!$J$33
Name nov_tot_hrs: 'November 2020'!$J$33
Name MAR_F_A_DN: 'March 2021'!$N$33
Name MAR_F_A_DN: 'April 2021'!$N$33
Name mar_tot_hrs: 'April 2021'!$J$33
Name jan_tot_up: 'January 2021'!$AA$33
Name dec_tot_up: 'December 2020'!$AA$33
Name feb_tot_up: 'February 2021'!$AA$33
Name mar_tot_down: 'April 2021'!$Z$33
Name mar_tot_up: 'March 2021'!$AA$33
Name dec_tot_hrs: 'December 2020'!$J$33

Sheet February 2021
A1: 28 | B1: Sunset | C1: Civil Twilight | D1: Captain | E1: Monitored (Y/N) | F1: Start time HH:MM | G1: End Date | H1: End time HH:MM | I1: Hours monitored | J1: Team Hrs. | K1: Start Temp | L1: End Temp | M1: Weather | N1: Females assisted down | O1: Males assisted down | P1: Unassisted Females down | Q1: Unasissted Males down | R1: Females assisted up | S1: Males assisted up | T1: Unassisted females up | U1: Unassisted males up | V1: Juveniles assisted up | W1: Roadkill Females | X1: Roadkill Males | Y1: Roadkill Unk | Z1: Total frogs down | AA1: Total frogs up | AB1: Total Frogs Assisted Down | AC1: Total Frogs Assisted Up | AD1: % moon visible | AE1: Comments
A2: 44228 | B2: 1717 | C2: 1748 | D2: =choose(weekday(A2),"Phil/Fred", "Jane/Sara", "Jim/John/Lena","Marsha/Anne","Shawn/Jenny","Jeff", "Rob/Maggie") -> Jane/Sara | E2: Y | F2: 0.72916667 | G2: 44228 | H2: 0.86458333 | I2: =iferror(24*( DATEDIF(A2,G2,"D")+TIMEVALUE(H2)-TIMEVALUE(F2)),0) -> 3.25 | J2: 18.5 | K2: 50.3 | L2: 46.5 | M2: light rain then clearing | N2: 1 | O2: 0 | P2: 1 | Q2: 0 | R2: 9 | S2: 0 | T2: 0 | U2: 0 | V2: 0 | W2: 0 | X2: 0 | Y2: 0 | Z2: =sum(N2:Q2) -> 2 | AA2: 0 | AB2: =sum(N2:O2) -> 1 | AC2: =sum(R2:S2,V2) -> 9 | AD2: 0.21 | AE2: Ideal conditions for first two hours, but not many frogs.
A3: 44229 | B3: 1718 | C3: 1750 | D3: =choose(weekday(A3),"Phil/Fred", "Jane/Sarah", "Jim/John/Lena","Marsha/Anne","Shawn/Jenny","Jeff", "Rob/Maggie") -> Jim/John/Lena | E3: Y | F3: 0.72916667 | G3: 44229 | H3: 0.79166667 | I3: =iferror(24*( DATEDIF(A3,G3,"D")+TIMEVALUE(H3)-TIMEVALUE(F3)),0) -> 1.5 | J3: 6 | K3: 42.6 | L3: 41.8 | M3: dry then heavy rain | N3: 0 | O3: 0 | P3: 0 | Q3: 0 | R3: 0 | S3: 0 | T3: 0 | U3: 0 | V3: 0 | W3: 0 | X3: 0 | Y3: 0 | Z3: =sum(N3:Q3) -> 0 | AA3: =sum(R3:V3) -> 0 | AB3: =sum(N3:O3) -> 0 | AC3: =sum(R3:S3,V3) -> 0 | AD3: 0.13 | AE3: cold. wind blew Marina fence off. 1 PSRE female assisted down, 2 more PSRE observed on Marina
A4: 44230 | B4: 1720 | C4: 1751 | D4: =choose(weekday(A4),"Phil/Fred", "Jane/Sarah", "Jim/John/Lena","Marsha/Anne","Shawn/Jenny","Jeff", "Rob/Maggie") -> Marsha/Anne | E4: N | G4: 44230 | I4: =iferror(24*( DATEDIF(A4,G4,"D")+TIMEVALUE(H4)-TIMEVALUE(F4)),0) -> 0 | K4: 41 | N4: 0 | O4: 0 | P4: 0 | Q4: 0 | R4: 0 | S4: 0 | T4: 0 | U4: 0 | V4: 0 | W4: 0 | X4: 0 | Y4: 0 | Z4: =sum(N4:Q4) -> 0 | AA4: =sum(R4:V4) -> 0 | AB4: =sum(N4:O4) -> 0 | AC4: =sum(R4:S4,V4) -> 0 | AD4: 0.07
A5: 44231 | B5: 1721 | C5: 1753 | D5: =choose(weekday(A5),"Phil/Fred", "Jane/Sarah", "Jim/John/Lena","Marsha/Anne","Shawn/Jenny","Jeff", "Rob/Maggie") -> Shawn/Jenny | E5: Y | F5: 0.70833333 | G5: 44231 | H5: 0.8125 | I5: =iferror(24*( DATEDIF(A5,G5,"D")+TIMEVALUE(H5)-TIMEVALUE(F5)),0) -> 2.5 | J5: 6.5 | K5: 46 | L5: 45 | M5: Mist then clear | N5: 1 | O5: 0 | P5: 0 | Q5: 0 | R5: 0 | S5: 0 | T5: 0 | U5: 0 | V5: 0 | W5: 0 | X5: 0 | Y5: 0 | Z5: =sum(N5:Q5) -> 1 | AA5: =sum(R5:V5) -> 0 | AB5: =sum(N5:O5) -> 1 | AC5: =sum(R5:S5,V5) -> 0 | AD5: 0.03 | AE5: Small female down end of night--dry at the time.
A6: 44232 | B6: 1723 | C6: 1754 | D6: =choose(weekday(A6),"Phil/Fred", "Jane/Sarah", "Jim/John/Lena","Marsha/Anne","Shawn/Jenny","Jeff", "Rob/Maggie") -> Jeff | E6: N | F6: 0.70833333 | G6: 44232 | H6: 0.70833333 | I6: =iferror(24*( DATEDIF(A6,G6,"D")+TIMEVALUE(H6)-TIMEVALUE(F6)),0) -> 0 | K6: 47 | L6: 47 | M6: broken clouds, open sky | N6: 0 | O6: 0 | P6: 0 | Q6: 0 | R6: 0 | S6: 0 | T6: 0 | U6: 0 | V6: 0 | W6: 0 | X6: 0 | Y6: 0 | Z6: =sum(N6:Q6) -> 0 | AA6: =sum(R6:V6) -> 0 | AB6: =sum(N6:O6) -> 0 | AC6: =sum(R6:S6,V6) -> 0 | AD6: 0.01
A7: 44233 | B7: 1724 | C7: 1755 | D7: =choose(weekday(A7),"Phil/Fred", "Jane/Sarah", "Jim/John/Lena","Marsha/Anne","Shawn/Jenny","Jeff", "Rob/Maggie") -> Rob/Maggie | E7: y | F7: 0.71875 | G7: 44233 | H7: 0.78125 | I7: =iferror(24*( DATEDIF(A7,G7,"D")+TIMEVALUE(H7)-TIMEVALUE(F7)),0) -> 1.5 | J7: 2.45 | K7: 47 | L7: 44 | M7: misty then clearing | N7: 0 | O7: 0 | P7: 0 | Q7: 0 | R7: 0 | S7: 0 | T7: 0 | U7: 0 | V7: 0 | W7: 0 | X7: 0 | Y7: 0 | Z7: =sum(N7:Q7) -> 0 | AA7: =sum(R7:V7) -> 0 | AB7: =sum(N7:O7) -> 0 | AC7: =sum(R7:S7,V7) -> 0 | AD7: 0
A8: 44234 | B8: 1726 | C8: 1757 | D8: =choose(weekday(A8),"Phil/Fred", "Jane/Sarah", "Jim/John/Lena","Marsha/Anne","Shawn/Jenny","Jeff", "Rob/Maggie") -> Phil/Fred | E8: N | G8: 44234 | I8: =iferror(24*( DATEDIF(A8,G8,"D")+TIMEVALUE(H8)-TIMEVALUE(F8)),0) -> 0 | K8: 42 | M8: dry | N8: 0 | O8: 0 | P8: 0 | Q8: 0 | R8: 0 | S8: 0 | T8: 0 | U8: 0 | V8: 0 | W8: 0 | X8: 0 | Y8: 0 | Z8: 2 | AA8: 9 | AB8: 2 | AC8: 6 | AD8: 0.01
A9: 44235 | B9: 1727 | C9: 1758 | D9: =choose(weekday(A9),"Phil/Fred", "Jane/Sarah", "Jim/John/Lena","Marsha/Anne","Shawn/Jenny","Jeff", "Rob/Maggie") -> Jane/Sarah | E9: N | G9: 44235 | I9: =iferror(24*( DATEDIF(A9,G9,"D")+TIMEVALUE(H9)-TIMEVALUE(F9)),0) -> 0 | K9: 42 | M9: Cloudy, no rain | N9: 0 | O9: 0 | P9: 0 | Q9: 0 | R9: 0 | S9: 0 | T9: 0 | U9: 0 | V9: 0 | W9: 0 | X9: 0 | Y9: 0 | Z9: =sum(N9:Q9) -> 0 | AA9: =sum(R9:V9) -> 0 | AB9: =sum(N9:O9) -> 0 | AC9: =sum(R9:S9,V9) -> 0 | AD9: 0.05
A10: 44236 | B10: 1728 | C10: 1759 | D10: =choose(weekday(A10),"Phil/Fred", "Jane/Sarah", "Jim/John/Lena","Marsha/Anne","Shawn/Jenny","Jeff", "Rob/Maggie") -> Jim/John/Lena | E10: Y | F10: 0.72916667 | G10: 44236 | H10: 0.75 | I10: =iferror(24*( DATEDIF(A10,G10,"D")+TIMEVALUE(H10)-TIMEVALUE(F10)),0) -> 0.5 | J10: 0.5 | K10: 37.9 | N10: 0 | O10: 0 | P10: 0 | Q10: 0 | R10: 0 | S10: 0 | T10: 0 | U10: 0 | V10: 0 | W10: 0 | X10: 0 | Y10: 0 | Z10: =sum(N10:Q10) -> 0 | AA10: =sum(R10:V10) -> 0 | AB10: =sum(N10:O10) -> 0 | AC10: =sum(R10:S10,V10) -> 0 | AD10: 0.09
A11: 44237 | B11: 1730 | C11: 1801 | D11: =choose(weekday(A11),"Phil/Fred", "Jane/Sarah", "Jim/John/Lena","Marsha/Anne","Shawn/Jenny","Jeff", "Rob/Maggie") -> Marsha/Anne | E11: N | G11: 44237 | I11: =iferror(24*( DATEDIF(A11,G11,"D")+TIMEVALUE(H11)-TIMEVALUE(F11)),0) -> 0 | N11: 0 | O11: 0 | P11: 0 | Q11: 0 | R11: 0 | S11: 0 | T11: 0 | U11: 0 | V11: 0 | W11: 0 | X11: 0 | Y11: 0 | Z11: =sum(N11:Q11) -> 0 | AA11: =sum(R11:V11) -> 0 | AB11: =sum(N11:O11) -> 0 | AC11: =sum(R11:S11,V11) -> 0 | AD11: 0.16
A12: 44238 | B12: 1731 | C12: 1802 | D12: =choose(weekday(A12),"Phil/Fred", "Jane/Sarah", "Jim/John/Lena","Marsha/Anne","Shawn/Jenny","Jeff", "Rob/Maggie") -> Shawn/Jenny | E12: N | F12: 0.70833333 | G12: 44238 | I12: =iferror(24*( DATEDIF(A12,G12,"D")+TIMEVALUE(H12)-TIMEVALUE(F12)),0) -> 0 | K12: 32 | M12: Snow flurrries | N12: 0 | O12: 0 | P12: 0 | Q12: 0 | R12: 0 | S12: 0 | T12: 0 | U12: 0 | V12: 0 | W12: 0 | X12: 0 | Y12: 0 | Z12: =sum(N12:Q12) -> 0 | AA12: =sum(R12:V12) -> 0 | AB12: =sum(N12:O12) -> 0 | AC12: =sum(R12:S12,V12) -> 0 | AD12: 0.23
A13: 44239 | B13: 1733 | C13: 1804 | D13: =choose(weekday(A13),"Phil/Fred", "Jane/Sarah", "Jim/John/Lena","Marsha/Anne","Shawn/Jenny","Jeff", "Rob/Maggie") -> Jeff | E13: N | G13: 44239 | I13: =iferror(24*( DATEDIF(A13,G13,"D")+TIMEVALUE(H13)-TIMEVALUE(F13)),0) -> 0 | N13: 0 | O13: 0 | P13: 0 | Q13: 0 | R13: 0 | S13: 0 | T13: 0 | U13: 0 | V13: 0 | W13: 0 | X13: 0 | Y13: 0 | Z13: =sum(N13:Q13) -> 0 | AA13: =sum(R13:V13) -> 0 | AB13: =sum(N13:O13) -> 0 | AC13: =sum(R13:S13,V13) -> 0 | AD13: 0.31
A14: 44240 | B14: 1734 | C14: 1805 | D14: =choose(weekday(A14),"Phil/Fred", "Jane/Sarah", "Jim/John/Lena","Marsha/Anne","Shawn/Jenny","Jeff", "Rob/Maggie") -> Rob/Maggie | E14: N | G14: 44240 | I14: =iferror(24*( DATEDIF(A14,G14,"D")+TIMEVALUE(H14)-TIMEVALUE(F14)),0) -> 0 | K14: 27 | M14: lots of snow | N14: 0 | O14: 0 | P14: 0 | Q14: 0 | R14: 0 | S14: 0 | T14: 0 | U14: 0 | V14: 0 | W14: 0 | X14: 0 | Y14: 0 | Z14: =sum(N14:Q14) -> 0 | AA14: =sum(R14:V14) -> 0 | AB14: =sum(N14:O14) -> 0 | AC14: =sum(R14:S14,V14) -> 0 | AD14: 0.41
A15: 44241 | B15: 1736 | C15: 1806 | D15: =choose(weekday(A15),"Phil/Fred", "Jane/Sarah", "Jim/John/Lena","Marsha/Anne","Shawn/Jenny","Jeff", "Rob/Maggie") -> Phil/Fred | E15: N | G15: 44241 | I15: =iferror(24*( DATEDIF(A15,G15,"D")+TIMEVALUE(H15)-TIMEVALUE(F15)),0) -> 0 | N15: 0 | O15: 0 | P15: 0 | Q15: 0 | R15: 0 | S15: 0 | T15: 0 | U15: 0 | V15: 0 | W15: 0 | X15: 0 | Y15: 0 | Z15: =sum(N15:Q15) -> 0 | AA15: =sum(R15:V15) -> 0 | AB15: =sum(N15:O15) -> 0 | AC15: =sum(R15:S15,V15) -> 0 | AD15: 0.51
A16: 44242 | B16: 1737 | C16: 1808 | D16: =choose(weekday(A16),"Phil/Fred", "Jane/Sarah", "Jim/John/Lena","Marsha/Anne","Shawn/Jenny","Jeff", "Rob/Maggie") -> Jane/Sarah | E16: N | G16: 44242 | I16: =iferror(24*( DATEDIF(A16,G16,"D")+TIMEVALUE(H16)-TIMEVALUE(F16)),0) -> 0 | K16: 44 | M16: Cloudy | N16: 0 | O16: 0 | P16: 0 | Q16: 0 | R16: 0 | S16: 0 | T16: 0 | U16: 0 | V16: 0 | W16: 0 | X16: 0 | Y16: 0 | Z16: =sum(N16:Q16) -> 0 | AA16: =sum(R16:V16) -> 0 | AB16: =sum(N16:O16) -> 0 | AC16: =sum(R16:S16,V16) -> 0 | AD16: 0.61
A17: 44243 | B17: 1739 | C17: 1809 | D17: =choose(weekday(A17),"Phil/Fred", "Jane/Sarah", "Jim/John/Lena","Marsha/Anne","Shawn/Jenny","Jeff", "Rob/Maggie") -> Jim/John/Lena | E17: N | G17: 44243 | I17: =iferror(24*( DATEDIF(A17,G17,"D")+TIMEVALUE(H17)-TIMEVALUE(F17)),0) -> 0 | N17: 0 | O17: 0 | P17: 0 | Q17: 0 | R17: 0 | S17: 0 | T17: 0 | U17: 0 | V17: 0 | W17: 0 | X17: 0 | Y17: 0 | Z17: =sum(N17:Q17) -> 0 | AA17: =sum(R17:V17) -> 0 | AB17: =sum(N17:O17) -> 0 | AC17: =sum(R17:S17,V17) -> 0 | AD17: 0.71
A18: 44244 | B18: 1740 | C18: 1810 | D18: =choose(weekday(A18),"Phil/Fred", "Jane/Sarah", "Jim/John/Lena","Marsha/Anne","Shawn/Jenny","Jeff", "Rob/Maggie") -> Marsha/Anne | E18: N | G18: 44244 | I18: =iferror(24*( DATEDIF(A18,G18,"D")+TIMEVALUE(H18)-TIMEVALUE(F18)),0) -> 0 | N18: 0 | O18: 0 | P18: 0 | Q18: 0 | R18: 0 | S18: 0 | T18: 0 | U18: 0 | V18: 0 | W18: 0 | X18: 0 | Y18: 0 | Z18: =sum(N18:Q18) -> 0 | AA18: =sum(R18:V18) -> 0 | AB18: =sum(N18:O18) -> 0 | AC18: =sum(R18:S18,V18) -> 0 | AD18: 0.8
A19: 44245 | B19: 1742 | C19: 1812 | D19: =choose(weekday(A19),"Phil/Fred", "Jane/Sarah", "Jim/John/Lena","Marsha/Anne","Shawn/Jenny","Jeff", "Rob/Maggie") -> Shawn/Jenny | E19: Y | F19: 0.73611111 | G19: 44245 | H19: 0.73958333 | I19: =iferror(24*( DATEDIF(A19,G19,"D")+TIMEVALUE(H19)-TIMEVALUE(F19)),0) -> 0.083333333 | K19: 39 | M19: 1-2 in. snow remaining | N19: 0 | O19: 0 | P19: 0 | Q19: 0 | R19: 0 | S19: 0 | T19: 0 | U19: 0 | V19: 0 | W19: 0 | X19: 0 | Y19: 0 | Z19: =sum(N19:Q19) -> 0 | AA19: =sum(R19:V19) -> 0 | AB19: =sum(N19:O19) -> 0 | AC19: =sum(R19:S19,V19) -> 0 | AD19: 0.88
A20: 44246 | B20: 1743 | C20: 1813 | D20: =choose(weekday(A20),"Phil/Fred", "Jane/Sarah", "Jim/John/Lena","Marsha/Anne","Shawn/Jenny","Jeff", "Rob/Maggie") -> Jeff | E20: Y | F20: 0.77083333 | G20: 44246 | H20: 0.78125 | I20: =iferror(24*( DATEDIF(A20,G20,"D")+TIMEVALUE(H20)-TIMEVALUE(F20)),0) -> 0.25 | J20: 0.25 | K20: 42 | L20: 42 | M20: Paverment wet | N20: 0 | O20: 0 | P20: 0 | Q20: 0 | R20: 0 | S20: 0 | T20: 0 | U20: 0 | V20: 0 | W20: 0 | X20: 0 | Y20: 0 | Z20: =sum(N20:Q20) -> 0 | AA20: =sum(R20:V20) -> 0 | AB20: =sum(N20:O20) -> 0 | AC20: =sum(R20:S20,V20) -> 0 | AD20: 0.95
A21: 44247 | B21: 1744 | C21: 1815 | D21: =choose(weekday(A21),"Phil/Fred", "Jane/Sarah", "Jim/John/Lena","Marsha/Anne","Shawn/Jenny","Jeff", "Rob/Maggie") -> Rob/Maggie | E21: y | F21: 0.23958333 | G21: 44247 | H21: 0.26041667 | I21: =iferror(24*( DATEDIF(A21,G21,"D")+TIMEVALUE(H21)-TIMEVALUE(F21)),0) -> 0.5 | J21: 0.5 | K21: 42 | L21: 41 | M21: drying | N21: 0 | O21: 0 | P21: 0 | Q21: 0 | R21: 0 | S21: 0 | T21: 0 | U21: 0 | V21: 0 | W21: 0 | X21: 0 | Y21: 0 | Z21: =sum(N21:Q21) -> 0 | AA21: =sum(R21:V21) -> 0 | AB21: =sum(N21:O21) -> 0 | AC21: =sum(R21:S21,V21) -> 0 | AD21: 0.99
A22: 44248 | B22: 1746 | C22: 1816 | D22: =choose(weekday(A22),"Phil/Fred", "Jane/Sarah", "Jim/John/Lena","Marsha/Anne","Shawn/Jenny","Jeff", "Rob/Maggie") -> Phil/Fred | E22: Y | F22: 0.72916667 | G22: 44248 | H22: 0.8125 | I22: =iferror(24*( DATEDIF(A22,G22,"D")+TIMEVALUE(H22)-TIMEVALUE(F22)),0) -> 2 | J22: 2 | K22: 49 | L22: 49 | M22: dry pavement | N22: 0 | O22: 0 | P22: 0 | Q22: 0 | R22: 0 | S22: 0 | T22: 0 | U22: 0 | V22: 0 | W22: 0 | X22: 0 | Y22: 0 | Z22: =sum(N22:Q22) -> 0 | AA22: =sum(R22:V22) -> 0 | AB22: =sum(N22:O22) -> 0 | AC22: =sum(R22:S22,V22) -> 0 | AD22: 1
A23: 44249 | B23: 1747 | C23: 1817 | D23: =choose(weekday(A23),"Phil/Fred", "Jane/Sara", "Jim/John/Lena","Marsha/Anne","Shawn/Jenny","Jeff", "Rob/Maggie") -> Jane/Sara | E23: Y | F23: 0.75 | G23: 44249 | H23: 0.8125 | I23: =iferror(24*( DATEDIF(A23,G23,"D")+TIMEVALUE(H23)-TIMEVALUE(F23)),0) -> 1.5 | J23: 12 | K23: 48 | L23: 45 | M23: Paverment wet | N23: 0 | O23: 0 | P23: 1 | Q23: 0 | R23: 3 | S23: 0 | T23: 0 | U23: 0 | V23: 0 | W23: 0 | X23: 0 | Y23: 0 | Z23: =sum(N23:Q23) -> 1 | AA23: =sum(R23:V23) -> 3 | AB23: =sum(N23:O23) -> 0 | AC23: =sum(R23:S23,V23) -> 3 | AD23: 0.98
A24: 44250 | B24: 1749 | C24: 1819 | D24: =choose(weekday(A24),"Phil/Fred", "Jane/Sarah", "Jim/John/Lena","Marsha/Anne","Shawn/Jenny","Jeff", "Rob/Maggie") -> Jim/John/Lena | G24: 44250 | I24: =iferror(24*( DATEDIF(A24,G24,"D")+TIMEVALUE(H24)-TIMEVALUE(F24)),0) -> 0 | N24: 0 | O24: 0 | P24: 0 | Q24: 0 | R24: 0 | S24: 0 | T24: 0 | U24: 0 | V24: 0 | W24: 0 | X24: 0 | Y24: 0 | Z24: =sum(N24:Q24) -> 0 | AA24: =sum(R24:V24) -> 0 | AB24: =sum(N24:O24) -> 0 | AC24: =sum(R24:S24,V24) -> 0 | AD24: 0.93
A25: 44251 | B25: 1750 | C25: 1820 | D25: =choose(weekday(A25),"Phil/Fred", "Jane/Sarah", "Jim/John/Lena","Marsha/Anne","Shawn/Jenny","Jeff", "Rob/Maggie") -> Marsha/Anne | G25: 44251 | I25: =iferror(24*( DATEDIF(A25,G25,"D")+TIMEVALUE(H25)-TIMEVALUE(F25)),0) -> 0 | N25: 0 | O25: 0 | P25: 0 | Q25: 0 | R25: 0 | S25: 0 | T25: 0 | U25: 0 | V25: 0 | W25: 0 | X25: 0 | Y25: 0 | Z25: =sum(N25:Q25) -> 0 | AA25: =sum(R25:V25) -> 0 | AB25: =sum(N25:O25) -> 0 | AC25: =sum(R25:S25,V25) -> 0 | AD25: 0.86
A26: 44252 | B26: 1752 | C26: 1821 | D26: =choose(weekday(A26),"Phil/Fred", "Jane/Sarah", "Jim/John/Lena","Marsha/Anne","Shawn/Jenny","Jeff", "Rob/Maggie") -> Shawn/Jenny | E26: Y | F26: 0.73958333 | G26: 44252 | H26: 0.8125 | I26: =iferror(24*( DATEDIF(A26,G26,"D")+TIMEVALUE(H26)-TIMEVALUE(F26)),0) -> 1.75 | J26: 12.5 | K26: 44 | L26: 43 | M26: Lite rain on & off | N26: 0 | O26: 0 | P26: 0 | Q26: 0 | R26: 0 | S26: 0 | T26: 0 | U26: 0 | V26: 0 | W26: 0 | X26: 0 | Y26: 0 | Z26: =sum(N26:Q26) -> 0 | AA26: =sum(R26:V26) -> 0 | AB26: =sum(N26:O26) -> 0 | AC26: =sum(R26:S26,V26) -> 0 | AD26: 0.77 | AE26: 2 tree frogs down. Wetlands getting noisy.
A27: 44253 | B27: 1753 | C27: 1823 | D27: =choose(weekday(A27),"Phil/Fred", "Jane/Sarah", "Jim/John/Lena","Marsha/Anne","Shawn/Jenny","Jeff", "Rob/Maggie") -> Jeff | E27: Y | F27: 0.72916667 | G27: 44253 | H27: 0.77083333 | I27: =iferror(24*( DATEDIF(A27,G27,"D")+TIMEVALUE(H27)-TIMEVALUE(F27)),0) -> 1 | J27: 1 | K27: 42 | L27: 40 | M27: Rainy | N27: 0 | O27: 0 | P27: 0 | Q27: 0 | R27: 0 | S27: 0 | T27: 0 | U27: 0 | V27: 0 | W27: 0 | X27: 0 | Y27: 0 | Z27: =sum(N27:Q27) -> 0 | AA27: =sum(R27:V27) -> 0 | AB27: =sum(N27:O27) -> 0 | AC27: =sum(R27:S27,V27) -> 0 | AD27: 0.67
A28: 44254 | B28: 1754 | C28: 1824 | D28: =choose(weekday(A28),"Phil/Fred", "Jane/Sarah", "Jim/John/Lena","Marsha/Anne","Shawn/Jenny","Jeff", "Rob/Maggie") -> Rob/Maggie | E28: N | G28: 44254 | I28: =iferror(24*( DATEDIF(A28,G28,"D")+TIMEVALUE(H28)-TIMEVALUE(F28)),0) -> 0 | K28: 44 | M28: dry | N28: 0 | O28: 0 | P28: 0 | Q28: 0 | R28: 0 | S28: 0 | T28: 0 | U28: 0 | V28: 0 | W28: 0 | X28: 0 | Y28: 0 | Z28: =sum(N28:Q28) -> 0 | AA28: =sum(R28:V28) -> 0 | AB28: =sum(N28:O28) -> 0 | AC28: =sum(R28:S28,V28) -> 0 | AD28: 0.56
A29: 44255 | B29: 1756 | C29: 1826 | D29: =choose(weekday(A29),"Phil/Fred", "Jane/Sarah", "Jim/John/Lena","Marsha/Anne","Shawn/Jenny","Jeff", "Rob/Maggie") -> Phil/Fred | E29: N | G29: 44255 | I29: =iferror(24*( DATEDIF(A29,G29,"D")+TIMEVALUE(H29)-TIMEVALUE(F29)),0) -> 0 | M29: dry | N29: 0 | O29: 0 | P29: 0 | Q29: 0 | R29: 0 | S29: 0 | T29: 0 | U29: 0 | V29: 0 | W29: 0 | X29: 0 | Y29: 0 | Z29: =sum(N29:Q29) -> 0 | AA29: =sum(R29:V29) -> 0 | AB29: =sum(N29:O29) -> 0 | AC29: =sum(R29:S29,V29) -> 0 | AD29: 0.45
A30: xx/xx/xxxx | B30: xxxx | C30: xxxx | D30: x | E30: x | F30: x | G30: xx/xx/xxxx | I30: xxxx | J30: xxxx | K30: xxxx | L30: xxxx | M30: xxxx | N30: xxxx | O30: xxxx | P30: xxxx | Q30: xxxx | R30: xxxx | S30: xxxx | T30: xxxx | U30: xxxx | V30: xxxx | W30: xxxx | X30: xxxx | Y30: xxxx | Z30: =sum(N30:Q30) -> 0 | AA30: =sum(R30:V30) -> 0 | AB30: =sum(N30:O30) -> 0 | AC30: =sum(R30:S30,V30) -> 0
A31: xx/xx/xxxx | B31: x | C31: x | D31: x | E31: x | F31: x | G31: xx/xx/xxxx | N31: xxxx | O31: xxxx | P31: xxxx | Q31: xxxx | R31: xxxx | S31: xxxx | T31: xxxx | U31: xxxx | V31: xxxx | W31: xxxx | X31: xxxx | Y31: xxxx | Z31: xxxx | AA31: xxxx | AB31: xxxx | AC31: xxxx
A32: xx/xx/xxxx | B32: x | C32: x | D32: x | E32: x | F32: x | G32: xx/xx/xxxx | N32: xxxx | O32: xxxx | P32: xxxx | Q32: xxxx | R32: xxxx | S32: xxxx | T32: xxxx | U32: xxxx | V32: xxxx | W32: xxxx | X32: xxxx | Y32: xxxx | Z32: xxxx | AA32: xxxx | AB32: xxxx | AC32: xxxx
E33: Monthly Total | I33: =SUM(I3:I32) -> 13.083333 | J33: =SUM(J2:J29) -> 62.2 | N33: =SUM(N2:N30) -> 2 | O33: =SUM(O2:O30) -> 0 | P33: =SUM(P2:P30) -> 2 | Q33: =SUM(Q2:Q30) -> 0 | R33: =SUM(R2:R30) -> 12 | S33: =SUM(S2:S30) -> 0 | T33: =SUM(T2:T30) -> 0 | U33: =SUM(U2:U30) -> 0 | ... AC33: =SUM(AC2:AC30) -> 18
E34: Cumulative Total | I34: ='November 2020'!I$33+'December 2020'!I$33+'January 2021'!I$33+'February 2021'!I$33 -> 87.383333 | J34: ='November 2020'!J$33+'December 2020'!J$33+'January 2021'!J$33+'February 2021'!J$33 -> 377.1 | N34: ='November 2020'!N$33+'December 2020'!N$33+'January 2021'!N$33+'February 2021'!N$33 -> 266 | O34: ='November 2020'!O$33+'December 2020'!O$33+'January 2021'!O$33+'February 2021'!O$33 -> 139 | P34: ='November 2020'!P$33+'December 2020'!P$33+'January 2021'!P$33+'February 2021'!P$33 -> 10 | Q34: ='November 2020'!Q$33+'December 2020'!Q$33+'January 2021'!Q$33+'February 2021'!Q$33 -> 0 | R34: ='November 2020'!R$33+'December 2020'!R$33+'January 2021'!R$33+'February 2021'!R$33 -> 45 | S34: ='November 2020'!S$33+'December 2020'!S$33+'January 2021'!S$33+'February 2021'!S$33 -> 3 | T34: ='November 2020'!T$33+'December 2020'!T$33+'January 2021'!T$33+'February 2021'!T$33 -> 7 | U34: ='November 2020'!U$33+'December 2020'!U$33+'January 2021'!U$33+'February 2021'!U$33 -> 0 | ... AA34: ='November 2020'!AA$33+'December 2020'!AA$33+'January 2021'!AA$33+'February 2021'!AA$33 -> 55 | AB34: ='November 2020'!AB33+'December 2020'!AB33+'January 2021'!AB33+'February 2021'!AB33 -> 407 | AC34: ='November 2020'!AC33+'December 2020'!AC33+'January 2021'!AC33+'February 2021'!AC33 -> 54
E35: Season Total | I35: ='November 2020'!I$33+'December 2020'!I$33+'January 2021'!I$33+'February 2021'!I$33+'March 2021'!I$33+'April 2021'!I$33 -> 112.63333 | J35: ='November 2020'!J33+'December 2020'!J33+'January 2021'!J33+'February 2021'!J33+'March 2021'!J33+'April 2021'!J33 -> 474.1 | N35: ='November 2020'!N33+'December 2020'!N33+'January 2021'!N33+'February 2021'!N33+'March 2021'!N33+'April 2021'!N33 -> 271 | O35: ='November 2020'!O33+'December 2020'!O33+'January 2021'!O33+'February 2021'!O33+'March 2021'!O33+'April 2021'!O33 -> 139 | P35: ='November 2020'!P33+'December 2020'!P33+'January 2021'!P33+'February 2021'!P33+'March 2021'!P33+'April 2021'!P33 -> 11 | Q35: ='November 2020'!Q33+'December 2020'!Q33+'January 2021'!Q33+'February 2021'!Q33+'March 2021'!Q33+'April 2021'!Q33 -> 0 | R35: ='November 2020'!R33+'December 2020'!R33+'January 2021'!R33+'February 2021'!R33+'March 2021'!R33+'April 2021'!R33 -> 147 | S35: ='November 2020'!S33+'December 2020'!S33+'January 2021'!S33+'February 2021'!S33+'March 2021'!S33+'April 2021'!S33 -> 28 | T35: ='November 2020'!T33+'December 2020'!T33+'January 2021'!T33+'February 2021'!T33+'March 2021'!T33+'April 2021'!T33 -> 8 | U35: ='November 2020'!U33+'December 2020'!U33+'January 2021'!U33+'February 2021'!U33+'March 2021'!U33+'April 2021'!U33 -> 0 | ... AC35: ='November 2020'!AC33+'December 2020'!AC33+'January 2021'!AC33+'February 2021'!AC33+'March 2021'!AC33+'April 2021'!AC33 -> 191
E36: 2019-20 Total | N36: 811 | O36: 1180 | P36: 13 | Q36: 2 | R36: 386 | S36: 89 | T36: 35 | U36: 2 | V36: 0 | W36: 9 | X36: 7 | Y36: 28 | Z36: 2006 | AA36: 512 | AB36: 1991 | AC36: 475
E37: 2018-19 Total | N37: 90 | O37: 1134 | P37: 3 | Q37: 4 | R37: 124 | S37: 791 | T37: 6 | U37: 17 | V37: 6 | W37: 4 | X37: 24 | Y37: 7 | Z37: 1231 | AA37: 944 | AB37: 1224 | AC37: 921
E38: 2017-18 Total | Z38: 433 | AA38: 297
E39: 2016-17 Total | Z39: 834 | AA39: 751
E40: 2015-16 Total | Z40: 688 | AA40: 1040
...

Sheet March 2021
A1: Date | B1: Sunset | C1: Civil Twilight | D1: Captain | E1: Monitored (Y/N) | F1: Start time HH:MM | G1: End Date | H1: End time HH:MM | I1: Hours monitored | J1: Team Hrs. | K1: Start temp | L1: End temp | M1: Weather | N1: Females assisted down | O1: Males assisted down | P1: Unassisted Females down | Q1: Unasissted Males down | R1: Females assisted up | S1: Males assisted up | T1: Unassisted females up | U1: Unassisted males up | V1: Juveniles assisted up | W1: Roadkill Females | X1: Roadkill Males | Y1: Roadkill Unk | Z1: Total frogs down | AA1: Total frogs up | AB1: Total Frogs Assisted Down | AC1: Total Frogs Assisted Up | AD1: % moon visible | AE1: Comments
A2: 44256 | B2: 1759 | C2: 1828 | D2: =choose(weekday(A2),"Phil/Fred", "Jane/Sarah", "Jim/John/Lena","Marsha/Anne","Shawn/Jenny","Jeff", "Rob/Maggie") -> Jane/Sarah | E2: N | F2: 0.26041667 | G2: 44256 | I2: =iferror(24*( DATEDIF(A2,G2,"D")+TIMEVALUE(H2)-TIMEVALUE(F2)),0) -> 0 | K2: 49 | M2: Clear and dry | N2: 0 | O2: 0 | P2: 0 | Q2: 0 | R2: 0 | S2: 0 | T2: 0 | U2: 0 | V2: 0 | W2: 0 | X2: 0 | Y2: 0 | Z2: =sum(N2:Q2) -> 0 | AA2: =sum(R2:V2) -> 0 | AB2: =sum(N2:O2) -> 0 | AC2: =sum(R2:S2,V2) -> 0 | AD2: 0.21
A3: 44257 | B3: 1800 | C3: 1830 | D3: =choose(weekday(A3),"Phil/Fred", "Jane/Sarah", "Jim/John/Lena","Marsha/Anne","Shawn/Jenny","Jeff", "Rob/Maggie") -> Jim/John/Lena | E3: N | G3: 44257 | I3: =iferror(24*( DATEDIF(A3,G3,"D")+TIMEVALUE(H3)-TIMEVALUE(F3)),0) -> 0 | N3: 0 | O3: 0 | P3: 0 | Q3: 0 | R3: 0 | S3: 0 | T3: 0 | U3: 0 | V3: 0 | W3: 0 | X3: 0 | Y3: 0 | Z3: =sum(N3:Q3) -> 0 | AA3: =sum(R3:V3) -> 0 | AB3: =sum(N3:O3) -> 0 | AC3: =sum(R3:S3,V3) -> 0 | AD3: 0.13
A4: 44258 | B4: 1801 | C4: 1831 | D4: =choose(weekday(A4),"Phil/Fred", "Jane/Sarah", "Jim/John/Lena","Marsha/Anne","Shawn/Jenny","Jeff", "Rob/Maggie") -> Marsha/Anne | E4: N | G4: 44258 | I4: =iferror(24*( DATEDIF(A4,G4,"D")+TIMEVALUE(H4)-TIMEVALUE(F4)),0) -> 0 | N4: 0 | O4: 0 | P4: 0 | Q4: 0 | R4: 0 | S4: 0 | T4: 0 | U4: 0 | V4: 0 | W4: 0 | X4: 0 | Y4: 0 | Z4: =sum(N4:Q4) -> 0 | AA4: =sum(R4:V4) -> 0 | AB4: =sum(N4:O4) -> 0 | AC4: =sum(R4:S4,V4) -> 0 | AD4: 0.07
A5: 44259 | B5: 1803 | C5: 1832 | D5: =choose(weekday(A5),"Phil/Fred", "Jane/Sarah", "Jim/John/Lena","Marsha/Anne","Shawn/Jenny","Jeff", "Rob/Maggie") -> Shawn/Jenny | E5: Y | F5: 0.73958333 | G5: 44259 | H5: 0.88541667 | I5: =iferror(24*( DATEDIF(A5,G5,"D")+TIMEVALUE(H5)-TIMEVALUE(F5)),0) -> 3.5 | J5: 19.5 | K5: 50 | L5: 48 | M5: Lite rain >dry; wt pvmnt | N5: 5 | O5: 0 | P5: 1 | Q5: 0 | R5: 73 | S5: 23 | T5: 1 | U5: 0 | V5: 0 | W5: 0 | X5: 0 | Y5: 0 | Z5: =sum(N5:Q5) -> 6 | AA5: =sum(R5:V5) -> 97 | AB5: =sum(N5:O5) -> 5 | AC5: =sum(R5:S5,V5) -> 96 | AD5: 0.03 | AE5: 5 chorus frogs down-Much of nite was dry with wet pavement
A6: 44260 | B6: 1804 | C6: 1834 | D6: =choose(weekday(A6),"Phil/Fred", "Jane/Sarah", "Jim/John/Lena","Marsha/Anne","Shawn/Jenny","Jeff", "Rob/Maggie") -> Jeff | E6: Y | F6: 0.76041667 | G6: 44260 | H6: 0.875 | I6: =iferror(24*( DATEDIF(A6,G6,"D")+TIMEVALUE(H6)-TIMEVALUE(F6)),0) -> 2.75 | J6: 14.5 | K6: 44 | L6: 43 | M6: Wet pvmnt, sprinkles | N6: 0 | O6: 0 | P6: 0 | Q6: 0 | R6: 0 | S6: 0 | T6: 0 | U6: 0 | V6: 0 | W6: 0 | X6: 0 | Y6: 0 | Z6: =sum(N6:Q6) -> 0 | AA6: =sum(R6:V6) -> 0 | AB6: =sum(N6:O6) -> 0 | AC6: =sum(R6:S6,V6) -> 0 | AD6: 0.01
A7: 44261 | B7: 1805 | C7: 1835 | D7: =choose(weekday(A7),"Phil/Fred", "Jane/Sarah", "Jim/John/Lena","Marsha/Anne","Shawn/Jenny","Jeff", "Rob/Maggie") -> Rob/Maggie | E7: y | F7: 0.26041667 | G7: 44261 | H7: 0.28125 | I7: =iferror(24*( DATEDIF(A7,G7,"D")+TIMEVALUE(H7)-TIMEVALUE(F7)),0) -> 0.5 | J7: 0.5 | K7: 44 | L7: 42 | M7: dry pavement | N7: 0 | O7: 0 | P7: 0 | Q7: 0 | R7: 0 | S7: 0 | T7: 0 | U7: 0 | V7: 0 | W7: 0 | X7: 0 | Y7: 0 | Z7: =sum(N7:Q7) -> 0 | AA7: =sum(R7:V7) -> 0 | AB7: =sum(N7:O7) -> 0 | AC7: =sum(R7:S7,V7) -> 0 | AD7: 0
A8: 44262 | B8: 1907 | C8: 1936 | D8: =choose(weekday(A8),"Phil/Fred", "Jane/Sarah", "Jim/John/Lena","Marsha/Anne","Shawn/Jenny","Jeff", "Rob/Maggie") -> Phil/Fred | E8: Y | F8: 0.76041667 | G8: 44262 | H8: 0.79166667 | I8: =iferror(24*( DATEDIF(A8,G8,"D")+TIMEVALUE(H8)-TIMEVALUE(F8)),0) -> 0.75 | J8: 0.75 | K8: 47 | L8: 44 | M8: dry pavement | N8: 0 | O8: 0 | P8: 0 | Q8: 0 | R8: 0 | S8: 0 | T8: 0 | U8: 0 | V8: 0 | W8: 0 | X8: 0 | Y8: 0 | Z8: =sum(N8:Q8) -> 0 | AA8: =sum(R8:V8) -> 0 | AB8: =sum(N8:O8) -> 0 | AC8: =sum(R8:S8,V8) -> 0 | AD8: 0.01
A9: 44263 | B9: 1908 | C9: 1938 | D9: =choose(weekday(A9),"Phil/Fred", "Jane/Sarah", "Jim/John/Lena","Marsha/Anne","Shawn/Jenny","Jeff", "Rob/Maggie") -> Jane/Sarah | E9: N | F9: 0.77083333 | G9: 44263 | I9: =iferror(24*( DATEDIF(A9,G9,"D")+TIMEVALUE(H9)-TIMEVALUE(F9)),0) -> 0 | K9: 46 | M9: Dry, no rain on radar | N9: 0 | O9: 0 | P9: 0 | Q9: 0 | R9: 0 | S9: 0 | T9: 0 | U9: 0 | V9: 0 | W9: 0 | X9: 0 | Y9: 0 | Z9: =sum(N9:Q9) -> 0 | AA9: =sum(R9:V9) -> 0 | AB9: =sum(N9:O9) -> 0 | AC9: =sum(R9:S9,V9) -> 0 | AD9: 0.05
A10: 44264 | B10: 1909 | C10: 1939 | D10: =choose(weekday(A10),"Phil/Fred", "Jane/Sarah", "Jim/John/Lena","Marsha/Anne","Shawn/Jenny","Jeff", "Rob/Maggie") -> Jim/John/Lena | G10: 44264 | I10: =iferror(24*( DATEDIF(A10,G10,"D")+TIMEVALUE(H10)-TIMEVALUE(F10)),0) -> 0 | N10: 0 | O10: 0 | P10: 0 | Q10: 0 | R10: 0 | S10: 0 | T10: 0 | U10: 0 | V10: 0 | W10: 0 | X10: 0 | Y10: 0 | Z10: =sum(N10:Q10) -> 0 | AA10: =sum(R10:V10) -> 0 | AB10: =sum(N10:O10) -> 0 | AC10: =sum(R10:S10,V10) -> 0 | AD10: 0.09
A11: 44265 | B11: 1911 | C11: 1940 | D11: =choose(weekday(A11),"Phil/Fred", "Jane/Sarah", "Jim/John/Lena","Marsha/Anne","Shawn/Jenny","Jeff", "Rob/Maggie") -> Marsha/Anne | E11: Y | F11: 18.1 | G11: 44265 | H11: 0.79166667 | I11: =iferror(24*( DATEDIF(A11,G11,"D")+TIMEVALUE(H11)-TIMEVALUE(F11)),0) -> 0 | J11: 1 | K11: 48 | L11: 45 | N11: 0 | O11: 0 | P11: 0 | Q11: 0 | R11: 0 | S11: 0 | T11: 0 | U11: 0 | V11: 0 | W11: 0 | X11: 0 | Y11: 0 | Z11: =sum(N11:Q11) -> 0 | AA11: =sum(R11:V11) -> 0 | AB11: =sum(N11:O11) -> 0 | AC11: =sum(R11:S11,V11) -> 0 | AD11: 0.16
A12: 44266 | B12: 1912 | C12: 1942 | D12: =choose(weekday(A12),"Phil/Fred", "Jane/Sarah", "Jim/John/Lena","Marsha/Anne","Shawn/Jenny","Jeff", "Rob/Maggie") -> Shawn/Jenny | E12: N | G12: 44266 | H12: 0.79166667 | I12: =iferror(24*( DATEDIF(A12,G12,"D")+TIMEVALUE(H12)-TIMEVALUE(F12)),0) -> 0 | K12: 46 | M12: Dry all day/night | N12: 0 | O12: 0 | P12: 0 | Q12: 0 | R12: 0 | S12: 0 | T12: 0 | U12: 0 | V12: 0 | W12: 0 | X12: 0 | Y12: 0 | Z12: =sum(N12:Q12) -> 0 | AA12: =sum(R12:V12) -> 0 | AB12: =sum(N12:O12) -> 0 | AC12: =sum(R12:S12,V12) -> 0 | AD12: 0.23
A13: 44267 | B13: 1913 | C13: 1943 | D13: =choose(weekday(A13),"Phil/Fred", "Jane/Sarah", "Jim/John/Lena","Marsha/Anne","Shawn/Jenny","Jeff", "Rob/Maggie") -> Jeff | G13: 44267 | I13: =iferror(24*( DATEDIF(A13,G13,"D")+TIMEVALUE(H13)-TIMEVALUE(F13)),0) -> 0 | N13: 0 | O13: 0 | P13: 0 | Q13: 0 | R13: 0 | S13: 0 | T13: 0 | U13: 0 | V13: 0 | W13: 0 | X13: 0 | Y13: 0 | Z13: =sum(N13:Q13) -> 0 | AA13: =sum(R13:V13) -> 0 | AB13: =sum(N13:O13) -> 0 | AC13: =sum(R13:S13,V13) -> 0 | AD13: 0.31
A14: 44268 | B14: 1914 | C14: 1944 | D14: =choose(weekday(A14),"Phil/Fred", "Jane/Sarah", "Jim/John/Lena","Marsha/Anne","Shawn/Jenny","Jeff", "Rob/Maggie") -> Rob/Maggie | E14: N | G14: 44268 | I14: =iferror(24*( DATEDIF(A14,G14,"D")+TIMEVALUE(H14)-TIMEVALUE(F14)),0) -> 0 | K14: 45 | M14: fair, dry | N14: 0 | O14: 0 | P14: 0 | Q14: 0 | R14: 0 | S14: 0 | T14: 0 | U14: 0 | V14: 0 | W14: 0 | X14: 0 | Y14: 0 | Z14: =sum(N14:Q14) -> 0 | AA14: =sum(R14:V14) -> 0 | AB14: =sum(N14:O14) -> 0 | AC14: =sum(R14:S14,V14) -> 0 | AD14: 0.41
A15: 44269 | B15: 1916 | C15: 1946 | D15: =choose(weekday(A15),"Phil/Fred", "Jane/Sarah", "Jim/John/Lena","Marsha/Anne","Shawn/Jenny","Jeff", "Rob/Maggie") -> Phil/Fred | E15: Y | F15: 0.8125 | G15: 44269 | H15: 0.88541667 | I15: =iferror(24*( DATEDIF(A15,G15,"D")+TIMEVALUE(H15)-TIMEVALUE(F15)),0) -> 1.75 | J15: 5.5 | K15: 43.5 | L15: 41.7 | M15: light rain | N15: 0 | O15: 0 | P15: 0 | Q15: 0 | R15: 4 | S15: 0 | T15: 0 | U15: 0 | V15: 0 | W15: 0 | X15: 0 | Y15: 0 | Z15: =sum(N15:Q15) -> 0 | AA15: =sum(R15:V15) -> 4 | AB15: =sum(N15:O15) -> 0 | AC15: =sum(R15:S15,V15) -> 4 | AD15: 0.51 | AE15: 1 female chorus frog assisted down.
A16: 44270 | B16: 1917 | C16: 1947 | D16: =choose(weekday(A16),"Phil/Fred", "Jane/Sarah", "Jim/John/Lena","Marsha/Anne","Shawn/Jenny","Jeff", "Rob/Maggie") -> Jane/Sarah | E16: N | F16: 0.77083333 | G16: 44270 | I16: =iferror(24*( DATEDIF(A16,G16,"D")+TIMEVALUE(H16)-TIMEVALUE(F16)),0) -> 0 | K16: 44 | M16: dry | N16: 0 | O16: 0 | P16: 0 | Q16: 0 | R16: 0 | S16: 0 | T16: 0 | U16: 0 | V16: 0 | W16: 0 | X16: 0 | Y16: 0 | Z16: =sum(N16:Q16) -> 0 | AA16: =sum(R16:V16) -> 0 | AB16: =sum(N16:O16) -> 0 | AC16: =sum(R16:S16,V16) -> 0 | AD16: 0.61
A17: 44271 | B17: 1919 | C17: 1948 | D17: =choose(weekday(A17),"Phil/Fred", "Jane/Sarah", "Jim/John/Lena","Marsha/Anne","Shawn/Jenny","Jeff", "Rob/Maggie") -> Jim/John/Lena | E17: y | F17: 0.77083333 | G17: 44271 | H17: 0.8125 | I17: =iferror(24*( DATEDIF(A17,G17,"D")+TIMEVALUE(H17)-TIMEVALUE(F17)),0) -> 1 | K17: 45 | M17: dry | N17: 0 | O17: 0 | P17: 0 | Q17: 0 | R17: 0 | S17: 0 | T17: 0 | U17: 0 | V17: 0 | W17: 0 | X17: 0 | Y17: 0 | Z17: =sum(N17:Q17) -> 0 | AA17: =sum(R17:V17) -> 0 | AB17: =sum(N17:O17) -> 0 | AC17: =sum(R17:S17,V17) -> 0 | AD17: 0.71
A18: 44272 | B18: 1920 | C18: 1950 | D18: =choose(weekday(A18),"Phil/Fred", "Jane/Sarah", "Jim/John/Lena","Marsha/Anne","Shawn/Jenny","Jeff", "Rob/Maggie") -> Marsha/Anne | E18: N | G18: 44272 | I18: =iferror(24*( DATEDIF(A18,G18,"D")+TIMEVALUE(H18)-TIMEVALUE(F18)),0) -> 0 | N18: 0 | O18: 0 | P18: 0 | Q18: 0 | R18: 0 | S18: 0 | T18: 0 | U18: 0 | V18: 0 | W18: 0 | X18: 0 | Y18: 0 | Z18: =sum(N18:Q18) -> 0 | AA18: =sum(R18:V18) -> 0 | AB18: =sum(N18:O18) -> 0 | AC18: =sum(R18:S18,V18) -> 0 | AD18: 0.8
A19: 44273 | B19: 1921 | C19: 1951 | D19: =choose(weekday(A19),"Phil/Fred", "Jane/Sarah", "Jim/John/Lena","Marsha/Anne","Shawn/Jenny","Jeff", "Rob/Maggie") -> Shawn/Jenny | E19: Y | F19: 0.79166667 | G19: 44273 | H19: 0.91666667 | I19: =iferror(24*( DATEDIF(A19,G19,"D")+TIMEVALUE(H19)-TIMEVALUE(F19)),0) -> 3 | J19: 18.5 | K19: 47 | L19: 44 | M19: Dry; wet pavement | N19: 0 | O19: 0 | P19: 0 | Q19: 0 | R19: 9 | S19: 2 | T19: 0 | U19: 0 | V19: 0 | W19: 0 | X19: 0 | Y19: 0 | Z19: =sum(N19:Q19) -> 0 | AA19: =sum(R19:V19) -> 11 | AB19: =sum(N19:O19) -> 0 | AC19: =sum(R19:S19,V19) -> 11 | AD19: 0.88 | AE19: 8 chorus frogs down; About half of R-L frogs came out beyond the silt fence
A20: 44274 | B20: 1923 | C20: 1952 | D20: =choose(weekday(A20),"Phil/Fred", "Jane/Sarah", "Jim/John/Lena","Marsha/Anne","Shawn/Jenny","Jeff", "Rob/Maggie") -> Jeff | E20: Y | F20: 0.85416667 | G20: 44274 | H20: 0.86458333 | I20: =iferror(24*( DATEDIF(A20,G20,"D")+TIMEVALUE(H20)-TIMEVALUE(F20)),0) -> 0.25 | J20: 0.25 | K20: 46 | L20: 46 | M20: dry, overcast | N20: 0 | O20: 0 | P20: 0 | Q20: 0 | R20: 0 | S20: 0 | T20: 0 | U20: 0 | V20: 0 | W20: 0 | X20: 0 | Y20: 0 | Z20: =sum(N20:Q20) -> 0 | AA20: =sum(R20:V20) -> 0 | AB20: =sum(N20:O20) -> 0 | AC20: =sum(R20:S20,V20) -> 0 | AD20: 0.95
A21: 44275 | B21: 1924 | C21: 1954 | D21: =choose(weekday(A21),"Phil/Fred", "Jane/Sarah", "Jim/John/Lena","Marsha/Anne","Shawn/Jenny","Jeff", "Rob/Maggie") -> Rob/Maggie | E21: y | F21: 0.28125 | G21: 44275 | H21: 0.35416667 | I21: =iferror(24*( DATEDIF(A21,G21,"D")+TIMEVALUE(H21)-TIMEVALUE(F21)),0) -> 1.75 | J21: 11.5 | K21: 47 | L21: 43 | M21: dryish, sprinkles | N21: 0 | O21: 0 | P21: 0 | Q21: 0 | R21: 2 | S21: 0 | T21: 0 | U21: 0 | V21: 0 | W21: 0 | X21: 0 | Y21: 0 | Z21: =sum(N21:Q21) -> 0 | AA21: =sum(R21:V21) -> 2 | AB21: =sum(N21:O21) -> 0 | AC21: =sum(R21:S21,V21) -> 2 | AD21: 0.99
A22: 44276 | B22: 1925 | C22: 1955 | D22: =choose(weekday(A22),"Phil/Fred", "Jane/Sarah", "Jim/John/Lena","Marsha/Anne","Shawn/Jenny","Jeff", "Rob/Maggie") -> Phil/Fred | E22: Y | F22: 0.8125 | G22: 44276 | H22: 0.95833333 | I22: =iferror(24*( DATEDIF(A22,G22,"D")+TIMEVALUE(H22)-TIMEVALUE(F22)),0) -> 3.5 | J22: 17.5 | K22: 45 | L22: 43 | M22: light rain | N22: 0 | O22: 0 | P22: 0 | Q22: 0 | R22: 12 | S22: 0 | T22: 0 | U22: 0 | V22: 10 | W22: 0 | X22: 0 | Y22: 0 | Z22: =sum(N22:Q22) -> 0 | AA22: =sum(R22:V22) -> 22 | AB22: =sum(N22:O22) -> 0 | AC22: =sum(R22:S22,V22) -> 22 | AD22: 1 | AE22: 1 salamander assisted up
A23: 44277 | B23: 1927 | C23: 1956 | D23: =choose(weekday(A23),"Phil/Fred", "Jane/Sarah", "Jim/John/Lena","Marsha/Anne","Shawn/Jenny","Jeff", "Rob/Maggie") -> Jane/Sarah | E23: N | F23: 0.83333333 | G23: 44277 | I23: =iferror(24*( DATEDIF(A23,G23,"D")+TIMEVALUE(H23)-TIMEVALUE(F23)),0) -> 0 | K23: 45 | M23: Dry and clear | N23: 0 | O23: 0 | P23: 0 | Q23: 0 | R23: 0 | S23: 0 | T23: 0 | U23: 0 | V23: 0 | W23: 0 | X23: 0 | Y23: 0 | Z23: =sum(N23:Q23) -> 0 | AA23: =sum(R23:V23) -> 0 | AB23: =sum(N23:O23) -> 0 | AC23: =sum(R23:S23,V23) -> 0 | AD23: 0.98
A24: 44278 | B24: 1928 | C24: 1958 | D24: =choose(weekday(A24),"Phil/Fred", "Jane/Sarah", "Jim/John/Lena","Marsha/Anne","Shawn/Jenny","Jeff", "Rob/Maggie") -> Jim/John/Lena | E24: y | F24: 0.8125 | G24: 44278 | H24: 0.85416667 | I24: =iferror(24*( DATEDIF(A24,G24,"D")+TIMEVALUE(H24)-TIMEVALUE(F24)),0) -> 1 | J24: 1 | K24: 45 | M24: dry | N24: 0 | O24: 0 | P24: 0 | Q24: 0 | R24: 0 | S24: 0 | T24: 0 | U24: 0 | V24: 0 | W24: 0 | X24: 0 | Y24: 0 | Z24: =sum(N24:Q24) -> 0 | AA24: =sum(R24:V24) -> 0 | AB24: =sum(N24:O24) -> 0 | AC24: =sum(R24:S24,V24) -> 0 | AD24: 0.93
A25: 44279 | B25: 1929 | C25: 1959 | D25: =choose(weekday(A25),"Phil/Fred", "Jane/Sarah", "Jim/John/Lena","Marsha/Anne","Shawn/Jenny","Jeff", "Rob/Maggie") -> Marsha/Anne | E25: Y | F25: 0.79166667 | G25: 44279 | H25: 0.86805556 | I25: =iferror(24*( DATEDIF(A25,G25,"D")+TIMEVALUE(H25)-TIMEVALUE(F25)),0) -> 1.8333333 | K25: 46 | L25: 43.7 | M25: damp pavement | N25: 0 | O25: 0 | P25: 0 | Q25: 0 | R25: 0 | S25: 0 | T25: 0 | U25: 0 | V25: 0 | W25: 0 | X25: 0 | Y25: 0 | Z25: =sum(N25:Q25) -> 0 | AA25: =sum(R25:V25) -> 0 | AB25: =sum(N25:O25) -> 0 | AC25: =sum(R25:S25,V25) -> 0 | AD25: 0.86
A26: 44280 | B26: 1931 | C26: 2000 | D26: =choose(weekday(A26),"Phil/Fred", "Jane/Sarah", "Jim/John/Lena","Marsha/Anne","Shawn/Jenny","Jeff", "Rob/Maggie") -> Shawn/Jenny | E26: Y | F26: 0.82291667 | G26: 44280 | H26: 0.86458333 | I26: =iferror(24*( DATEDIF(A26,G26,"D")+TIMEVALUE(H26)-TIMEVALUE(F26)),0) -> 1 | J26: 1 | K26: 48 | L26: 46 | M26: Dry; mostly dry pavemt | N26: 0 | O26: 0 | P26: 0 | Q26: 0 | R26: 1 | S26: 0 | T26: 0 | U26: 0 | V26: 0 | W26: 0 | X26: 0 | Y26: 0 | Z26: =sum(N26:Q26) -> 0 | AA26: =sum(R26:V26) -> 1 | AB26: =sum(N26:O26) -> 0 | AC26: =sum(R26:S26,V26) -> 1 | AD26: 0.77 | AE26: One fairly dry female RL crossing Marina Way.
A27: 44281 | B27: 1932 | C27: 2002 | D27: =choose(weekday(A27),"Phil/Fred", "Jane/Sarah", "Jim/John/Lena","Marsha/Anne","Shawn/Jenny","Jeff", "Rob/Maggie") -> Jeff | E27: N | G27: 44281 | I27: =iferror(24*( DATEDIF(A27,G27,"D")+TIMEVALUE(H27)-TIMEVALUE(F27)),0) -> 0 | M27: Broken clouds, dry all day | N27: 0 | O27: 0 | P27: 0 | Q27: 0 | R27: 0 | S27: 0 | T27: 0 | U27: 0 | V27: 0 | W27: 0 | X27: 0 | Y27: 0 | Z27: =sum(N27:Q27) -> 0 | AA27: =sum(R27:V27) -> 0 | AB27: =sum(N27:O27) -> 0 | AC27: =sum(R27:S27,V27) -> 0 | AD27: 0.67
A28: 44282 | B28: 1933 | C28: 2003 | D28: =choose(weekday(A28),"Phil/Fred", "Jane/Sarah", "Jim/John/Lena","Marsha/Anne","Shawn/Jenny","Jeff", "Rob/Maggie") -> Rob/Maggie | E28: N | G28: 44282 | I28: =iferror(24*( DATEDIF(A28,G28,"D")+TIMEVALUE(H28)-TIMEVALUE(F28)),0) -> 0 | K28: 46 | M28: clear,fair | N28: 0 | O28: 0 | P28: 0 | Q28: 0 | R28: 0 | S28: 0 | T28: 0 | U28: 0 | V28: 0 | W28: 0 | X28: 0 | Y28: 0 | Z28: =sum(N28:Q28) -> 0 | AA28: =sum(R28:V28) -> 0 | AB28: =sum(N28:O28) -> 0 | AC28: =sum(R28:S28,V28) -> 0 | AD28: 0.56
A29: 44283 | B29: 1934 | C29: 2004 | D29: =choose(weekday(A29),"Phil/Fred", "Jane/Sarah", "Jim/John/Lena","Marsha/Anne","Shawn/Jenny","Jeff", "Rob/Maggie") -> Phil/Fred | E29: Y | F29: 0.83333333 | G29: 44283 | H29: 0.85416667 | I29: =iferror(24*( DATEDIF(A29,G29,"D")+TIMEVALUE(H29)-TIMEVALUE(F29)),0) -> 0.5 | J29: 0.5 | K29: 41.1 | L29: 39.2 | M29: wet pavement- drying | N29: 0 | O29: 0 | P29: 0 | Q29: 0 | R29: 0 | S29: 0 | T29: 0 | U29: 0 | V29: 0 | W29: 0 | X29: 0 | Y29: 0 | Z29: =sum(N29:Q29) -> 0 | AA29: =sum(R29:V29) -> 0 | AB29: =sum(N29:O29) -> 0 | AC29: =sum(R29:S29,V29) -> 0 | AD29: 0.45
A30: 44284 | B30: 1936 | C30: 2006 | D30: =choose(weekday(A30),"Phil/Fred", "Jane/Sarah", "Jim/John/Lena","Marsha/Anne","Shawn/Jenny","Jeff", "Rob/Maggie") -> Jane/Sarah | E30: N | F30: 0.83333333 | G30: 44284 | I30: =iferror(24*( DATEDIF(A30,G30,"D")+TIMEVALUE(H30)-TIMEVALUE(F30)),0) -> 0 | K30: 44 | M30: Clear/dry | N30: 0 | O30: 0 | P30: 0 | Q30: 0 | R30: 0 | S30: 0 | T30: 0 | U30: 0 | V30: 0 | W30: 0 | X30: 0 | Y30: 0 | Z30: =sum(N30:Q30) -> 0 | AA30: =sum(R30:V30) -> 0 | AB30: =sum(N30:O30) -> 0 | AC30: =sum(R30:S30,V30) -> 0 | AD30: 0.35
A31: 44285 | B31: 1937 | C31: 2007 | D31: =choose(weekday(A31),"Phil/Fred", "Jane/Sarah", "Jim/John/Lena","Marsha/Anne","Shawn/Jenny","Jeff", "Rob/Maggie") -> Jim/John/Lena | G31: 44285 | I31: =iferror(24*( DATEDIF(A31,G31,"D")+TIMEVALUE(H31)-TIMEVALUE(F31)),0) -> 0 | N31: 0 | O31: 0 | P31: 0 | Q31: 0 | R31: 0 | S31: 0 | T31: 0 | U31: 0 | V31: 0 | W31: 0 | X31: 0 | Y31: 0 | Z31: =sum(N31:Q31) -> 0 | AA31: =sum(R31:V31) -> 0 | AB31: =sum(N31:O31) -> 0 | AC31: =sum(R31:S31,V31) -> 0 | AD31: 0.26
A32: 44286 | B32: 1938 | C32: 2008 | D32: =choose(weekday(A32),"Phil/Fred", "Jane/Sarah", "Jim/John/Lena","Marsha/Anne","Shawn/Jenny","Jeff", "Rob/Maggie") -> Marsha/Anne | G32: 44286 | I32: =iferror(24*( DATEDIF(A32,G32,"D")+TIMEVALUE(H32)-TIMEVALUE(F32)),0) -> 0 | N32: 0 | O32: 0 | P32: 0 | Q32: 0 | R32: 0 | S32: 0 | T32: 0 | U32: 0 | V32: 0 | W32: 0 | X32: 0 | Y32: 0 | Z32: =sum(N32:Q32) -> 0 | AA32: =sum(R32:V32) -> 0 | AB32: =sum(N32:O32) -> 0 | AC32: =sum(R32:S32,V32) -> 0 | AD32: 0.18
E33: Monthly total | I33: =SUM(I3:I32) -> 23.083333 | J33: =SUM(J2:J32) -> 92 | N33: =sum(N2:N32) -> 5 | O33: =sum(O2:O32) -> 0 | P33: =sum(P2:P32) -> 1 | Q33: =sum(Q2:Q32) -> 0 | R33: =sum(R2:R32) -> 101 | S33: =sum(S2:S32) -> 25 | T33: =sum(T2:T32) -> 1 | U33: =sum(U2:U32) -> 0 | ... Y33: =sum(Y2:Y32) -> 0 | Z33: =SUM(Z2:Z32) -> 6 | AA33: =SUM(AA2:AA32) -> 137 | AB33: =sum(AB2:AB32) -> 5 | AC33: =sum(AC2:AC32) -> 136
E34: Cumulative Total | I34: ='November 2020'!I$33+'December 2020'!I$33+'January 2021'!I$33+'February 2021'!I$33+'March 2021'!I$33 -> 110.46667 | J34: ='November 2020'!J$33+'December 2020'!J$33+'January 2021'!J$33+'February 2021'!J$33+'March 2021'!J$33 -> 469.1 | N34: ='November 2020'!N$33+'December 2020'!N$33+'January 2021'!N$33+'February 2021'!N$33+'March 2021'!N$33 -> 271 | O34: ='November 2020'!O$33+'December 2020'!O$33+'January 2021'!O$33+'February 2021'!O$33+'March 2021'!O$33 -> 139 | P34: ='November 2020'!P$33+'December 2020'!P$33+'January 2021'!P$33+'February 2021'!P$33+'March 2021'!P$33 -> 11 | Q34: ='November 2020'!Q$33+'December 2020'!Q$33+'January 2021'!Q$33+'February 2021'!Q$33+'March 2021'!Q$33 -> 0 | R34: ='November 2020'!R$33+'December 2020'!R$33+'January 2021'!R$33+'February 2021'!R$33+'March 2021'!R$33 -> 146 | S34: ='November 2020'!S$33+'December 2020'!S$33+'January 2021'!S$33+'February 2021'!S$33+'March 2021'!S$33 -> 28 | T34: ='November 2020'!T$33+'December 2020'!T$33+'January 2021'!T$33+'February 2021'!T$33+'March 2021'!T$33 -> 8 | U34: ='November 2020'!U$33+'December 2020'!U$33+'January 2021'!U$33+'February 2021'!U$33+'March 2021'!U$33 -> 0 | ... AA34: ='November 2020'!AA$33+'December 2020'!AA$33+'January 2021'!AA$33+'February 2021'!AA$33+'March 2021'!AA$33 -> 192 | AB34: ='November 2020'!AB33+'December 2020'!AB33+'January 2021'!AB33+'February 2021'!AB33+'March 2021'!AB33 -> 412 | AC34: ='November 2020'!AC33+'December 2020'!AC33+'January 2021'!AC33+'February 2021'!AC33+'March 2021'!AC33 -> 190
E35: Season Total | I35: ='November 2020'!I$33+'December 2020'!I$33+'January 2021'!I$33+'February 2021'!I$33+'March 2021'!I$33+'April 2021'!I$33 -> 112.63333 | J35: ='November 2020'!J33+'December 2020'!J33+'January 2021'!J33+'February 2021'!J33+'March 2021'!J33+'April 2021'!J33 -> 474.1 | N35: ='November 2020'!N33+'December 2020'!N33+'January 2021'!N33+'February 2021'!N33+'March 2021'!N33+'April 2021'!N33 -> 271 | O35: ='November 2020'!O33+'December 2020'!O33+'January 2021'!O33+'February 2021'!O33+'March 2021'!O33+'April 2021'!O33 -> 139 | P35: ='November 2020'!P33+'December 2020'!P33+'January 2021'!P33+'February 2021'!P33+'March 2021'!P33+'April 2021'!P33 -> 11 | Q35: ='November 2020'!Q33+'December 2020'!Q33+'January 2021'!Q33+'February 2021'!Q33+'March 2021'!Q33+'April 2021'!Q33 -> 0 | R35: ='November 2020'!R33+'December 2020'!R33+'January 2021'!R33+'February 2021'!R33+'March 2021'!R33+'April 2021'!R33 -> 147 | S35: ='November 2020'!S33+'December 2020'!S33+'January 2021'!S33+'February 2021'!S33+'March 2021'!S33+'April 2021'!S33 -> 28 | T35: ='November 2020'!T33+'December 2020'!T33+'January 2021'!T33+'February 2021'!T33+'March 2021'!T33+'April 2021'!T33 -> 8 | U35: ='November 2020'!U33+'December 2020'!U33+'January 2021'!U33+'February 2021'!U33+'March 2021'!U33+'April 2021'!U33 -> 0 | ... AC35: ='November 2020'!AC33+'December 2020'!AC33+'January 2021'!AC33+'February 2021'!AC33+'March 2021'!AC33+'April 2021'!AC33 -> 191
E36: 2019-20 Total | N36: 811 | O36: 1180 | P36: 13 | Q36: 2 | R36: 386 | S36: 89 | T36: 35 | U36: 2 | V36: 0 | W36: 9 | X36: 7 | Y36: 28 | Z36: 2006 | AA36: 512 | AB36: 1991 | AC36: 475
E37: 2018-19 Total | N37: 90 | O37: 1134 | P37: 3 | Q37: 4 | R37: 124 | S37: 791 | T37: 6 | U37: 17 | V37: 6 | W37: 4 | X37: 24 | Y37: 7 | Z37: 1231 | AA37: 944 | AB37: 1224 | AC37: 921
E38: 2017-18 Total | Z38: 433 | AA38: 297
E39: 2016-17 Total | Z39: 834 | AA39: 751
E40: 2015-16 Total | Z40: 688 | AA40: 1040
...

Sheet Sheet25

Sheet April 2021
A1: Date | B1: Sunset | C1: Civil Twilight | D1: Captain | E1: Monitored (Y/N) | F1: Start time HH:MM | G1: End Date | H1: End time HH:MM | I1: Hours monitored | J1: Team Hrs. | K1: Start temp | L1: End temp | M1: Weather | N1: Females assisted down | O1: Males assisted down | P1: Unassisted Females down | Q1: Unasissted Males down | R1: Females assisted up | S1: Males assisted up | T1: Unassisted females up | U1: Unassisted males up | V1: Juveniles assisted up | W1: Roadkill Females | X1: Roadkill Males | Y1: Roadkill Unk | Z1: Total frogs down | AA1: Total frogs up | AB1: Total Frogs Assisted Down | AC1: Total Frogs Assisted Up | AD1: % moon visible | AE1: Comments
A2: 44287 | B2: 1940 | C2: 2010 | D2: =choose(weekday(A2),"Phil/Fred", "Jane/Sarah", "Jim/John/Lena","Marsha/Anne","Shawn/Jenny","Jeff", "Rob/Maggie") -> Shawn/Jenny | E2: N | G2: 44287 | I2: =iferror(24*( DATEDIF(A2,G2,"D")+TIMEVALUE(H2)-TIMEVALUE(F2)),0) -> 0 | M2: Dry all day/all night | N2: 0 | O2: 0 | P2: 0 | Q2: 0 | R2: 0 | S2: 0 | T2: 0 | U2: 0 | V2: 0 | W2: 0 | X2: 0 | Y2: 0 | Z2: =sum(N2:Q2) -> 0 | AA2: =sum(R2:V2) -> 0 | AB2: =sum(N2:O2) -> 0 | AC2: =sum(R2:S2,V2) -> 0 | AD2: 0.15
A3: 44288 | B3: 1941 | C3: 2011 | D3: =choose(weekday(A3),"Phil/Fred", "Jane/Sarah", "Jim/John/Lena","Marsha/Anne","Shawn/Jenny","Jeff", "Rob/Maggie") -> Jeff | E3: N | G3: 44288 | I3: =iferror(24*( DATEDIF(A3,G3,"D")+TIMEVALUE(H3)-TIMEVALUE(F3)),0) -> 0 | M3: Dry all day/all night | N3: 0 | O3: 0 | P3: 0 | Q3: 0 | R3: 0 | S3: 0 | T3: 0 | U3: 0 | V3: 0 | W3: 0 | X3: 0 | Y3: 0 | Z3: =sum(N3:Q3) -> 0 | AA3: =sum(R3:V3) -> 0 | AB3: =sum(N3:O3) -> 0 | AC3: =sum(R3:S3,V3) -> 0 | AD3: 0.09
A4: 44289 | B4: 1942 | C4: 2012 | D4: =choose(weekday(A4),"Phil/Fred", "Jane/Sarah", "Jim/John/Lena","Marsha/Anne","Shawn/Jenny","Jeff", "Rob/Maggie") -> Rob/Maggie | E4: N | G4: 44289 | I4: =iferror(24*( DATEDIF(A4,G4,"D")+TIMEVALUE(H4)-TIMEVALUE(F4)),0) -> 0 | K4: 52 | M4: fair,dry, spring | N4: 0 | O4: 0 | P4: 0 | Q4: 0 | R4: 0 | S4: 0 | T4: 0 | U4: 0 | V4: 0 | W4: 0 | X4: 0 | Y4: 0 | Z4: =sum(N4:Q4) -> 0 | AA4: =sum(R4:V4) -> 0 | AB4: =sum(N4:O4) -> 0 | AC4: =sum(R4:S4,V4) -> 0 | AD4: 0.04
A5: 44290 | B5: 1944 | C5: 2014 | D5: =choose(weekday(A5),"Phil/Fred", "Jane/Sarah", "Jim/John/Lena","Marsha/Anne","Shawn/Jenny","Jeff", "Rob/Maggie") -> Phil/Fred | E5: N | G5: 44290 | I5: =iferror(24*( DATEDIF(A5,G5,"D")+TIMEVALUE(H5)-TIMEVALUE(F5)),0) -> 0 | M5: Dry | N5: 0 | O5: 0 | P5: 0 | Q5: 0 | R5: 0 | S5: 0 | T5: 0 | U5: 0 | V5: 0 | W5: 0 | X5: 0 | Y5: 0 | Z5: =sum(N5:Q5) -> 0 | AA5: =sum(R5:V5) -> 0 | AB5: =sum(N5:O5) -> 0 | AC5: =sum(R5:S5,V5) -> 0 | AD5: 0.01
A6: 44291 | B6: 1945 | C6: 2015 | D6: =choose(weekday(A6),"Phil/Fred", "Jane/Sarah", "Jim/John/Lena","Marsha/Anne","Shawn/Jenny","Jeff", "Rob/Maggie") -> Jane/Sarah | E6: N | G6: 44291 | I6: =iferror(24*( DATEDIF(A6,G6,"D")+TIMEVALUE(H6)-TIMEVALUE(F6)),0) -> 0 | K6: 44 | M6: Dry | N6: 0 | O6: 0 | P6: 0 | Q6: 0 | R6: 0 | S6: 0 | T6: 0 | U6: 0 | V6: 0 | W6: 0 | X6: 0 | Y6: 0 | Z6: =sum(N6:Q6) -> 0 | AA6: =sum(R6:V6) -> 0 | AB6: =sum(N6:O6) -> 0 | AC6: =sum(R6:S6,V6) -> 0 | AD6: 0
A7: 44292 | B7: 1946 | C7: 2017 | D7: =choose(weekday(A7),"Phil/Fred", "Jane/Sarah", "Jim/John/Lena","Marsha/Anne","Shawn/Jenny","Jeff", "Rob/Maggie") -> Jim/John/Lena | E7: N | G7: 44292 | I7: =iferror(24*( DATEDIF(A7,G7,"D")+TIMEVALUE(H7)-TIMEVALUE(F7)),0) -> 0 | N7: 0 | O7: 0 | P7: 0 | Q7: 0 | R7: 0 | S7: 0 | T7: 0 | U7: 0 | V7: 0 | W7: 0 | X7: 0 | Y7: 0 | Z7: =sum(N7:Q7) -> 0 | AA7: =sum(R7:V7) -> 0 | AB7: =sum(N7:O7) -> 0 | AC7: =sum(R7:S7,V7) -> 0 | AD7: 0.01
A8: 44293 | B8: 1947 | C8: 2018 | D8: =choose(weekday(A8),"Phil/Fred", "Jane/Sarah", "Jim/John/Lena","Marsha/Anne","Shawn/Jenny","Jeff", "Rob/Maggie") -> Marsha/Anne | E8: Y | F8: 0.83333333 | G8: 44293 | H8: 0.89930556 | I8: =iferror(24*( DATEDIF(A8,G8,"D")+TIMEVALUE(H8)-TIMEVALUE(F8)),0) -> 1.5833333 | J8: 4.5 | K8: 46.7 | L8: 45.1 | M8: damp pavement | N8: 0 | O8: 0 | P8: 0 | Q8: 0 | R8: 1 | S8: 0 | T8: 0 | U8: 0 | V8: 0 | W8: 0 | X8: 0 | Y8: 0 | Z8: =sum(N8:Q8) -> 0 | AA8: =sum(R8:V8) -> 1 | AB8: =sum(N8:O8) -> 0 | AC8: =sum(R8:S8,V8) -> 1 | AD8: 0.04 | AE8: Downpour ~0330. Jim checked at 0545 and found 12 PSRE and 2 salamanders as roadkill
A9: 44294 | B9: 1949 | C9: 2019 | D9: =choose(weekday(A9),"Phil/Fred", "Jane/Sarah", "Jim/John/Lena","Marsha/Anne","Shawn/Jenny","Jeff", "Rob/Maggie") -> Shawn/Jenny | E9: Y | F9: 0.85416667 | G9: 44294 | H9: 0.85763889 | I9: =iferror(24*( DATEDIF(A9,G9,"D")+TIMEVALUE(H9)-TIMEVALUE(F9)),0) -> 0.083333333 | K9: 48 | L9: 48 | M9: Dry, clear | N9: 0 | O9: 0 | P9: 0 | Q9: 0 | R9: 0 | S9: 0 | T9: 0 | U9: 0 | V9: 0 | W9: 0 | X9: 0 | Y9: 0 | Z9: =sum(N9:Q9) -> 0 | AA9: =sum(R9:V9) -> 0 | AB9: =sum(N9:O9) -> 0 | AC9: =sum(R9:S9,V9) -> 0 | AD9: 0.09
A10: 44295 | B10: 1950 | C10: 2021 | D10: =choose(weekday(A10),"Phil/Fred", "Jane/Sarah", "Jim/John/Lena","Marsha/Anne","Shawn/Jenny","Jeff", "Rob/Maggie") -> Jeff | E10: Y | F10: 0.85416667 | G10: 44295 | H10: 0.875 | I10: =iferror(24*( DATEDIF(A10,G10,"D")+TIMEVALUE(H10)-TIMEVALUE(F10)),0) -> 0.5 | J10: 0.5 | K10: 48 | L10: 48 | M10: Dry, parital overcast | N10: 0 | O10: 0 | P10: 0 | Q10: 0 | R10: 0 | S10: 0 | T10: 0 | U10: 0 | V10: 0 | W10: 0 | X10: 0 | Y10: 0 | Z10: =sum(N10:Q10) -> 0 | AA10: =sum(R10:V10) -> 0 | AB10: =sum(N10:O10) -> 0 | AC10: =sum(R10:S10,V10) -> 0 | AD10: 0.16
A11: 44296 | B11: 1951 | C11: 2022 | D11: =choose(weekday(A11),"Phil/Fred", "Jane/Sarah", "Jim/John/Lena","Marsha/Anne","Shawn/Jenny","Jeff", "Rob/Maggie") -> Rob/Maggie | E11: N | G11: 44296 | I11: =iferror(24*( DATEDIF(A11,G11,"D")+TIMEVALUE(H11)-TIMEVALUE(F11)),0) -> 0 | M11: Dry | N11: 0 | O11: 0 | P11: 0 | Q11: 0 | R11: 0 | S11: 0 | T11: 0 | U11: 0 | V11: 0 | W11: 0 | X11: 0 | Y11: 0 | Z11: =sum(N11:Q11) -> 0 | AA11: =sum(R11:V11) -> 0 | AB11: =sum(N11:O11) -> 0 | AC11: =sum(R11:S11,V11) -> 0 | AD11: 0.24
A12: 44297 | B12: 1953 | C12: 2023 | D12: =choose(weekday(A12),"Phil/Fred", "Jane/Sarah", "Jim/John/Lena","Marsha/Anne","Shawn/Jenny","Jeff", "Rob/Maggie") -> Phil/Fred | E12: N | G12: 44297 | I12: =iferror(24*( DATEDIF(A12,G12,"D")+TIMEVALUE(H12)-TIMEVALUE(F12)),0) -> 0 | M12: Dry | N12: 0 | O12: 0 | P12: 0 | Q12: 0 | R12: 0 | S12: 0 | T12: 0 | U12: 0 | V12: 0 | W12: 0 | X12: 0 | Y12: 0 | Z12: =sum(N12:Q12) -> 0 | AA12: =sum(R12:V12) -> 0 | AB12: =sum(N12:O12) -> 0 | AC12: =sum(R12:S12,V12) -> 0 | AD12: 0.34
A13: 44298 | B13: 1954 | C13: 2025 | D13: =choose(weekday(A13),"Phil/Fred", "Jane/Sarah", "Jim/John/Lena","Marsha/Anne","Shawn/Jenny","Jeff", "Rob/Maggie") -> Jane/Sarah | E13: N | G13: 44298 | I13: =iferror(24*( DATEDIF(A13,G13,"D")+TIMEVALUE(H13)-TIMEVALUE(F13)),0) -> 0 | M13: Dry | N13: 0 | O13: 0 | P13: 0 | Q13: 0 | R13: 0 | S13: 0 | T13: 0 | U13: 0 | V13: 0 | W13: 0 | X13: 0 | Y13: 0 | Z13: =sum(N13:Q13) -> 0 | AA13: =sum(R13:V13) -> 0 | AB13: =sum(N13:O13) -> 0 | AC13: =sum(R13:S13,V13) -> 0 | AD13: 0.45
A14: 44299 | B14: 1955 | C14: 2026 | D14: =choose(weekday(A14),"Phil/Fred", "Jane/Sarah", "Jim/John/Lena","Marsha/Anne","Shawn/Jenny","Jeff", "Rob/Maggie") -> Jim/John/Lena | E14: N | G14: 44299 | I14: =iferror(24*( DATEDIF(A14,G14,"D")+TIMEVALUE(H14)-TIMEVALUE(F14)),0) -> 0 | M14: Dry | N14: 0 | O14: 0 | P14: 0 | Q14: 0 | R14: 0 | S14: 0 | T14: 0 | U14: 0 | V14: 0 | W14: 0 | X14: 0 | Y14: 0 | Z14: =sum(N14:Q14) -> 0 | AA14: =sum(R14:V14) -> 0 | AB14: =sum(N14:O14) -> 0 | AC14: =sum(R14:S14,V14) -> 0 | AD14: 0.56
A15: 44300 | B15: 1956 | C15: 2028 | D15: =choose(weekday(A15),"Phil/Fred", "Jane/Sarah", "Jim/John/Lena","Marsha/Anne","Shawn/Jenny","Jeff", "Rob/Maggie") -> Marsha/Anne | E15: N | G15: 44300 | I15: =iferror(24*( DATEDIF(A15,G15,"D")+TIMEVALUE(H15)-TIMEVALUE(F15)),0) -> 0 | M15: Dry | N15: 0 | O15: 0 | P15: 0 | Q15: 0 | R15: 0 | S15: 0 | T15: 0 | U15: 0 | V15: 0 | W15: 0 | X15: 0 | Y15: 0 | Z15: =sum(N15:Q15) -> 0 | AA15: =sum(R15:V15) -> 0 | AB15: =sum(N15:O15) -> 0 | AC15: =sum(R15:S15,V15) -> 0 | AD15: 0.67
A16: 44301 | B16: 1958 | C16: 2029 | D16: =choose(weekday(A16),"Phil/Fred", "Jane/Sarah", "Jim/John/Lena","Marsha/Anne","Shawn/Jenny","Jeff", "Rob/Maggie") -> Shawn/Jenny | E16: N | G16: 44301 | I16: =iferror(24*( DATEDIF(A16,G16,"D")+TIMEVALUE(H16)-TIMEVALUE(F16)),0) -> 0 | M16: Dry | N16: 0 | O16: 0 | P16: 0 | Q16: 0 | R16: 0 | S16: 0 | T16: 0 | U16: 0 | V16: 0 | W16: 0 | X16: 0 | Y16: 0 | Z16: =sum(N16:Q16) -> 0 | AA16: =sum(R16:V16) -> 0 | AB16: =sum(N16:O16) -> 0 | AC16: =sum(R16:S16,V16) -> 0 | AD16: 0.78
A17: 44302 | B17: 1959 | C17: 2030 | D17: =choose(weekday(A17),"Phil/Fred", "Jane/Sarah", "Jim/John/Lena","Marsha/Anne","Shawn/Jenny","Jeff", "Rob/Maggie") -> Jeff | E17: N | G17: 44302 | I17: =iferror(24*( DATEDIF(A17,G17,"D")+TIMEVALUE(H17)-TIMEVALUE(F17)),0) -> 0 | M17: Dry | N17: 0 | O17: 0 | P17: 0 | Q17: 0 | R17: 0 | S17: 0 | T17: 0 | U17: 0 | V17: 0 | W17: 0 | X17: 0 | Y17: 0 | Z17: =sum(N17:Q17) -> 0 | AA17: =sum(R17:V17) -> 0 | AB17: =sum(N17:O17) -> 0 | AC17: =sum(R17:S17,V17) -> 0 | AD17: 0.87
A18: 44303 | B18: 2000 | C18: 2032 | D18: =choose(weekday(A18),"Phil/Fred", "Jane/Sarah", "Jim/John/Lena","Marsha/Anne","Shawn/Jenny","Jeff", "Rob/Maggie") -> Rob/Maggie | E18: N | G18: 44303 | I18: =iferror(24*( DATEDIF(A18,G18,"D")+TIMEVALUE(H18)-TIMEVALUE(F18)),0) -> 0 | M18: Dry | N18: 0 | O18: 0 | P18: 0 | Q18: 0 | R18: 0 | S18: 0 | T18: 0 | U18: 0 | V18: 0 | W18: 0 | X18: 0 | Y18: 0 | Z18: =sum(N18:Q18) -> 0 | AA18: =sum(R18:V18) -> 0 | AB18: =sum(N18:O18) -> 0 | AC18: =sum(R18:S18,V18) -> 0 | AD18: 0.94
A19: 44304 | B19: 2002 | C19: 2033 | D19: =choose(weekday(A19),"Phil/Fred", "Jane/Sarah", "Jim/John/Lena","Marsha/Anne","Shawn/Jenny","Jeff", "Rob/Maggie") -> Phil/Fred | E19: N | G19: 44304 | I19: =iferror(24*( DATEDIF(A19,G19,"D")+TIMEVALUE(H19)-TIMEVALUE(F19)),0) -> 0 | M19: Dry | N19: 0 | O19: 0 | P19: 0 | Q19: 0 | R19: 0 | S19: 0 | T19: 0 | U19: 0 | V19: 0 | W19: 0 | X19: 0 | Y19: 0 | Z19: =sum(N19:Q19) -> 0 | AA19: =sum(R19:V19) -> 0 | AB19: =sum(N19:O19) -> 0 | AC19: =sum(R19:S19,V19) -> 0 | AD19: 0.98
A20: 44305 | B20: 2003 | C20: 2034 | D20: =choose(weekday(A20),"Phil/Fred", "Jane/Sarah", "Jim/John/Lena","Marsha/Anne","Shawn/Jenny","Jeff", "Rob/Maggie") -> Jane/Sarah | E20: N | G20: 44305 | I20: =iferror(24*( DATEDIF(A20,G20,"D")+TIMEVALUE(H20)-TIMEVALUE(F20)),0) -> 0 | M20: Dry | N20: 0 | O20: 0 | P20: 0 | Q20: 0 | R20: 0 | S20: 0 | T20: 0 | U20: 0 | V20: 0 | W20: 0 | X20: 0 | Y20: 0 | Z20: =sum(N20:Q20) -> 0 | AA20: =sum(R20:V20) -> 0 | AB20: =sum(N20:O20) -> 0 | AC20: =sum(R20:S20,V20) -> 0 | AD20: 1
A21: 44306 | B21: 2004 | C21: 2036 | D21: =choose(weekday(A21),"Phil/Fred", "Jane/Sarah", "Jim/John/Lena","Marsha/Anne","Shawn/Jenny","Jeff", "Rob/Maggie") -> Jim/John/Lena | E21: N | G21: 44306 | I21: =iferror(24*( DATEDIF(A21,G21,"D")+TIMEVALUE(H21)-TIMEVALUE(F21)),0) -> 0 | M21: Dry | N21: 0 | O21: 0 | P21: 0 | Q21: 0 | R21: 0 | S21: 0 | T21: 0 | U21: 0 | V21: 0 | W21: 0 | X21: 0 | Y21: 0 | Z21: =sum(N21:Q21) -> 0 | AA21: =sum(R21:V21) -> 0 | AB21: =sum(N21:O21) -> 0 | AC21: =sum(R21:S21,V21) -> 0 | AD21: 0.99
A22: 44307 | B22: 2005 | C22: 2037 | D22: =choose(weekday(A22),"Phil/Fred", "Jane/Sarah", "Jim/John/Lena","Marsha/Anne","Shawn/Jenny","Jeff", "Rob/Maggie") -> Marsha/Anne | E22: N | G22: 44307 | I22: =iferror(24*( DATEDIF(A22,G22,"D")+TIMEVALUE(H22)-TIMEVALUE(F22)),0) -> 0 | M22: Dry | N22: 0 | O22: 0 | P22: 0 | Q22: 0 | R22: 0 | S22: 0 | T22: 0 | U22: 0 | V22: 0 | W22: 0 | X22: 0 | Y22: 0 | Z22: =sum(N22:Q22) -> 0 | AA22: =sum(R22:V22) -> 0 | AB22: =sum(N22:O22) -> 0 | AC22: =sum(R22:S22,V22) -> 0 | AD22: 0.95
A23: 44308 | B23: 2007 | C23: 2039 | D23: =choose(weekday(A23),"Phil/Fred", "Jane/Sarah", "Jim/John/Lena","Marsha/Anne","Shawn/Jenny","Jeff", "Rob/Maggie") -> Shawn/Jenny | E23: N | G23: 44308 | I23: =iferror(24*( DATEDIF(A23,G23,"D")+TIMEVALUE(H23)-TIMEVALUE(F23)),0) -> 0 | M23: Dry, partly cloudy | N23: 0 | O23: 0 | P23: 0 | Q23: 0 | R23: 0 | S23: 0 | T23: 0 | U23: 0 | V23: 0 | W23: 0 | X23: 0 | Y23: 0 | Z23: =sum(N23:Q23) -> 0 | AA23: =sum(R23:V23) -> 0 | AB23: =sum(N23:O23) -> 0 | AC23: =sum(R23:S23,V23) -> 0 | AD23: 0.9
A24: 44309 | B24: 2008 | C24: 2040 | D24: =choose(weekday(A24),"Phil/Fred", "Jane/Sarah", "Jim/John/Lena","Marsha/Anne","Shawn/Jenny","Jeff", "Rob/Maggie") -> Jeff | G24: 44309 | I24: =iferror(24*( DATEDIF(A24,G24,"D")+TIMEVALUE(H24)-TIMEVALUE(F24)),0) -> 0 | N24: 0 | O24: 0 | P24: 0 | Q24: 0 | R24: 0 | S24: 0 | T24: 0 | U24: 0 | V24: 0 | W24: 0 | X24: 0 | Y24: 0 | Z24: =sum(N24:Q24) -> 0 | AA24: =sum(R24:V24) -> 0 | AB24: =sum(N24:O24) -> 0 | AC24: =sum(R24:S24,V24) -> 0 | AD24: 0.83
A25: 44310 | B25: 2009 | C25: 2042 | D25: =choose(weekday(A25),"Phil/Fred", "Jane/Sarah", "Jim/John/Lena","Marsha/Anne","Shawn/Jenny","Jeff", "Rob/Maggie") -> Rob/Maggie | G25: 44310 | I25: =iferror(24*( DATEDIF(A25,G25,"D")+TIMEVALUE(H25)-TIMEVALUE(F25)),0) -> 0 | N25: 0 | O25: 0 | P25: 0 | Q25: 0 | R25: 0 | S25: 0 | T25: 0 | U25: 0 | V25: 0 | W25: 0 | X25: 0 | Y25: 0 | Z25: =sum(N25:Q25) -> 0 | AA25: =sum(R25:V25) -> 0 | AB25: =sum(N25:O25) -> 0 | AC25: =sum(R25:S25,V25) -> 0 | AD25: 0.74
A26: 44311 | B26: 2011 | C26: 2043 | D26: =choose(weekday(A26),"Phil/Fred", "Jane/Sarah", "Jim/John/Lena","Marsha/Anne","Shawn/Jenny","Jeff", "Rob/Maggie") -> Phil/Fred | G26: 44311 | I26: =iferror(24*( DATEDIF(A26,G26,"D")+TIMEVALUE(H26)-TIMEVALUE(F26)),0) -> 0 | N26: 0 | O26: 0 | P26: 0 | Q26: 0 | R26: 0 | S26: 0 | T26: 0 | U26: 0 | V26: 0 | W26: 0 | X26: 0 | Y26: 0 | Z26: =sum(N26:Q26) -> 0 | AA26: =sum(R26:V26) -> 0 | AB26: =sum(N26:O26) -> 0 | AC26: =sum(R26:S26,V26) -> 0 | AD26: 0.65
A27: 44312 | B27: 2012 | C27: 2044 | D27: =choose(weekday(A27),"Phil/Fred", "Jane/Sarah", "Jim/John/Lena","Marsha/Anne","Shawn/Jenny","Jeff", "Rob/Maggie") -> Jane/Sarah | G27: 44312 | I27: =iferror(24*( DATEDIF(A27,G27,"D")+TIMEVALUE(H27)-TIMEVALUE(F27)),0) -> 0 | K27: 52 | M27: Dry | N27: 0 | O27: 0 | P27: 0 | Q27: 0 | R27: 0 | S27: 0 | T27: 0 | U27: 0 | V27: 0 | W27: 0 | X27: 0 | Y27: 0 | Z27: =sum(N27:Q27) -> 0 | AA27: =sum(R27:V27) -> 0 | AB27: =sum(N27:O27) -> 0 | AC27: =sum(R27:S27,V27) -> 0 | AD27: 0.56
A28: 44313 | B28: 2013 | C28: 2046 | D28: =choose(weekday(A28),"Phil/Fred", "Jane/Sarah", "Jim/John/Lena","Marsha/Anne","Shawn/Jenny","Jeff", "Rob/Maggie") -> Jim/John/Lena | G28: 44313 | I28: =iferror(24*( DATEDIF(A28,G28,"D")+TIMEVALUE(H28)-TIMEVALUE(F28)),0) -> 0 | N28: 0 | O28: 0 | P28: 0 | Q28: 0 | R28: 0 | S28: 0 | T28: 0 | U28: 0 | V28: 0 | W28: 0 | X28: 0 | Y28: 0 | Z28: =sum(N28:Q28) -> 0 | AA28: =sum(R28:V28) -> 0 | AB28: =sum(N28:O28) -> 0 | AC28: =sum(R28:S28,V28) -> 0 | AD28: 0.46
A29: 44314 | B29: 2014 | C29: 2047 | D29: =choose(weekday(A29),"Phil/Fred", "Jane/Sarah", "Jim/John/Lena","Marsha/Anne","Shawn/Jenny","Jeff", "Rob/Maggie") -> Marsha/Anne | G29: 44314 | I29: =iferror(24*( DATEDIF(A29,G29,"D")+TIMEVALUE(H29)-TIMEVALUE(F29)),0) -> 0 | N29: 0 | O29: 0 | P29: 0 | Q29: 0 | R29: 0 | S29: 0 | T29: 0 | U29: 0 | V29: 0 | W29: 0 | X29: 0 | Y29: 0 | Z29: =sum(N29:Q29) -> 0 | AA29: =sum(R29:V29) -> 0 | AB29: =sum(N29:O29) -> 0 | AC29: =sum(R29:S29,V29) -> 0 | AD29: 0.37
A30: 44315 | B30: 2016 | C30: 2049 | D30: =choose(weekday(A30),"Phil/Fred", "Jane/Sarah", "Jim/John/Lena","Marsha/Anne","Shawn/Jenny","Jeff", "Rob/Maggie") -> Shawn/Jenny | G30: 44315 | I30: =iferror(24*( DATEDIF(A30,G30,"D")+TIMEVALUE(H30)-TIMEVALUE(F30)),0) -> 0 | N30: 0 | O30: 0 | P30: 0 | Q30: 0 | R30: 0 | S30: 0 | T30: 0 | U30: 0 | V30: 0 | W30: 0 | X30: 0 | Y30: 0 | Z30: =sum(N30:Q30) -> 0 | AA30: =sum(R30:V30) -> 0 | AB30: =sum(N30:O30) -> 0 | AC30: =sum(R30:S30,V30) -> 0 | AD30: 0.28
A31: 44316 | B31: 2017 | C31: 2050 | D31: =choose(weekday(A31),"Phil/Fred", "Jane/Sarah", "Jim/John/Lena","Marsha/Anne","Shawn/Jenny","Jeff", "Rob/Maggie") -> Jeff | G31: 44316 | I31: =iferror(24*( DATEDIF(A31,G31,"D")+TIMEVALUE(H31)-TIMEVALUE(F31)),0) -> 0 | N31: 0 | O31: 0 | P31: 0 | Q31: 0 | R31: 0 | S31: 0 | T31: 0 | U31: 0 | V31: 0 | W31: 0 | X31: 0 | Y31: 0 | Z31: =sum(N31:Q31) -> 0 | AA31: =sum(R31:V31) -> 0 | AB31: =sum(N31:O31) -> 0 | AC31: =sum(R31:S31,V31) -> 0 | AD31: 0.2
A32: xx/xx/xxxx | B32: x | C32: x | I32: =iferror(24*( DATEDIF(A32,G32,"D")+TIMEVALUE(H32)-TIMEVALUE(F32)),0) -> 0 | N32: xxxx | O32: xxxx | P32: xxxx | Q32: xxxx | R32: xxxx | S32: xxxx | T32: xxxx | U32: xxxx | V32: xxxx | W32: xxxx | X32: xxxx | Y32: xxxx | Z32: xxxx | AA32: xxxx | AB32: xxxx | AC32: xxxx | AD32: X
D33: Monthly total | I33: =SUM(I3:I32) -> 2.1666667 | J33: =SUM(J2:J32) -> 5 | N33: =sum(N2:N32) -> 0 | O33: =sum(O2:O32) -> 0 | P33: =sum(P2:P32) -> 0 | Q33: =sum(Q2:Q32) -> 0 | R33: =sum(R2:R32) -> 1 | S33: =sum(S2:S32) -> 0 | T33: =sum(T2:T32) -> 0 | U33: =sum(U2:U32) -> 0 | ... Y33: =sum(Y2:Y32) -> 0 | Z33: =SUM(Z2:Z32) -> 0 | AA33: =SUM(AA2:AA32) -> 1 | AB33: =sum(AB2:AB32) -> 0 | AC33: =sum(AC2:AC32) -> 1
